Workbook

Sheet Cover
K7: Coal India Ltd.
K8: Open Source Financial Model
B21: Contact
B22: Anil Bains
B23: anil@edupristine.com | I23: © Neev Knowledge Management - Pristine
B24: +91 96196 73853 | I24: www.edupristine.com
I25: info@edupristine.com
B26: Paramdeep Singh
B27: paramdeep@edupristine.com | I27: +91 22 3215 6191
B28: +91 98929 80608 | I28: +91 8080 00 55 33
A30: Pristine is India's largest authorized training provider for CFA®, FRM®, PRM and Financial Modeling. It has conducted more than 300,000+ man-hours of finance trainings for individuals and corporates in all the major Indian cities and outside India.

Sheet ReadMeFirst
A3: CIL is the largest IPO in India till date. It has generated enormous interest in the investor community (both retail and institutional). Many potential investors want a financial model in MS Excel© which can help them in a thorough analysis of the company. Creating such models have always been a time-taking and daunting exercise. Pristine has created an integrated valuation model based on publically available information. It is available as an open-source model for any user. Kindly note that this model is meant for information purpose only. The complete structure of the model and formulas, linkages etc. have been kept open to allow for any modification on the part of the user. Users can use the model freely but should make reference to Pristine while using the same. Pristine conducts extensive trainings for financial modeling in MS Excel©. These trainings are targeted towards investors/ professionals who are looking for a career in finance (Investment Banking, PE, Broking, Equity Research, etc.). At the completion of the trainings, the participants should be able to create models like these. For more information you can contact the authors or Pristine.
I25: © Neev Knowledge Management - Pristine
I26: www.edupristine.com
I27: info@edupristine.com
A29: Pristine is India's largest authorized training provider for CFA®, FRM®, PRM and Financial Modeling. It has conducted more than 300,000+ man-hours of finance trainings for individuals and corporates in all the major Indian cities and outside India.

Sheet Disclaimer
A4: This open source financial model is for information purposes only. Due efforts have been taken by Pristine and its employees in preparation of this model to ensure that the information is accurate to the best of their knowledge and belief. The primary source of information contained in the report has been the DRHP filing of the company with SEBI. Pristine, makes no representations or warranties regarding the accuracy or completeness of such information and expressly disclaims any and all liabilities based on such information or on omissions there from. The analysts who compiled this open source financial model hereby state that the contents in the document reflect his/her/their views and opinions on the subject matter. Pristine, and its employees/ analysts do conduct trainings and from time to time to seek establish business or financial relationships with companies covered in the open research models. As a result, investors should be aware that Pristine and/or such individuals may have conflicts of interests that could affect the objectivity of this report.
I26: © Neev Knowledge Management - Pristine
I27: www.edupristine.com
I28: info@edupristine.com
A30: Pristine is India's largest authorized training provider for CFA®, FRM®, PRM and Financial Modeling. It has conducted more than 300,000+ man-hours of finance trainings for individuals and corporates in all the major Indian cities and outside India.

Sheet Assumptions
R1: CAGR
R2: Scroll Bar
A4: (Unless otherwise specified, all financials are in INR Million) | F4: =CF!F4 | G4: =CF!G4 | H4: =CF!H4 | I4: =CF!I4 | J4: =CF!J4 | K4: =CF!K4 | L4: =CF!L4 | M4: =CF!M4 | ... O4: =CF!O4
A5: P&L Assumptions
K6: 21 | L6: 21 | M6: 21 | N6: 21 | O6: 21
B7: Sales Growth Rate | E7: Scroll Bar | G7: ='P&L'!G7/'P&L'!F7-1 | H7: ='P&L'!H7/'P&L'!G7-1 | I7: ='P&L'!I7/'P&L'!H7-1 | J7: ='P&L'!J7/'P&L'!I7-1 | K7: =IF($E7="CAGR",AVERAGE(G7:J7),K6/100) | L7: =IF($E7="CAGR",AVERAGE(H7:K7),L6/100) | M7: =IF($E7="CAGR",AVERAGE(I7:L7),M6/100) | N7: =IF($E7="CAGR",AVERAGE(J7:M7),N6/100) | O7: =IF($E7="CAGR",AVERAGE(K7:N7),O6/100)
K9: 8 | L9: 19 | M9: 44 | N9: 44 | O9: 44
B10: Other Income Growth Rate | E10: CAGR | G10: ='P&L'!G10/'P&L'!F10-1 | H10: ='P&L'!H10/'P&L'!G10-1 | I10: ='P&L'!I10/'P&L'!H10-1 | J10: ='P&L'!J10/'P&L'!I10-1 | K10: =IF($E10="CAGR",AVERAGE(G10:J10),K9/100) | L10: =IF($E10="CAGR",AVERAGE(H10:K10),L9/100) | M10: =IF($E10="CAGR",AVERAGE(I10:L10),M9/100) | N10: =IF($E10="CAGR",AVERAGE(J10:M10),N9/100) | O10: =IF($E10="CAGR",AVERAGE(K10:N10),O9/100)
K12: 8 | L12: 9 | M12: 44 | N12: 44 | O12: 44
B13: Internal consumption of coal Growth Rate | E13: CAGR | G13: ='P&L'!G14/'P&L'!F14-1 | H13: ='P&L'!H14/'P&L'!G14-1 | I13: ='P&L'!I14/'P&L'!H14-1 | J13: ='P&L'!J14/'P&L'!I14-1 | K13: =IF($E13="CAGR",AVERAGE(G13:J13),K12/100) | L13: =IF($E13="CAGR",AVERAGE(H13:K13),L12/100) | M13: =IF($E13="CAGR",AVERAGE(I13:L13),M12/100) | N13: =IF($E13="CAGR",AVERAGE(J13:M13),N12/100) | O13: =IF($E13="CAGR",AVERAGE(K13:N13),O12/100)
K15: 8 | L15: 9 | M15: 44 | N15: 44 | O15: 44
B16: Consumption of Stores & Spares as % of Sales | E16: CAGR | G16: ='P&L'!G15/'P&L'!G7 | H16: ='P&L'!H15/'P&L'!H7 | I16: ='P&L'!I15/'P&L'!I7 | J16: ='P&L'!J15/'P&L'!J7 | K16: =IF($E16="CAGR",AVERAGE(G16:J16),K15/100) | L16: =IF($E16="CAGR",AVERAGE(H16:K16),L15/100) | M16: =IF($E16="CAGR",AVERAGE(I16:L16),M15/100) | N16: =IF($E16="CAGR",AVERAGE(J16:M16),N15/100) | O16: =IF($E16="CAGR",AVERAGE(K16:N16),O15/100)
K18: 36 | L18: 33 | M18: 44 | N18: 44 | O18: 44
B19: Employees remuneration & Benefits Growth Rate | E19: CAGR | G19: ='P&L'!G16/'P&L'!F16-1 | H19: ='P&L'!H16/'P&L'!G16-1 | I19: ='P&L'!I16/'P&L'!H16-1 | J19: ='P&L'!J16/'P&L'!I16-1 | K19: =IF($E19="CAGR",AVERAGE(G19:J19),K18/100) | L19: =IF($E19="CAGR",AVERAGE(H19:K19),L18/100) | M19: =IF($E19="CAGR",AVERAGE(I19:L19),M18/100) | N19: =IF($E19="CAGR",AVERAGE(J19:M19),N18/100) | O19: =IF($E19="CAGR",AVERAGE(K19:N19),O18/100)
K21: 26 | L21: 33 | M21: 44 | N21: 44 | O21: 44
B22: Power & Fuel as % of Sales | E22: CAGR | G22: ='P&L'!G17/'P&L'!G7 | H22: ='P&L'!H17/'P&L'!H7 | I22: ='P&L'!I17/'P&L'!I7 | J22: ='P&L'!J17/'P&L'!J7 | K22: =IF($E22="CAGR",AVERAGE(G22:J22),K21/100) | L22: =IF($E22="CAGR",AVERAGE(H22:K22),L21/100) | M22: =IF($E22="CAGR",AVERAGE(I22:L22),M21/100) | N22: =IF($E22="CAGR",AVERAGE(J22:M22),N21/100) | O22: =IF($E22="CAGR",AVERAGE(K22:N22),O21/100)
K24: 33 | M24: 44 | N24: 44 | O24: 44
B25: Social Overhead as % of Sales | E25: CAGR | G25: ='P&L'!G18/'P&L'!G7 | H25: ='P&L'!H18/'P&L'!H7 | I25: ='P&L'!I18/'P&L'!I7 | J25: ='P&L'!J18/'P&L'!J7 | K25: =IF($E25="CAGR",AVERAGE(G25:J25),K24/100) | L25: =IF($E25="CAGR",AVERAGE(H25:K25),L24/100) | M25: =IF($E25="CAGR",AVERAGE(I25:L25),M24/100) | N25: =IF($E25="CAGR",AVERAGE(J25:M25),N24/100) | O25: =IF($E25="CAGR",AVERAGE(K25:N25),O24/100)
K27: 36 | L27: 33 | M27: 44 | N27: 44 | O27: 44
B28: Repairs as % of Sales | E28: CAGR | G28: ='P&L'!G19/'P&L'!G7 | H28: ='P&L'!H19/'P&L'!H7 | I28: ='P&L'!I19/'P&L'!I7 | J28: ='P&L'!J19/'P&L'!J7 | K28: =IF($E28="CAGR",AVERAGE(G28:J28),K27/100) | L28: =IF($E28="CAGR",AVERAGE(H28:K28),L27/100) | M28: =IF($E28="CAGR",AVERAGE(I28:L28),M27/100) | N28: =IF($E28="CAGR",AVERAGE(J28:M28),N27/100) | O28: =IF($E28="CAGR",AVERAGE(K28:N28),O27/100)
K30: 26 | L30: 33 | M30: 44 | N30: 54 | O30: 44
B31: Contractual Expenses as % of Sales | E31: CAGR | G31: ='P&L'!G20/'P&L'!G7 | H31: ='P&L'!H20/'P&L'!H7 | I31: ='P&L'!I20/'P&L'!I7 | J31: ='P&L'!J20/'P&L'!J7 | K31: =IF($E31="CAGR",AVERAGE(G31:J31),K30/100) | L31: =IF($E31="CAGR",AVERAGE(H31:K31),L30/100) | M31: =IF($E31="CAGR",AVERAGE(I31:L31),M30/100) | N31: =IF($E31="CAGR",AVERAGE(J31:M31),N30/100) | O31: =IF($E31="CAGR",AVERAGE(K31:N31),O30/100)
K33: 26 | L33: 33 | M33: 44 | N33: 44 | O33: 44
B34: Other Expenditure as % of Sales | E34: CAGR | G34: ='P&L'!G21/'P&L'!G7 | H34: ='P&L'!H21/'P&L'!H7 | I34: ='P&L'!I21/'P&L'!I7 | J34: ='P&L'!J21/'P&L'!J7 | K34: =IF($E34="CAGR",AVERAGE(G34:J34),K33/100) | L34: =IF($E34="CAGR",AVERAGE(H34:K34),L33/100) | M34: =IF($E34="CAGR",AVERAGE(I34:L34),M33/100) | N34: =IF($E34="CAGR",AVERAGE(J34:M34),N33/100) | O34: =IF($E34="CAGR",AVERAGE(K34:N34),O33/100)
K36: 26 | L36: 33 | M36: 44 | N36: 44 | O36: 44
B37: Overburden removal adjustment as % of Sales | E37: CAGR | G37: ='P&L'!G23/'P&L'!G7 | H37: ='P&L'!H23/'P&L'!H7 | I37: ='P&L'!I23/'P&L'!I7 | J37: ='P&L'!J23/'P&L'!J7 | K37: =IF($E37="CAGR",AVERAGE(G37:J37),K36/100) | L37: =IF($E37="CAGR",AVERAGE(H37:K37),L36/100) | M37: =IF($E37="CAGR",AVERAGE(I37:L37),M36/100) | N37: =IF($E37="CAGR",AVERAGE(J37:M37),N36/100) | O37: =IF($E37="CAGR",AVERAGE(K37:N37),O36/100)
K39: 26 | L39: 33 | M39: 44 | N39: 44 | O39: 44
B40: Finance Charges/Commitment Charges | E40: CAGR | G40: ='P&L'!G24/'P&L'!F24-1 | H40: ='P&L'!H24/'P&L'!G24-1 | I40: ='P&L'!I24/'P&L'!H24-1 | J40: ='P&L'!J24/'P&L'!I24-1 | K40: =IF($E40="CAGR",AVERAGE(G40:J40),K39/100) | L40: =IF($E40="CAGR",AVERAGE(H40:K40),L39/100) | M40: =IF($E40="CAGR",AVERAGE(I40:L40),M39/100) | N40: =IF($E40="CAGR",AVERAGE(J40:M40),N39/100) | O40: =IF($E40="CAGR",AVERAGE(K40:N40),O39/100)
K42: 0 | L42: 0 | M42: 0 | N42: 0 | O42: 0
B43: Impairment | E43: Scroll Bar | G43: ='P&L'!G26/'P&L'!F26-1 | H43: ='P&L'!H26/'P&L'!G26-1 | I43: ='P&L'!I26/'P&L'!H26-1 | J43: ='P&L'!J26/'P&L'!I26-1 | K43: =IF($E43="CAGR",AVERAGE(G43:J43),K42/100) | L43: =IF($E43="CAGR",AVERAGE(H43:K43),L42/100) | M43: =IF($E43="CAGR",AVERAGE(I43:L43),M42/100) | N43: =IF($E43="CAGR",AVERAGE(J43:M43),N42/100) | O43: =IF($E43="CAGR",AVERAGE(K43:N43),O42/100)
K45: 26 | L45: 33 | M45: 44 | N45: 44 | O45: 44
B46: Write off as % of Provisions | E46: CAGR | G46: ='P&L'!G27/BS!G9 | H46: ='P&L'!H27/BS!H9 | I46: ='P&L'!I27/BS!I9 | J46: ='P&L'!J27/BS!J9 | K46: =IF($E46="CAGR",AVERAGE(G46:J46),K45/100) | L46: =IF($E46="CAGR",AVERAGE(H46:K46),L45/100) | M46: =IF($E46="CAGR",AVERAGE(I46:L46),M45/100) | N46: =IF($E46="CAGR",AVERAGE(J46:M46),N45/100) | O46: =IF($E46="CAGR",AVERAGE(K46:N46),O45/100)
A49: Balance Sheet Assumptions
K50: 26 | L50: 33 | M50: 44 | N50: 44 | O50: 44
B51: Capital Work in Progress as % of Sales | E51: CAGR | G51: =BS!G12/'P&L'!G7 | H51: =BS!H12/'P&L'!H7 | I51: =BS!I12/'P&L'!I7 | J51: =BS!J12/'P&L'!J7 | K51: =IF($E51="CAGR",AVERAGE(G51:J51),K50/100) | L51: =IF($E51="CAGR",AVERAGE(H51:K51),L50/100) | M51: =IF($E51="CAGR",AVERAGE(I51:L51),M50/100) | N51: =IF($E51="CAGR",AVERAGE(J51:M51),N50/100) | O51: =IF($E51="CAGR",AVERAGE(K51:N51),O50/100)
K53: 26 | L53: 33 | M53: 44 | N53: 44 | O53: 44
B54: Surveyed Off Assets as % of Net Block | E54: CAGR | G54: =BS!F13/BS!F11 | H54: =BS!G13/BS!G11 | I54: =BS!H13/BS!H11 | J54: =BS!I13/BS!I11 | K54: =IF($E54="CAGR",AVERAGE(G54:J54),K53/100) | L54: =IF($E54="CAGR",AVERAGE(H54:K54),L53/100) | M54: =IF($E54="CAGR",AVERAGE(I54:L54),M53/100) | N54: =IF($E54="CAGR",AVERAGE(J54:M54),N53/100) | O54: =IF($E54="CAGR",AVERAGE(K54:N54),O53/100)
K56: 36 | L56: 33 | M56: 44 | N56: 44 | O56: 44
B57: Sundry Debtors as % of Gross Block | E57: CAGR | G57: =BS!G21/BS!G7 | H57: =BS!H21/BS!H7 | I57: =BS!I21/BS!I7 | J57: =BS!J21/BS!J7 | K57: =IF($E57="CAGR",AVERAGE(G57:J57),K56/100) | L57: =IF($E57="CAGR",AVERAGE(H57:K57),L56/100) | M57: =IF($E57="CAGR",AVERAGE(I57:L57),M56/100) | N57: =IF($E57="CAGR",AVERAGE(J57:M57),N56/100) | O57: =IF($E57="CAGR",AVERAGE(K57:N57),O56/100)
K59: 180 | L59: 165 | M59: 160 | N59: 150 | O59: 150
...

Sheet P&L
A1: Profit & Loss Statement
A4: (Unless otherwise specified, all financials are in INR Million) | F4: FY06A | G4: FY07A | H4: FY08A | I4: FY09A | J4: FY10A | K4: FY11E | L4: FY12E | M4: FY13E | N4: FY14E | O4: FY15E
A6: Income
B7: Sales | F7: 287018.31 | G7: 296021.85 | H7: 326338.6 | I7: 387888.3 | J7: 446152.51 | K7: =J7*(1+Assumptions!K7) | L7: =K7*(1+Assumptions!L7) | M7: =L7*(1+Assumptions!M7) | N7: =M7*(1+Assumptions!N7) | O7: =N7*(1+Assumptions!O7)
B8: Coal used for other purposes | F8: 20540.47 | G8: 19404.7 | H8: 19745.42 | I8: 20219.81 | J8: 20690.44 | K8: =J8 | L8: =K8 | M8: =L8 | N8: =M8 | O8: =N8
B9: Accretion(+)/Decretion(-) of stock | F9: 4837.76 | G9: 2475.52 | H9: 2441.95 | I9: 1336.07 | J9: 6671.58 | K9: =J9 | L9: =K9 | M9: =L9 | N9: =M9 | O9: =N9
B10: Other Income | F10: 27691.45 | G10: 32152 | H10: 37641 | I10: 51196.47 | J10: 52408.39 | K10: =J10*(1+Assumptions!K10) | L10: =K10*(1+Assumptions!L10) | M10: =L10*(1+Assumptions!M10) | N10: =M10*(1+Assumptions!N10) | O10: =N10*(1+Assumptions!O10)
A11: Total | F11: =SUM(F7:F10) | G11: =SUM(G7:G10) | H11: =SUM(H7:H10) | I11: =SUM(I7:I10) | J11: =SUM(J7:J10) | K11: =SUM(K7:K10) | L11: =SUM(L7:L10) | M11: =SUM(M7:M10) | ... O11: =SUM(O7:O10)
A13: Expenditure
B14: Internal consumption of coal | F14: 20136.65 | G14: 18480.49 | H14: 19508.61 | I14: 19921.53 | J14: 19721.13 | K14: =J14*(1+Assumptions!K13) | L14: =K14*(1+Assumptions!L13) | M14: =L14*(1+Assumptions!M13) | N14: =M14*(1+Assumptions!N13) | O14: =N14*(1+Assumptions!O13)
B15: Consumption of Stores & Spares | F15: 38887.5 | G15: 41255.92 | H15: 43785.55 | I15: 48613.01 | J15: 49269.18 | K15: =Assumptions!K16*K7 | L15: =Assumptions!L16*L7 | M15: =Assumptions!M16*M7 | N15: =Assumptions!N16*N7 | O15: =Assumptions!O16*O7
B16: Employees remuneration & Benefits | F16: 97879.94 | G16: 100975.32 | H16: 126351.59 | I16: 197420.85 | J16: 166555.22 | K16: =J16*(1+Assumptions!K19) | L16: =K16*(1+Assumptions!L19) | M16: =L16*(1+Assumptions!M19) | N16: =M16*(1+Assumptions!N19) | O16: =N16*(1+Assumptions!O19)
B17: Power & Fuel | F17: 15513.33 | G17: 16003.48 | H17: 15937 | I17: 15950.52 | J17: 17395.95 | K17: =Assumptions!K22*K7 | L17: =Assumptions!L22*L7 | M17: =Assumptions!M22*M7 | N17: =Assumptions!N22*N7 | O17: =Assumptions!O22*O7
B18: Social Overhead | F18: 13677.35 | G18: 14780.48 | H18: 16228.57 | I18: 18851.22 | J18: 20174.87 | K18: =Assumptions!K25*K7 | L18: =Assumptions!L25*L7 | M18: =Assumptions!M25*M7 | N18: =Assumptions!N25*N7 | O18: =Assumptions!O25*O7
B19: Repairs | F19: 6501.78 | G19: 6649.14 | H19: 7096.92 | I19: 7860.61 | J19: 8479.39 | K19: =Assumptions!K28*K7 | L19: =Assumptions!L28*L7 | M19: =Assumptions!M28*M7 | N19: =Assumptions!N28*N7 | O19: =Assumptions!O28*O7
B20: Contractual Expenses | F20: 19745.03 | G20: 20934.03 | H20: 26332.58 | I20: 33398.54 | J20: 37318.37 | K20: =Assumptions!K31*K7 | L20: =Assumptions!L31*L7 | M20: =Assumptions!M31*M7 | N20: =Assumptions!N31*N7 | O20: =Assumptions!O31*O7
B21: Other Expenditure | F21: 13280.94 | G21: 12639.82 | H21: 14873.47 | I21: 19285.19 | J21: 19335.99 | K21: =Assumptions!K34*K7 | L21: =Assumptions!L34*L7 | M21: =Assumptions!M34*M7 | N21: =Assumptions!N34*N7 | O21: =Assumptions!O34*O7
B22: Interest | F22: 909.04 | G22: ='Debt Schedule'!G20 | H22: ='Debt Schedule'!H20 | I22: ='Debt Schedule'!I20 | J22: ='Debt Schedule'!J20 | K22: ='Debt Schedule'!K20 | L22: ='Debt Schedule'!L20 | M22: ='Debt Schedule'!M20 | N22: ='Debt Schedule'!N20 | O22: ='Debt Schedule'!O20
B23: Overburden removal adjustment | F23: 12098.88 | G23: 16865.82 | H23: 15640.33 | I23: 21771.86 | J23: 30539.18 | K23: =Assumptions!K37*K7 | L23: =Assumptions!L37*L7 | M23: =Assumptions!M37*M7 | N23: =Assumptions!N37*N7 | O23: =Assumptions!O37*O7
B24: Finance Charges/Commitment Charges | F24: 283.06 | G24: 231.8 | H24: 193.56 | I24: 223.83 | J24: 194.95 | K24: =J24 | L24: =K24 | M24: =L24 | N24: =M24 | O24: =N24
B25: Depreciation | F25: 13154.11 | G25: 13116.35 | H25: 15299.45 | I25: 16629.29 | J25: 13138.41 | K25: =J25/BS!J7*BS!K7 | L25: =K25/BS!K7*BS!L7 | M25: =L25/BS!L7*BS!M7 | N25: =M25/BS!M7*BS!N7 | O25: =N25/BS!N7*BS!O7
B26: Impairment | F26: 318.84 | G26: 461.8 | H26: 307.02 | I26: 279.74 | J26: 156.12 | K26: =J26*(1+Assumptions!K43) | L26: =K26*(1+Assumptions!L43) | M26: =L26*(1+Assumptions!M43) | N26: =M26*(1+Assumptions!N43) | O26: =N26*(1+Assumptions!O43)
B27: Provisions/Write off | F27: 444.88 | G27: 1168.55 | H27: 2320.09 | I27: 1759.96 | J27: 2093.69 | K27: =Assumptions!K46*BS!K9 | L27: =Assumptions!L46*BS!L9 | M27: =Assumptions!M46*BS!M9 | N27: =Assumptions!N46*BS!N9 | O27: =Assumptions!O46*BS!O9
A28: Total Operating Costs | F28: =SUM(F14:F27) | G28: =SUM(G14:G27) | H28: =SUM(H14:H27) | I28: =SUM(I14:I27) | J28: =SUM(J14:J27) | K28: =SUM(K14:K27) | L28: =SUM(L14:L27) | M28: =SUM(M14:M27) | ... O28: =SUM(O14:O27)
A30: Profit for the year | F30: =F11-F28 | G30: =G11-G28 | H30: =H11-H28 | I30: =I11-I28 | J30: =J11-J28 | K30: =K11-K28 | L30: =L11-L28 | M30: =M11-M28 | ... O30: =O11-O28
B31: Prior period Adjustment | F31: 284.96 | G31: 220.56 | H31: 1111.28 | I31: 277.18 | J31: -536.6 | K31: 0 | L31: 0 | M31: 0 | N31: 0 | O31: 0
A33: Profit Before Tax & Extra-Ordinary Items | F33: =F30+F31 | G33: =G30+G31 | H33: =H30+H31 | I33: =I30+I31 | J33: =J30+J31 | K33: =K30+K31 | L33: =L30+L31 | M33: =M30+M31 | ... O33: =O30+O31
B34: Provision for Income Tax | F34: 28708.43 | G34: 31684.92 | H34: 35985.88 | I34: 36839.42 | J34: 44332.47 | K34: =AVERAGE(F34/F33,G34/G33,H34/H33,I34/I33,J34/J33)*K33 | L34: =AVERAGE(G34/G33,H34/H33,I34/I33,J34/J33,K34/K33)*L33 | M34: =AVERAGE(H34/H33,I34/I33,J34/J33,K34/K33,L34/L33)*M33 | N34: =AVERAGE(I34/I33,J34/J33,K34/K33,L34/L33,M34/M33)*N33 | O34: =AVERAGE(J34/J33,K34/K33,L34/L33,M34/M33,N34/N33)*O33
B35: Provision for Deferred Tax ( written back ) | F35: -1876.4 | G35: -2779.81 | H35: -2488.39 | I35: -1032.34 | J35: -336.23 | K35: 0 | L35: 0 | M35: 0 | N35: 0 | O35: 0
B36: Provision for Income Tax for earlier year | F36: 1920.81 | G36: -355.89 | H36: 764.61 | I36: 460.3 | J36: 576.02 | K36: 0 | L36: 0 | M36: 0 | N36: 0 | O36: 0
B37: Excess Prov. For income tax written back (earlier period) | F37: -128 | H37: -0.33 | I37: -141.87 | J37: -1147.45 | K37: 0 | L37: 0 | M37: 0 | N37: 0 | O37: 0
B38: Fringe benefit Tax | F38: 344.72 | G38: 388.06 | H38: 483.7 | I38: 506.91 | J38: 0 | K38: =AVERAGE(F38/F16,G38/G16,H38/H16,I38/I16,J38/J16)*K16 | L38: =AVERAGE(G38/G16,H38/H16,I38/I16,J38/J16,K38/K16)*L16 | M38: =AVERAGE(H38/H16,I38/I16,J38/J16,K38/K16,L38/L16)*M16 | N38: =AVERAGE(I38/I16,J38/J16,K38/K16,L38/L16,M38/M16)*N16 | O38: =AVERAGE(J38/J16,K38/K16,L38/L16,M38/M16,N38/N16)*O16
A40: Profit After Tax, Before Extra Ordinary Items | F40: =F33-SUM(F34:F38) | G40: =G33-SUM(G34:G38) | H40: =H33-SUM(H34:H38) | I40: =I33-SUM(I34:I38) | J40: =J33-SUM(J34:J38) | K40: =K33-SUM(K34:K38) | L40: =L33-SUM(L34:L38) | M40: =M33-SUM(M34:M38) | ... O40: =O33-SUM(O34:O38)
B41: Extra ordinary item | F41: 343.19 | G41: 162.21 | H41: 5274.01 | I41: 32.63 | J41: 0 | K41: 0 | L41: 0 | M41: 0 | N41: 0
A42: Profit after Tax | F42: =F40+F41 | G42: =G40+G41 | H42: =H40+H41 | I42: =I40+I41 | J42: =J40+J41 | K42: =K40+K41 | L42: =L40+L41 | M42: =M40+M41 | ... O42: =O40+O41
A44: Adjustment for Restatement
B45: Change in Accounting Policies | F45: -841.43 | G45: -272.42 | H45: 779.71 | I45: 533.27 | J45: 58.49 | K45: 0 | L45: 0 | M45: 0 | N45: 0 | O45: 0
B46: Other adjustments & prior period items | F46: 3218.52 | G46: -1493.56 | H46: -5523.34 | I46: -766.36 | J46: 2372.31 | K46: 0 | L46: 0 | M46: 0 | N46: 0 | O46: 0
B47: Current Tax impact on adjustments | F47: -685.69 | G47: 2654.07 | H47: 5208.64 | I47: -2881.55 | J47: -2319.69 | K47: 0 | L47: 0 | M47: 0 | N47: 0 | O47: 0
B48: Deferred tax impact on adjustments | F48: 529.36 | G48: -1320.96 | H48: -1512.62 | I48: 2004.49 | J48: -226.97 | K48: 0 | L48: 0 | M48: 0 | N48: 0 | O48: 0
...

Sheet BS
A1: Balance Sheet
A4: (Unless otherwise specified, all financials are in INR Million) | F4: ='P&L'!F4 | G4: ='P&L'!G4 | H4: ='P&L'!H4 | I4: ='P&L'!I4 | J4: ='P&L'!J4 | K4: ='P&L'!K4 | L4: ='P&L'!L4 | M4: ='P&L'!M4 | ... O4: ='P&L'!O4
A6: Fixed Assets
B7: Gross Block | F7: ='Asset Schedule'!F8 | G7: ='Asset Schedule'!G8 | H7: ='Asset Schedule'!H8 | I7: ='Asset Schedule'!I8 | J7: ='Asset Schedule'!J8 | K7: ='Asset Schedule'!K8 | L7: ='Asset Schedule'!L8 | M7: ='Asset Schedule'!M8 | ... O7: ='Asset Schedule'!O8
B8: Less: Accumulated depreciation | F8: ='Asset Schedule'!F13 | G8: ='Asset Schedule'!G13 | H8: ='Asset Schedule'!H13 | I8: ='Asset Schedule'!I13 | J8: ='Asset Schedule'!J13 | K8: ='Asset Schedule'!K13 | L8: ='Asset Schedule'!L13 | M8: ='Asset Schedule'!M13 | ... O8: ='Asset Schedule'!O13
B9: Less: Provision for Impairment | F9: ='Asset Schedule'!F14 | G9: ='Asset Schedule'!G14 | H9: ='Asset Schedule'!H14 | I9: ='Asset Schedule'!I14 | J9: ='Asset Schedule'!J14 | K9: ='Asset Schedule'!K14 | L9: ='Asset Schedule'!L14 | M9: ='Asset Schedule'!M14 | ... O9: ='Asset Schedule'!O14
B10: Less: Other provisions | F10: ='Asset Schedule'!F15 | G10: ='Asset Schedule'!G15 | H10: ='Asset Schedule'!H15 | I10: ='Asset Schedule'!I15 | J10: ='Asset Schedule'!J15 | K10: ='Asset Schedule'!K15 | L10: ='Asset Schedule'!L15 | M10: ='Asset Schedule'!M15 | ... O10: ='Asset Schedule'!O15
B11: Net Block | F11: =F7-F8-F9-F10 | G11: =G7-G8-G9-G10 | H11: =H7-H8-H9-H10 | I11: =I7-I8-I9-I10 | J11: =J7-J8-J9-J10 | K11: =K7-K8-K9-K10 | L11: =L7-L8-L9-L10 | M11: =M7-M8-M9-M10 | ... O11: =O7-O8-O9-O10
C12: Add: Capital Work in Progress | F12: 10988.28 | G12: 12377.38 | H12: 15391.96 | I12: 18222.99 | J12: 20908.79 | K12: =Assumptions!K51*'P&L'!K7 | L12: =Assumptions!L51*'P&L'!L7 | M12: =Assumptions!M51*'P&L'!M7 | N12: =Assumptions!N51*'P&L'!N7 | O12: =Assumptions!O51*'P&L'!O7
C13: Add: Surveyed off Assets | F13: 228.11 | G13: 240.51 | H13: 291.36 | I13: 971.92 | J13: 1197.9 | K13: =Assumptions!K54*K11 | L13: =Assumptions!L54*L11 | M13: =Assumptions!M54*M11 | N13: =Assumptions!N54*N11 | O13: =Assumptions!O54*O11
B14: Total Fixed Assets | F14: =F11+F12+F13 | G14: =G11+G12+G13 | H14: =H11+H12+H13 | I14: =I11+I12+I13 | J14: =J11+J12+J13 | K14: =K11+K12+K13 | L14: =L11+L12+L13 | M14: =M11+M12+M13 | ... O14: =O11+O12+O13
B16: Investments | F16: 22445.2 | G16: 20258.77 | H16: 17179.01 | I16: 15051.79 | J16: 12821.4 | K16: =J16 | L16: =K16 | M16: =L16 | N16: =M16 | O16: =N16
B17: Net Interest in Joint Venture | J17: 2 | K17: 0 | L17: 0 | M17: 0 | N17: 0 | O17: 0
B18: Deffered tax Assets | F18: 7280.76 | G18: 6602.16 | H18: 7877.52 | I18: 9548.29 | J18: 9657.55 | K18: =J18 | L18: =K18 | M18: =L18 | N18: =M18 | O18: =N18
A19: Current Assets, loans & Advances
B20: Inventories | F20: 29134.45 | G20: 31250.08 | H20: 34073.57 | I20: 36668.67 | J20: 44017.72 | K20: =2*Assumptions!K60*('P&L'!K14+'P&L'!K15)/365-BS!J20 | L20: =2*Assumptions!L60*('P&L'!L14+'P&L'!L15)/365-BS!K20 | M20: =2*Assumptions!M60*('P&L'!M14+'P&L'!M15)/365-BS!L20 | N20: =2*Assumptions!N60*('P&L'!N14+'P&L'!N15)/365-BS!M20 | O20: =2*Assumptions!O60*('P&L'!O14+'P&L'!O15)/365-BS!N20
B21: Sundry Debtors | F21: 18840.52 | G21: 16822.29 | H21: 16571.58 | I21: 18474.84 | J21: 21686.48 | K21: =Assumptions!K57*K7 | L21: =Assumptions!L57*L7 | M21: =Assumptions!M57*M7 | N21: =Assumptions!N57*N7 | O21: =Assumptions!O57*O7
B22: Cash & Bank Balances | F22: 134272.37 | G22: 159292.66 | H22: 209614.8 | I22: 296950.09 | J22: 390777.6 | K22: =CF!K39+J22 | L22: =CF!L39+K22 | M22: =CF!M39+L22 | N22: =CF!N39+M22 | O22: =CF!O39+N22
B23: loans & Advances | F23: 65004.26 | G23: 78184.36 | H23: 102662.87 | I23: 117270.5 | J23: 86762.02 | K23: =J23*(1+Assumptions!K63) | L23: =K23*(1+Assumptions!L63) | M23: =L23*(1+Assumptions!M63) | N23: =M23*(1+Assumptions!N63) | O23: =N23*(1+Assumptions!O63)
B24: Total Current Assets | F24: =SUM(F20:F23) | G24: =SUM(G20:G23) | H24: =SUM(H20:H23) | I24: =SUM(I20:I23) | J24: =SUM(J20:J23) | K24: =SUM(K20:K23) | L24: =SUM(L20:L23) | M24: =SUM(M20:M23) | ... O24: =SUM(O20:O23)
A26: Total Assets | F26: =F14+F16+F17+F18+F24 | G26: =G14+G16+G17+G18+G24 | H26: =H14+H16+H17+H18+H24 | I26: =I14+I16+I17+I18+I24 | J26: =J14+J16+J17+J18+J24 | K26: =K14+K16+K17+K18+K24 | L26: =L14+L16+L17+L18+L24 | M26: =M14+M16+M17+M18+M24 | ... O26: =O14+O16+O17+O18+O24
A28: Liabilities & Provisions
B29: Secured Loans | F29: ='Debt Schedule'!F16 | G29: ='Debt Schedule'!G16 | H29: ='Debt Schedule'!H16 | I29: ='Debt Schedule'!I16 | J29: ='Debt Schedule'!J16 | K29: ='Debt Schedule'!K16 | L29: ='Debt Schedule'!L16 | M29: ='Debt Schedule'!M16 | ... O29: ='Debt Schedule'!O16
B30: Unsecured loans | F30: ='Debt Schedule'!F10 | G30: ='Debt Schedule'!G10 | H30: ='Debt Schedule'!H10 | I30: ='Debt Schedule'!I10 | J30: ='Debt Schedule'!J10 | K30: ='Debt Schedule'!K10 | L30: ='Debt Schedule'!L10 | M30: ='Debt Schedule'!M10 | ... O30: ='Debt Schedule'!O10
B31: Current liabilities & Provisions | F31: 216437.77 | G31: 236171.42 | H31: 305944.58 | I31: 399423.27 | J31: 413824.78 | K31: =Assumptions!K66*K7 | L31: =Assumptions!L66*L7 | M31: =Assumptions!M66*M7 | N31: =Assumptions!N66*N7 | O31: =Assumptions!O66*O7
B32: Minority Interest | I32: 18.97 | J32: 236.07 | K32: =J32 | L32: =K32 | M32: =L32 | N32: =M32 | O32: =N32
B33: Shifting & Rehabilitation Fund | F33: 4859.46 | G33: 6880.78 | H33: 9458.78 | I33: 12238.43 | J33: 14774.27 | K33: =Assumptions!K69*K7 | L33: =Assumptions!L69*L7 | M33: =Assumptions!M69*M7 | N33: =Assumptions!N69*N7 | O33: =Assumptions!O69*O7
B34: Deferred Tax Liability | F34: 4468.65 | G34: 2331.22 | H34: 1800.62 | K34: 0 | L34: 0 | M34: 0 | N34: 0 | O34: 0
A35: Total Liabilities | F35: =SUM(F29:F34) | G35: =SUM(G29:G34) | H35: =SUM(H29:H34) | I35: =SUM(I29:I34) | J35: =SUM(J29:J34) | K35: =SUM(K29:K34) | L35: =SUM(L29:L34) | M35: =SUM(M29:M34) | ... O35: =SUM(O29:O34)
A37: Net Worth represented by | F37: =F26-F35 | G37: =G26-G35 | H37: =H26-H35 | I37: =I26-I35 | J37: =J26-J35 | K37: =K26-K35 | L37: =L26-L35 | M37: =M26-M35 | ... O37: =O26-O35
B39: Share Capital | F39: =Reserves!F6 | G39: =Reserves!G6 | H39: =Reserves!H6 | I39: =Reserves!I6 | J39: =Reserves!J6 | K39: =Reserves!K6 | L39: =Reserves!L6 | M39: =Reserves!M6 | ... O39: =Reserves!O6
B40: Reserves & Surplus | F40: =Reserves!F16 | G40: =Reserves!G16 | H40: =Reserves!H16 | I40: =Reserves!I16 | J40: =Reserves!J16 | K40: =Reserves!K16 | L40: =Reserves!L16 | M40: =Reserves!M16 | ... O40: =Reserves!O16
B41: Less: Miscellaneous Expenditure(Not written off) | F41: =Reserves!F17 | G41: =Reserves!G17 | H41: =Reserves!H17 | I41: =Reserves!I17 | J41: =Reserves!J17 | K41: =Reserves!K17 | L41: =Reserves!L17 | M41: =Reserves!M17 | ... O41: =Reserves!O17
A42: Net Worth | F42: =F39+F40-F41 | G42: =G39+G40-G41 | H42: =H39+H40-H41 | I42: =I39+I40-I41 | J42: =J39+J40-J41 | K42: =K39+K40-K41 | L42: =L39+L40-L41 | M42: =M39+M40-M41 | ... O42: =O39+O40-O41
B44: Check | F44: =ABS(F37-F42)<1 | G44: =ABS(G37-G42)<1 | H44: =ABS(H37-H42)<1 | I44: =ABS(I37-I42)<1 | J44: =ABS(J37-J42)<1 | K44: =ABS(K37-K42)<1 | L44: =ABS(L37-L42)<1 | M44: =ABS(M37-M42)<1 | ... O44: =ABS(O37-O42)<1

Sheet CF
A1: Cash Flow Statement
A4: (Unless otherwise specified, all financials are in INR Million) | F4: =BS!F4 | G4: =BS!G4 | H4: =BS!H4 | I4: =BS!I4 | J4: =BS!J4 | K4: =BS!K4 | L4: =BS!L4 | M4: =BS!M4 | ... O4: =BS!O4
A6: Cashflow from Operations
B7: PAT | G7: ='P&L'!G52 | H7: ='P&L'!H52 | I7: ='P&L'!I52 | J7: ='P&L'!J52 | K7: ='P&L'!K52 | L7: ='P&L'!L52 | M7: ='P&L'!M52 | N7: ='P&L'!N52 | O7: ='P&L'!O52
B8: Less: Depreciation | G8: =BS!G8-BS!F8 | H8: =BS!H8-BS!G8 | I8: =BS!I8-BS!H8 | J8: =BS!J8-BS!I8 | K8: =BS!K8-BS!J8 | L8: =BS!L8-BS!K8 | M8: =BS!M8-BS!L8 | N8: =BS!N8-BS!M8 | O8: =BS!O8-BS!N8
B9: Less: Increase in Misc Exp. (Not written off) | G9: =BS!G41-BS!F41 | H9: =BS!H41-BS!G41 | I9: =BS!I41-BS!H41 | J9: =BS!J41-BS!I41 | K9: =BS!K41-BS!J41 | L9: =BS!L41-BS!K41 | M9: =BS!M41-BS!L41 | N9: =BS!N41-BS!M41 | O9: =BS!O41-BS!N41
B10: Less: Increase in Surveyed off Assets | G10: =BS!G13-BS!F13 | H10: =BS!H13-BS!G13 | I10: =BS!I13-BS!H13 | J10: =BS!J13-BS!I13 | K10: =BS!K13-BS!J13 | L10: =BS!L13-BS!K13 | M10: =BS!M13-BS!L13 | N10: =BS!N13-BS!M13 | O10: =BS!O13-BS!N13
B11: Less: Increase in Deferred Tax Assets | G11: =BS!G18-BS!F18 | H11: =BS!H18-BS!G18 | I11: =BS!I18-BS!H18 | J11: =BS!J18-BS!I18 | K11: =BS!K18-BS!J18 | L11: =BS!L18-BS!K18 | M11: =BS!M18-BS!L18 | N11: =BS!N18-BS!M18 | O11: =BS!O18-BS!N18
B12: Less: Increase in Inventory | G12: =BS!G20-BS!F20 | H12: =BS!H20-BS!G20 | I12: =BS!I20-BS!H20 | J12: =BS!J20-BS!I20 | K12: =BS!K20-BS!J20 | L12: =BS!L20-BS!K20 | M12: =BS!M20-BS!L20 | N12: =BS!N20-BS!M20 | O12: =BS!O20-BS!N20
B13: Less: Increase in Sundry Debtors | G13: =BS!G21-BS!F21 | H13: =BS!H21-BS!G21 | I13: =BS!I21-BS!H21 | J13: =BS!J21-BS!I21 | K13: =BS!K21-BS!J21 | L13: =BS!L21-BS!K21 | M13: =BS!M21-BS!L21 | N13: =BS!N21-BS!M21 | O13: =BS!O21-BS!N21
B14: Less: Increase in Loans and Advances | G14: =BS!G23-BS!F23 | H14: =BS!H23-BS!G23 | I14: =BS!I23-BS!H23 | J14: =BS!J23-BS!I23 | K14: =BS!K23-BS!J23 | L14: =BS!L23-BS!K23 | M14: =BS!M23-BS!L23 | N14: =BS!N23-BS!M23 | O14: =BS!O23-BS!N23
B15: Add: Increase in Current Liabilities | G15: =BS!G31-BS!F31 | H15: =BS!H31-BS!G31 | I15: =BS!I31-BS!H31 | J15: =BS!J31-BS!I31 | K15: =BS!K31-BS!J31 | L15: =BS!L31-BS!K31 | M15: =BS!M31-BS!L31 | N15: =BS!N31-BS!M31 | O15: =BS!O31-BS!N31
B16: Add: Increase in Minority Interests | G16: =BS!G32-BS!F32 | H16: =BS!H32-BS!G32 | I16: =BS!I32-BS!H32 | J16: =BS!J32-BS!I32 | K16: =BS!K32-BS!J32 | L16: =BS!L32-BS!K32 | M16: =BS!M32-BS!L32 | N16: =BS!N32-BS!M32 | O16: =BS!O32-BS!N32
B17: Add: Increase in Deferred Tax Liabilities | G17: =BS!G34-BS!F34 | H17: =BS!H34-BS!G34 | I17: =BS!I34-BS!H34 | J17: =BS!J34-BS!I34 | K17: =BS!K34-BS!J34 | L17: =BS!L34-BS!K34 | M17: =BS!M34-BS!L34 | N17: =BS!N34-BS!M34 | O17: =BS!O34-BS!N34
C18: Net Cashflow from Operations | G18: =G7-SUM(G9:G14)+SUM(G15:G17)+G8 | H18: =H7-SUM(H9:H14)+SUM(H15:H17)+H8 | I18: =I7-SUM(I9:I14)+SUM(I15:I17)+I8 | J18: =J7-SUM(J9:J14)+SUM(J15:J17)+J8 | K18: =K7-SUM(K9:K14)+SUM(K15:K17)+K8 | L18: =L7-SUM(L9:L14)+SUM(L15:L17)+L8 | M18: =M7-SUM(M9:M14)+SUM(M15:M17)+M8 | N18: =N7-SUM(N9:N14)+SUM(N15:N17)+N8 | O18: =O7-SUM(O9:O14)+SUM(O15:O17)+O8
A20: Cashflow from Investment Activities
B21: Less: Increase in Gross Block | G21: =-(BS!G7-BS!F7) | H21: =-(BS!H7-BS!G7) | I21: =-(BS!I7-BS!H7) | J21: =-(BS!J7-BS!I7) | K21: =-(BS!K7-BS!J7) | L21: =-(BS!L7-BS!K7) | M21: =-(BS!M7-BS!L7) | N21: =-(BS!N7-BS!M7) | O21: =-(BS!O7-BS!N7)
B22: Less: Increase in Provision for Impairment | G22: =(BS!G9-BS!F9) | H22: =(BS!H9-BS!G9) | I22: =(BS!I9-BS!H9) | J22: =(BS!J9-BS!I9) | K22: =(BS!K9-BS!J9) | L22: =(BS!L9-BS!K9) | M22: =(BS!M9-BS!L9) | N22: =(BS!N9-BS!M9) | O22: =(BS!O9-BS!N9)
B23: Less: Increase in Other provisions | G23: =(BS!G10-BS!F10) | H23: =(BS!H10-BS!G10) | I23: =(BS!I10-BS!H10) | J23: =(BS!J10-BS!I10) | K23: =(BS!K10-BS!J10) | L23: =(BS!L10-BS!K10) | M23: =(BS!M10-BS!L10) | N23: =(BS!N10-BS!M10) | O23: =(BS!O10-BS!N10)
B24: Less: Increase in CWIP | G24: =-(BS!G12-BS!F12) | H24: =-(BS!H12-BS!G12) | I24: =-(BS!I12-BS!H12) | J24: =-(BS!J12-BS!I12) | K24: =-(BS!K12-BS!J12) | L24: =-(BS!L12-BS!K12) | M24: =-(BS!M12-BS!L12) | N24: =-(BS!N12-BS!M12) | O24: =-(BS!O12-BS!N12)
B25: Less: Increase in Investments | G25: =-(BS!G16-BS!F16) | H25: =-(BS!H16-BS!G16) | I25: =-(BS!I16-BS!H16) | J25: =-(BS!J16-BS!I16) | K25: =-(BS!K16-BS!J16) | L25: =-(BS!L16-BS!K16) | M25: =-(BS!M16-BS!L16) | N25: =-(BS!N16-BS!M16) | O25: =-(BS!O16-BS!N16)
B26: Less: Increase in Net Interest in JV | G26: =-(BS!G17-BS!F17) | H26: =-(BS!H17-BS!G17) | I26: =-(BS!I17-BS!H17) | J26: =-(BS!J17-BS!I17) | K26: =-(BS!K17-BS!J17) | L26: =-(BS!L17-BS!K17) | M26: =-(BS!M17-BS!L17) | N26: =-(BS!N17-BS!M17) | O26: =-(BS!O17-BS!N17)
C27: Net Cashflow from Investment Activities | G27: =SUM(G21:G26) | H27: =SUM(H21:H26) | I27: =SUM(I21:I26) | J27: =SUM(J21:J26) | K27: =SUM(K21:K26) | L27: =SUM(L21:L26) | M27: =SUM(M21:M26) | N27: =SUM(N21:N26) | O27: =SUM(O21:O26)
A29: Cashflow from Financing Activities
B30: Less: Increse in Reserves | G30: =Reserves!G13-Reserves!F13 | H30: =Reserves!H13-Reserves!G13 | I30: =Reserves!I13-Reserves!H13 | J30: =Reserves!J13-Reserves!I13 | K30: =Reserves!K13-Reserves!J13 | L30: =Reserves!L13-Reserves!K13 | M30: =Reserves!M13-Reserves!L13 | N30: =Reserves!N13-Reserves!M13 | O30: =Reserves!O13-Reserves!N13
B31: Add: Transitional Provision for Employee Benefits | G31: ='P&L'!G55 | H31: ='P&L'!H55 | I31: ='P&L'!I55 | J31: ='P&L'!J55 | K31: ='P&L'!K55 | L31: ='P&L'!L55 | M31: ='P&L'!M55 | N31: ='P&L'!N55 | O31: ='P&L'!O55
B32: Less: Appropriations | G32: =-'P&L'!G64 | H32: =-'P&L'!H64 | I32: =-'P&L'!I64 | J32: =-'P&L'!J64 | K32: =-'P&L'!K64 | L32: =-'P&L'!L64 | M32: =-'P&L'!M64 | N32: =-'P&L'!N64 | O32: =-'P&L'!O64
B33: Add: Increase in Rehab Fund | G33: =BS!G33-BS!F33 | H33: =BS!H33-BS!G33 | I33: =BS!I33-BS!H33 | J33: =BS!J33-BS!I33 | K33: =BS!K33-BS!J33 | L33: =BS!L33-BS!K33 | M33: =BS!M33-BS!L33 | N33: =BS!N33-BS!M33 | O33: =BS!O33-BS!N33
B34: Add: Increase in Secured Loans | G34: =BS!G29-BS!F29 | H34: =BS!H29-BS!G29 | I34: =BS!I29-BS!H29 | J34: =BS!J29-BS!I29 | K34: =BS!K29-BS!J29 | L34: =BS!L29-BS!K29 | M34: =BS!M29-BS!L29 | N34: =BS!N29-BS!M29 | O34: =BS!O29-BS!N29
B35: Add: Increase in Unsecured Loans | G35: =BS!G30-BS!F30 | H35: =BS!H30-BS!G30 | I35: =BS!I30-BS!H30 | J35: =BS!J30-BS!I30 | K35: =BS!K30-BS!J30 | L35: =BS!L30-BS!K30 | M35: =BS!M30-BS!L30 | N35: =BS!N30-BS!M30 | O35: =BS!O30-BS!N30
B36: Add: Increase in Share Capital | G36: =BS!G39-BS!F39 | H36: =BS!H39-BS!G39 | I36: =BS!I39-BS!H39 | J36: =BS!J39-BS!I39 | K36: =BS!K39-BS!J39 | L36: =BS!L39-BS!K39 | M36: =BS!M39-BS!L39 | N36: =BS!N39-BS!M39 | O36: =BS!O39-BS!N39
C37: Net Cashflow from Financing Activities | G37: =SUM(G30:G36) | H37: =SUM(H30:H36) | I37: =SUM(I30:I36) | J37: =SUM(J30:J36) | K37: =SUM(K30:K36) | L37: =SUM(L30:L36) | M37: =SUM(M30:M36) | N37: =SUM(N30:N36) | O37: =SUM(O30:O36)
A39: Net Change in Cash | G39: =G37+G27+G18 | H39: =H37+H27+H18 | I39: =I37+I27+I18 | J39: =J37+J27+J18 | K39: =K37+K27+K18 | L39: =L37+L27+L18 | M39: =M37+M27+M18 | N39: =N37+N27+N18 | O39: =O37+O27+O18
B41: Cash Balance
C42: Opening Cash Balance | G42: =BS!F22 | H42: =G44 | I42: =H44 | J42: =I44 | K42: =J44 | L42: =K44 | M42: =L44 | N42: =M44 | O42: =N44
C43: Net Cashflow | G43: =G39 | H43: =H39 | I43: =I39 | J43: =J39 | K43: =K39 | L43: =L39 | M43: =M39 | N43: =N39 | O43: =O39
C44: Closing Cash Balance | G44: =G43+G42 | H44: =H43+H42 | I44: =I43+I42 | J44: =J43+J42 | K44: =K43+K42 | L44: =L43+L42 | M44: =M43+M42 | N44: =N43+N42 | O44: =O43+O42
A46: Cash Balance in Balance Sheet | F46: =BS!F22 | G46: =BS!G22 | H46: =BS!H22 | I46: =BS!I22 | J46: =BS!J22 | K46: =BS!K22 | L46: =BS!L22 | M46: =BS!M22 | ... O46: =BS!O22
G48: =ABS(G44-G46)<1 | H48: =ABS(H44-H46)<1 | I48: =ABS(I44-I46)<1 | J48: =ABS(J44-J46)<1 | K48: =ABS(K44-K46)<1 | L48: =ABS(L44-L46)<1 | M48: =ABS(M44-M46)<1 | N48: =ABS(N44-N46)<1 | O48: =ABS(O44-O46)<1

Sheet Reserves
A1: Reserves
A4: (Unless otherwise specified, all financials are in INR Million) | F4: =BS!F4 | G4: =BS!G4 | H4: =BS!H4 | I4: =BS!I4 | J4: =BS!J4 | K4: =BS!K4 | L4: =BS!L4 | M4: =BS!M4 | ... O4: =BS!O4
A6: Share Capital | F6: 63163.64 | G6: 63163.64 | H6: 63163.64 | I6: 63163.64 | J6: 63163.64 | K6: 63163.64 | L6: 63163.64 | M6: 63163.64 | N6: 63163.64 | O6: 63163.64
B7: Reserves
C8: Capital Reserves | F8: 165.84 | G8: 161.51 | H8: 157.23 | I8: 151.79 | J8: 104.41 | K8: =J8 | L8: =K8 | M8: =L8 | N8: =M8 | O8: =N8
C9: Capital Redemption Reserves | F9: 18083.6 | G9: 18083.6 | H9: 18083.6 | I9: 18083.6 | J9: 18083.6 | K9: =J9 | L9: =K9 | M9: =L9 | N9: =M9 | O9: =N9
C10: Reserve for Foreign Exchange Transactions | F10: 911.59 | G10: =F10+'P&L'!G59 | H10: =G10+'P&L'!H59 | I10: =H10+'P&L'!I59 | J10: =I10+'P&L'!J59 | K10: =J10+'P&L'!K59 | L10: =K10+'P&L'!L59 | M10: =L10+'P&L'!M59 | N10: =M10+'P&L'!N59 | O10: =N10+'P&L'!O59
C11: CSR Reserve | F11: 0 | G11: 0 | H11: 0 | I11: 0 | J11: 1519.06 | K11: =J11+'P&L'!K61 | L11: =K11+'P&L'!L61 | M11: =L11+'P&L'!M61 | N11: =M11+'P&L'!N61 | O11: =N11+'P&L'!O61
C12: General Reserve (Including Bond Redemption Reserve) | F12: 41888.05 | G12: 48684.97 | H12: 57397.45 | I12: 66736.3 | J12: 79480.39 | K12: =J12+'P&L'!K60 | L12: =K12+'P&L'!L60 | M12: =L12+'P&L'!M60 | N12: =M12+'P&L'!N60 | O12: =N12+'P&L'!O60
C13: Total Reserves | F13: =SUM(F8:F12) | G13: =SUM(G8:G12) | H13: =SUM(H8:H12) | I13: =SUM(I8:I12) | J13: =SUM(J8:J12) | K13: =SUM(K8:K12) | L13: =SUM(L8:L12) | M13: =SUM(M8:M12) | ... O13: =SUM(O8:O12)
C15: Balance Carried Forward | F15: ='P&L'!F66 | G15: ='P&L'!G66 | H15: ='P&L'!H66 | I15: ='P&L'!I66 | J15: ='P&L'!J66 | K15: ='P&L'!K66 | L15: ='P&L'!L66 | M15: ='P&L'!M66 | ... O15: ='P&L'!O66
A16: Total Reserve and Surplus | F16: =F13+F15 | G16: =G13+G15 | H16: =H13+H15 | I16: =I13+I15 | J16: =J13+J15 | K16: =K13+K15 | L16: =L13+L15 | M16: =M13+M15 | ... O16: =O13+O15
B17: Less: Miscellaneous Expenditure(Not written off) | F17: 0 | G17: 0 | H17: 0 | I17: 0.24 | J17: 15.35 | K17: 0 | L17: 0 | M17: 0 | N17: 0 | O17: 0
A19: Net Worth | F19: =F6+F16-F17 | G19: =G6+G16-G17 | H19: =H6+H16-H17 | I19: =I6+I16-I17 | J19: =J6+J16-J17 | K19: =K6+K16-K17 | L19: =L6+L16-L17 | M19: =M6+M16-M17 | ... O19: =O6+O16-O17

Sheet Debt Schedule
A1: Debt Schedule
A4: (Unless otherwise specified, all financials are in INR Million) | F4: ='Asset Schedule'!F4 | G4: ='Asset Schedule'!G4 | H4: ='Asset Schedule'!H4 | I4: ='Asset Schedule'!I4 | J4: ='Asset Schedule'!J4 | K4: ='Asset Schedule'!K4 | L4: ='Asset Schedule'!L4 | M4: ='Asset Schedule'!M4 | ... O4: ='Asset Schedule'!O4
A6: Unsecured Loans
B7: Opening Balance | G7: =F10 | H7: =G10 | I7: =H10 | J7: =I10 | K7: =J10 | L7: =K10 | M7: =L10 | N7: =M10 | O7: =N10
B8: Add: New Issued | G8: 0 | H8: 0 | I8: 3088.14 | J8: 0 | K8: 0 | L8: 0 | M8: 0 | N8: 0 | O8: 0
B9: Less: Repayments | G9: -2600.79 | H9: -1519.9 | I9: 0 | J9: -3480.74 | K9: 0 | L9: 0 | M9: 0 | N9: 0 | O9: 0
B10: Closing Balance | F10: 20712.72 | G10: =SUM(G7:G9) | H10: =SUM(H7:H9) | I10: =SUM(I7:I9) | J10: =SUM(J7:J9) | K10: =SUM(K7:K9) | L10: =SUM(L7:L9) | M10: =SUM(M7:M9) | N10: =SUM(N7:N9) | O10: =SUM(O7:O9)
A12: Secured Loans
B13: Opening Balance | G13: =F16 | H13: =G16 | I13: =H16 | J13: =I16 | K13: =J16 | L13: =K16 | M13: =L16 | N13: =M16 | O13: =N16
B14: Add: New Issued | G14: 849.87 | H14: 0 | I14: 0 | J14: 2864.45 | K14: 0 | L14: 0 | M14: 0 | N14: 0 | O14: 0
B15: Less: Repayments | G15: 0 | H15: -1079.98 | I15: -442.44 | J15: 0 | K15: 0 | L15: 0 | M15: 0 | N15: 0 | O15: 0
B16: Closing Balance | F16: 2477.18 | G16: =SUM(G13:G15) | H16: =SUM(H13:H15) | I16: =SUM(I13:I15) | J16: =SUM(J13:J15) | K16: =SUM(K13:K15) | L16: =SUM(L13:L15) | M16: =SUM(M13:M15) | N16: =SUM(N13:N15) | O16: =SUM(O13:O15)
B18: Average Loan Outstanding | G18: =AVERAGE(G16,G13,G10,G7) | H18: =AVERAGE(H16,H13,H10,H7) | I18: =AVERAGE(I16,I13,I10,I7) | J18: =AVERAGE(J16,J13,J10,J7) | K18: =AVERAGE(K16,K13,K10,K7) | L18: =AVERAGE(L16,L13,L10,L7) | M18: =AVERAGE(M16,M13,M10,M7) | N18: =AVERAGE(N16,N13,N10,N7) | O18: =AVERAGE(O16,O13,O10,O7)
B19: Interest Rate | D19: % | G19: 0.07611932 | H19: 0.14889786 | I19: 0.15523994 | J19: 0.12887682 | K19: 0.13 | L19: 0.13 | M19: 0.13 | N19: 0.13 | O19: 0.13
B20: Interest Expense | G20: =G18*G19 | H20: =H18*H19 | I20: =I18*I19 | J20: =J18*J19 | K20: =K18*K19 | L20: =L18*L19 | M20: =M18*M19 | N20: =N18*N19 | O20: =O18*O19

Sheet Asset Schedule
A1: Asset Schedule
A4: (Unless otherwise specified, all financials are in INR Million) | F4: =CF!F4 | G4: =CF!G4 | H4: =CF!H4 | I4: =CF!I4 | J4: =CF!J4 | K4: =CF!K4 | L4: =CF!L4 | M4: =CF!M4 | ... O4: =CF!O4
A6: Opening Gross Block | G6: =F8 | H6: =G8 | I6: =H8 | J6: =I8 | K6: =J8 | L6: =K8 | M6: =L8 | N6: =M8 | O6: =N8
B7: Addition of Asset | G7: 10283.01 | H7: 11575.26 | I7: 13957.45 | J7: 16903.31 | K7: 22800 | L7: 34875 | M7: 30000 | N7: =M7 | O7: =N7
A8: Closing Gross Block | F8: 296734.13 | G8: =G6+G7 | H8: =H6+H7 | I8: =I6+I7 | J8: =J6+J7 | K8: =K6+K7 | L8: =L6+L7 | M8: =M6+M7 | N8: =N6+N7 | O8: =O6+O7
C10: P&L Item: Depreciation Expense | F10: ='P&L'!F25 | G10: ='P&L'!G25 | H10: ='P&L'!H25 | I10: ='P&L'!I25 | J10: ='P&L'!J25 | K10: ='P&L'!K25 | L10: ='P&L'!L25 | M10: ='P&L'!M25 | ... O10: ='P&L'!O25
C11: P&L Item: Depreciation Non-Expense | G11: 8278.01 | H11: -4514.9 | I11: -8695.65 | J11: -6255.29 | K11: 0 | L11: 0 | M11: 0 | N11: 0 | O11: 0
B13: Accumulated Depreciation | F13: 177915.74 | G13: =F13+G10+G11 | H13: =G13+H10+H11 | I13: =H13+I10+I11 | J13: =I13+J10+J11 | K13: =J13+K10+K11 | L13: =K13+L10+L11 | M13: =L13+M10+M11 | N13: =M13+N10+N11 | O13: =N13+O10+O11
B14: Less: Provision for Impairment | F14: 15520.17 | G14: 3776.69 | H14: 4106.47 | I14: 4429.6 | J14: 4228.42 | K14: 4228.42 | L14: 4228.42 | M14: 4228.42 | N14: 4228.42 | O14: 4228.42
B15: Less: Other provisions | G15: 4.93 | H15: 4.04 | I15: 4.15 | J15: 3.73 | K15: 3.73 | L15: 3.73 | M15: 3.73 | N15: 3.73 | O15: 3.73
B16: Net Block | F16: =F8-SUM(F13:F15) | G16: =G8-SUM(G13:G15) | H16: =H8-SUM(H13:H15) | I16: =I8-SUM(I13:I15) | J16: =J8-SUM(J13:J15) | K16: =K8-SUM(K13:K15) | L16: =L8-SUM(L13:L15) | M16: =M8-SUM(M13:M15) | ... O16: =O8-SUM(O13:O15)

Sheet Valuation
A1: Valuation
C3: Risk Free Rate | F3: 0.075
C4: Market Rate | F4: 0.13
C5: Beta | F5: 0.9
C6: Cost of Equity | F6: =F3+F5*(F4-F3)
C7: Tax Rate | F7: 0.34
C8: Terminal Growth Rate | F8: 0.03
C9: No of shares Outstanding | D9: Millions | F9: 6316
A11: (Unless otherwise specified, all financials are in INR Million) | G11: ='Asset Schedule'!G4 | H11: ='Asset Schedule'!H4 | I11: ='Asset Schedule'!I4 | J11: ='Asset Schedule'!J4 | K11: ='Asset Schedule'!K4 | L11: ='Asset Schedule'!L4 | M11: ='Asset Schedule'!M4 | N11: ='Asset Schedule'!N4 | O11: ='Asset Schedule'!O4
A13: Net Income | G13: ='P&L'!G52 | H13: ='P&L'!H52 | I13: ='P&L'!I52 | J13: ='P&L'!J52 | K13: ='P&L'!K52 | L13: ='P&L'!L52 | M13: ='P&L'!M52 | N13: ='P&L'!N52 | O13: ='P&L'!O52
B14: Add: Depreciation | G14: ='P&L'!G25 | H14: ='P&L'!H25 | I14: ='P&L'!I25 | J14: ='P&L'!J25 | K14: ='P&L'!K25 | L14: ='P&L'!L25 | M14: ='P&L'!M25 | N14: ='P&L'!N25 | O14: ='P&L'!O25
B15: Add: Interest*(1-Tax Rate) | G15: ='P&L'!G22*(1-$F$7) | H15: ='P&L'!H22*(1-$F$7) | I15: ='P&L'!I22*(1-$F$7) | J15: ='P&L'!J22*(1-$F$7) | K15: ='P&L'!K22*(1-$F$7) | L15: ='P&L'!L22*(1-$F$7) | M15: ='P&L'!M22*(1-$F$7) | N15: ='P&L'!N22*(1-$F$7) | O15: ='P&L'!O22*(1-$F$7)
B16: Less: Fixed Capital Investment | G16: ='Asset Schedule'!G8-'Asset Schedule'!F8 | H16: ='Asset Schedule'!H8-'Asset Schedule'!G8 | I16: ='Asset Schedule'!I8-'Asset Schedule'!H8 | J16: ='Asset Schedule'!J8-'Asset Schedule'!I8 | K16: ='Asset Schedule'!K8-'Asset Schedule'!J8 | L16: ='Asset Schedule'!L8-'Asset Schedule'!K8 | M16: ='Asset Schedule'!M8-'Asset Schedule'!L8 | N16: ='Asset Schedule'!N8-'Asset Schedule'!M8 | O16: ='Asset Schedule'!O8-'Asset Schedule'!N8
B17: Less: Working Capital Investment
C18: Inventories | G18: =BS!G20-BS!F20 | H18: =BS!H20-BS!G20 | I18: =BS!I20-BS!H20 | J18: =BS!J20-BS!I20 | K18: =BS!K20-BS!J20 | L18: =BS!L20-BS!K20 | M18: =BS!M20-BS!L20 | N18: =BS!N20-BS!M20 | O18: =BS!O20-BS!N20
C19: Sundry Debtors | G19: =BS!G21-BS!F21 | H19: =BS!H21-BS!G21 | I19: =BS!I21-BS!H21 | J19: =BS!J21-BS!I21 | K19: =BS!K21-BS!J21 | L19: =BS!L21-BS!K21 | M19: =BS!M21-BS!L21 | N19: =BS!N21-BS!M21 | O19: =BS!O21-BS!N21
C20: loans & Advances | G20: =BS!G23-BS!F23 | H20: =BS!H23-BS!G23 | I20: =BS!I23-BS!H23 | J20: =BS!J23-BS!I23 | K20: =BS!K23-BS!J23 | L20: =BS!L23-BS!K23 | M20: =BS!M23-BS!L23 | N20: =BS!N23-BS!M23 | O20: =BS!O23-BS!N23
A21: Free Cash Flow to firm | G21: =G13+G14+G15-G16-SUM(G18:G20) | H21: =H13+H14+H15-H16-SUM(H18:H20) | I21: =I13+I14+I15-I16-SUM(I18:I20) | J21: =J13+J14+J15-J16-SUM(J18:J20) | K21: =K13+K14+K15-K16-SUM(K18:K20) | L21: =L13+L14+L15-L16-SUM(L18:L20) | M21: =M13+M14+M15-M16-SUM(M18:M20) | N21: =N13+N14+N15-N16-SUM(N18:N20) | O21: =O13+O14+O15-O16-SUM(O18:O20)
B22: Less: Interest*(1-Tax Rate) | G22: ='P&L'!G22*(1-$F$7) | H22: ='P&L'!H22*(1-$F$7) | I22: ='P&L'!I22*(1-$F$7) | J22: ='P&L'!J22*(1-$F$7) | K22: ='P&L'!K22*(1-$F$7) | L22: ='P&L'!L22*(1-$F$7) | M22: ='P&L'!M22*(1-$F$7) | N22: ='P&L'!N22*(1-$F$7) | O22: ='P&L'!O22*(1-$F$7)
B23: Add: Net Borrowing | G23: ='Debt Schedule'!G10-'Debt Schedule'!F10+'Debt Schedule'!G16-'Debt Schedule'!F16 | H23: ='Debt Schedule'!H10-'Debt Schedule'!G10+'Debt Schedule'!H16-'Debt Schedule'!G16 | I23: ='Debt Schedule'!I10-'Debt Schedule'!H10+'Debt Schedule'!I16-'Debt Schedule'!H16 | J23: ='Debt Schedule'!J10-'Debt Schedule'!I10+'Debt Schedule'!J16-'Debt Schedule'!I16 | K23: ='Debt Schedule'!K10-'Debt Schedule'!J10+'Debt Schedule'!K16-'Debt Schedule'!J16 | L23: ='Debt Schedule'!L10-'Debt Schedule'!K10+'Debt Schedule'!L16-'Debt Schedule'!K16 | M23: ='Debt Schedule'!M10-'Debt Schedule'!L10+'Debt Schedule'!M16-'Debt Schedule'!L16 | N23: ='Debt Schedule'!N10-'Debt Schedule'!M10+'Debt Schedule'!N16-'Debt Schedule'!M16 | O23: ='Debt Schedule'!O10-'Debt Schedule'!N10+'Debt Schedule'!O16-'Debt Schedule'!N16
A24: Free Cash Flow to Equity | G24: =G21-G22+G23 | H24: =H21-H22+H23 | I24: =I21-I22+I23 | J24: =J21-J22+J23 | K24: =K21-K22+K23 | L24: =L21-L22+L23 | M24: =M21-M22+M23 | N24: =N21-N22+N23 | O24: =O21-O22+O23
A26: Present Value of FCFE | E26: =NPV(F6,K24:O24)
A27: Terminal Value of FCFE | E27: =O24*(1+F8)/(F6-F8)/(1+F6)^5
A28: Total Free Cash Flow to Equity | E28: =E27+E26
A29: Value Per share | D29: Rs. | E29: =E28/F9
L32: Beta---------->
L34: =E29 | M34: 0.8 | N34: =M34+0.02 | O34: =N34+0.02 | P34: =O34+0.02 | Q34: =P34+0.02 | R34: =Q34+0.02 | S34: =R34+0.02 | T34: =S34+0.02 | U34: =T34+0.02 | ... W34: =V34+0.02
L35: 0.02 | M35: =TABLE($L$34,$F$8,$L35,$F$5,M$34) | N35: =TABLE($L$34,$F$8,$L35,$F$5,N$34) | O35: =TABLE($L$34,$F$8,$L35,$F$5,O$34) | P35: =TABLE($L$34,$F$8,$L35,$F$5,P$34) | Q35: =TABLE($L$34,$F$8,$L35,$F$5,Q$34) | R35: =TABLE($L$34,$F$8,$L35,$F$5,R$34) | S35: =TABLE($L$34,$F$8,$L35,$F$5,S$34) | T35: =TABLE($L$34,$F$8,$L35,$F$5,T$34) | ... W35: =TABLE($L$34,$F$8,$L35,$F$5,W$34)
L36: =L35+0.1% | M36: =TABLE($L$34,$F$8,$L36,$F$5,M$34) | N36: =TABLE($L$34,$F$8,$L36,$F$5,N$34) | O36: =TABLE($L$34,$F$8,$L36,$F$5,O$34) | P36: =TABLE($L$34,$F$8,$L36,$F$5,P$34) | Q36: =TABLE($L$34,$F$8,$L36,$F$5,Q$34) | R36: =TABLE($L$34,$F$8,$L36,$F$5,R$34) | S36: =TABLE($L$34,$F$8,$L36,$F$5,S$34) | T36: =TABLE($L$34,$F$8,$L36,$F$5,T$34) | ... W36: =TABLE($L$34,$F$8,$L36,$F$5,W$34)
L37: =L36+0.1% | M37: =TABLE($L$34,$F$8,$L37,$F$5,M$34) | N37: =TABLE($L$34,$F$8,$L37,$F$5,N$34) | O37: =TABLE($L$34,$F$8,$L37,$F$5,O$34) | P37: =TABLE($L$34,$F$8,$L37,$F$5,P$34) | Q37: =TABLE($L$34,$F$8,$L37,$F$5,Q$34) | R37: =TABLE($L$34,$F$8,$L37,$F$5,R$34) | S37: =TABLE($L$34,$F$8,$L37,$F$5,S$34) | T37: =TABLE($L$34,$F$8,$L37,$F$5,T$34) | ... W37: =TABLE($L$34,$F$8,$L37,$F$5,W$34)
L38: =L37+0.1% | M38: =TABLE($L$34,$F$8,$L38,$F$5,M$34) | N38: =TABLE($L$34,$F$8,$L38,$F$5,N$34) | O38: =TABLE($L$34,$F$8,$L38,$F$5,O$34) | P38: =TABLE($L$34,$F$8,$L38,$F$5,P$34) | Q38: =TABLE($L$34,$F$8,$L38,$F$5,Q$34) | R38: =TABLE($L$34,$F$8,$L38,$F$5,R$34) | S38: =TABLE($L$34,$F$8,$L38,$F$5,S$34) | T38: =TABLE($L$34,$F$8,$L38,$F$5,T$34) | ... W38: =TABLE($L$34,$F$8,$L38,$F$5,W$34)
L39: =L38+0.1% | M39: =TABLE($L$34,$F$8,$L39,$F$5,M$34) | N39: =TABLE($L$34,$F$8,$L39,$F$5,N$34) | O39: =TABLE($L$34,$F$8,$L39,$F$5,O$34) | P39: =TABLE($L$34,$F$8,$L39,$F$5,P$34) | Q39: =TABLE($L$34,$F$8,$L39,$F$5,Q$34) | R39: =TABLE($L$34,$F$8,$L39,$F$5,R$34) | S39: =TABLE($L$34,$F$8,$L39,$F$5,S$34) | T39: =TABLE($L$34,$F$8,$L39,$F$5,T$34) | ... W39: =TABLE($L$34,$F$8,$L39,$F$5,W$34)
L40: =L39+0.1% | M40: =TABLE($L$34,$F$8,$L40,$F$5,M$34) | N40: =TABLE($L$34,$F$8,$L40,$F$5,N$34) | O40: =TABLE($L$34,$F$8,$L40,$F$5,O$34) | P40: =TABLE($L$34,$F$8,$L40,$F$5,P$34) | Q40: =TABLE($L$34,$F$8,$L40,$F$5,Q$34) | R40: =TABLE($L$34,$F$8,$L40,$F$5,R$34) | S40: =TABLE($L$34,$F$8,$L40,$F$5,S$34) | T40: =TABLE($L$34,$F$8,$L40,$F$5,T$34) | ... W40: =TABLE($L$34,$F$8,$L40,$F$5,W$34)
L41: =L40+0.1% | M41: =TABLE($L$34,$F$8,$L41,$F$5,M$34) | N41: =TABLE($L$34,$F$8,$L41,$F$5,N$34) | O41: =TABLE($L$34,$F$8,$L41,$F$5,O$34) | P41: =TABLE($L$34,$F$8,$L41,$F$5,P$34) | Q41: =TABLE($L$34,$F$8,$L41,$F$5,Q$34) | R41: =TABLE($L$34,$F$8,$L41,$F$5,R$34) | S41: =TABLE($L$34,$F$8,$L41,$F$5,S$34) | T41: =TABLE($L$34,$F$8,$L41,$F$5,T$34) | ... W41: =TABLE($L$34,$F$8,$L41,$F$5,W$34)
L42: =L41+0.1% | M42: =TABLE($L$34,$F$8,$L42,$F$5,M$34) | N42: =TABLE($L$34,$F$8,$L42,$F$5,N$34) | O42: =TABLE($L$34,$F$8,$L42,$F$5,O$34) | P42: =TABLE($L$34,$F$8,$L42,$F$5,P$34) | Q42: =TABLE($L$34,$F$8,$L42,$F$5,Q$34) | R42: =TABLE($L$34,$F$8,$L42,$F$5,R$34) | S42: =TABLE($L$34,$F$8,$L42,$F$5,S$34) | T42: =TABLE($L$34,$F$8,$L42,$F$5,T$34) | ... W42: =TABLE($L$34,$F$8,$L42,$F$5,W$34)
L43: =L42+0.1% | M43: =TABLE($L$34,$F$8,$L43,$F$5,M$34) | N43: =TABLE($L$34,$F$8,$L43,$F$5,N$34) | O43: =TABLE($L$34,$F$8,$L43,$F$5,O$34) | P43: =TABLE($L$34,$F$8,$L43,$F$5,P$34) | Q43: =TABLE($L$34,$F$8,$L43,$F$5,Q$34) | R43: =TABLE($L$34,$F$8,$L43,$F$5,R$34) | S43: =TABLE($L$34,$F$8,$L43,$F$5,S$34) | T43: =TABLE($L$34,$F$8,$L43,$F$5,T$34) | ... W43: =TABLE($L$34,$F$8,$L43,$F$5,W$34)
K44: Terminal | L44: =L43+0.1% | M44: =TABLE($L$34,$F$8,$L44,$F$5,M$34) | N44: =TABLE($L$34,$F$8,$L44,$F$5,N$34) | O44: =TABLE($L$34,$F$8,$L44,$F$5,O$34) | P44: =TABLE($L$34,$F$8,$L44,$F$5,P$34) | Q44: =TABLE($L$34,$F$8,$L44,$F$5,Q$34) | R44: =TABLE($L$34,$F$8,$L44,$F$5,R$34) | S44: =TABLE($L$34,$F$8,$L44,$F$5,S$34) | T44: =TABLE($L$34,$F$8,$L44,$F$5,T$34) | ... W44: =TABLE($L$34,$F$8,$L44,$F$5,W$34)
K45: Growth | L45: =L44+0.1% | M45: =TABLE($L$34,$F$8,$L45,$F$5,M$34) | N45: =TABLE($L$34,$F$8,$L45,$F$5,N$34) | O45: =TABLE($L$34,$F$8,$L45,$F$5,O$34) | P45: =TABLE($L$34,$F$8,$L45,$F$5,P$34) | Q45: =TABLE($L$34,$F$8,$L45,$F$5,Q$34) | R45: =TABLE($L$34,$F$8,$L45,$F$5,R$34) | S45: =TABLE($L$34,$F$8,$L45,$F$5,S$34) | T45: =TABLE($L$34,$F$8,$L45,$F$5,T$34) | ... W45: =TABLE($L$34,$F$8,$L45,$F$5,W$34)
K46: Rate | L46: =L45+0.1% | M46: =TABLE($L$34,$F$8,$L46,$F$5,M$34) | N46: =TABLE($L$34,$F$8,$L46,$F$5,N$34) | O46: =TABLE($L$34,$F$8,$L46,$F$5,O$34) | P46: =TABLE($L$34,$F$8,$L46,$F$5,P$34) | Q46: =TABLE($L$34,$F$8,$L46,$F$5,Q$34) | R46: =TABLE($L$34,$F$8,$L46,$F$5,R$34) | S46: =TABLE($L$34,$F$8,$L46,$F$5,S$34) | T46: =TABLE($L$34,$F$8,$L46,$F$5,T$34) | ... W46: =TABLE($L$34,$F$8,$L46,$F$5,W$34)
L47: =L46+0.1% | M47: =TABLE($L$34,$F$8,$L47,$F$5,M$34) | N47: =TABLE($L$34,$F$8,$L47,$F$5,N$34) | O47: =TABLE($L$34,$F$8,$L47,$F$5,O$34) | P47: =TABLE($L$34,$F$8,$L47,$F$5,P$34) | Q47: =TABLE($L$34,$F$8,$L47,$F$5,Q$34) | R47: =TABLE($L$34,$F$8,$L47,$F$5,R$34) | S47: =TABLE($L$34,$F$8,$L47,$F$5,S$34) | T47: =TABLE($L$34,$F$8,$L47,$F$5,T$34) | ... W47: =TABLE($L$34,$F$8,$L47,$F$5,W$34)
...
