Workbook

Sheet Introduction
B1: Financial Projection Model
B3: This spreadsheet walks you through the process of developing an integrated set of financial projections.
B5: To use this model, simply complete any information asked for found in the color yellow.
B6: Example: Fill in boxes that look like this | C6: 0
B8: A number found in the color green is optional information that you can complete.
B9: Example: Check these assumptions | C9: 0
B11: Otherwise, any information found in black type is automatically calculated for you.
B12: Although the cells that are calculated are locked (or protected), you can turn off this protection to modify the sheets.
B13: To do this, select "Tools" from the menu bar at the top of the screen. Then select, "Protection."
B14: Finally, select "Unprotect Sheet" and you will be able to edit any labels or formulas.
B16: Before you begin, we need some information about your business to best customize your financial statements.
B17: Please enter the name of your business in the box below:
B19: Enter Your Business Name Here
B22: The first six worksheets in this workbook are steps you will need to complete. They are titled:
B23: 1. Required Start-Up Funds
B24: 2. Salaries and Wages
B25: 3. Fixed Operating Expenses
B26: 4. Projected Sales Forecast (2 sheets)
... B32: q

Sheet 1. Required Start-Up Funds
A1: =Introduction!B19 | M1: =NOW()
A2: Required Start-Up Funds
A6: Required Start-Up Funds | E6: Amount | G6: Totals | H6: Depreciation | J6: Notes
B7: Fixed Assets
C8: Real Estate | E8: 0
C9: Buildings | E9: 0 | H9: 20 | I9: years
C10: Leasehold Improvements | E10: 0 | H10: 7 | I10: years
C11: Equipment | E11: 0 | H11: 7 | I11: years
C12: Furniture and Fixtures | E12: 0 | H12: 5 | I12: years
C13: Vehicles | E13: 0 | H13: 5 | I13: years
C14: Other Fixed Assets | E14: 0 | H14: 5 | I14: years
B15: Total Fixed Assets | G15: =SUM(E8:E14)
B17: Operating Capital
C18: Pre-Opening Salaries and Wages | E18: 0
C19: Prepaid Insurance Premiums | E19: 0
C20: Beginning Inventory | E20: 0
C21: Legal and Accounting Fees | E21: 0
C22: Rent Deposits | E22: 0
C23: Utility Deposits | E23: 0
C24: Supplies | E24: 0
C25: Advertising and Promotions | E25: 0
C26: Licenses | E26: 0
C27: Other Initial Start-Up Costs | E27: 0
C28: Working Capital (Cash On Hand) | E28: 0
B29: Total Operating Capital | G29: =SUM(E18:E28)
A31: Total Required Funds | G31: =G15+G29
A36: Sources of Funding | E36: Amount | G36: Totals | H36: Loan Rate | I36: Term in Months | J36: Monthly Payments
B37: Owner's Cash Injection | E37: =IF(G37=0,0,G37/G42) | G37: 0
B38: Outside Investors | E38: =IF(G38=0,0,G38/G42) | G38: 0
B39: Additional Loans or Debt
C40: Commercial Loan | E40: =IF(G40=0,0,G40/G42) | G40: =(G31-E8-E9)-((G37+G38)-(E8+E9-G41)) | H40: 0.09 | I40: =7*12 | J40: =ABS(PMT(H40/12,I40,G40))
C41: Commercial Mortgage | E41: =IF(G41=0,0,G41/G42) | G41: =IF((G31-G37+G38)<(E8+E9)*0.8,G31-G37+G38,(E8+E9)*0.8) | H41: 0.09 | I41: =20*12 | J41: =ABS(PMT(H41/12,I41,G41))
A42: Total Sources of Funding | E42: =SUM(E37:E41) | G42: =SUM(G37:G41) | J42: =J40+J41
A44: =IF('9. Cash Flow Statement'!Q35>0,"A line of credit is also required in the amount of","") | G44: =IF('9. Cash Flow Statement'!Q35>0,'9. Cash Flow Statement'!Q35,"")

Sheet 2. Salaries and Wages
A1: ='1. Required Start-Up Funds'!A1 | R1: =NOW()
A2: Salaries and Wages
A6: Salaries and Related Expenses | F6: # | G6: Assumptions | I6: Wage Base | K6: Monthly | M6: Year One | N6: Year Two | O6: Year Three
A8: Percent Change | N8: 0.03 | O8: 0.03
A10: Salaries and Wages
B11: Owner's Compensation | F11: 0 | K11: 0 | M11: =K11*12 | N11: =M11*(1+$N$8) | O11: =N11*(1+$O$8)
B12: Salaries | F12: 0 | K12: 0 | M12: =K12*12 | N12: =M12*(1+$N$8) | O12: =N12*(1+$O$8)
B13: Wages
C14: Full-Time Employees | F14: 0 | K14: =M14/12 | M14: =G15*G16*52*F14 | N14: =M14*(1+$N$8) | O14: =N14*(1+$O$8)
D15: Estimated Hours Per Week | G15: 40
D16: Estimated Rate Per Hour | G16: 9
C17: Part-Time Employees | F17: 0 | K17: =M17/12 | M17: =G18*G19*52*F17 | N17: =M17*(1+$N$8) | O17: =N17*(1+$O$8)
D18: Estimated Hours Per Week | G18: 20
D19: Estimated Rate Per Hour | G19: 9
B20: Independent Contractors | K20: 0 | M20: =K20*12 | N20: =M20*(1+$N$8) | O20: =N20*(1+$O$8)
A21: Total Salaries and Wages | F21: =SUM(F11:F20) | K21: =SUM(K11:K20) | M21: =SUM(M11:M20) | N21: =SUM(N11:N20) | O21: =SUM(O11:O20)
A23: Payroll Taxes and Benefits
B24: Social Security | G24: 0.062 | I24: 102000 | K24: =K21*$G$24 | M24: =M21*$G$24 | N24: =N21*$G$24 | O24: =O21*$G$24
B25: Medicare | G25: 0.0145 | K25: =K21*$G$25 | M25: =M21*$G$25 | N25: =N21*$G$25 | O25: =O21*$G$25
B26: Federal Unemployment Tax (FUTA) | G26: 0.008 | I26: 7000 | K26: =F21*I26*G26/12 | M26: =K26*12 | N26: =M26 | O26: =N26
B27: State Unemployment Tax (SUTA) | G27: 0.027 | I27: 7000 | K27: =F21*I27*G27/12 | M27: =K27*12 | N27: =M27 | O27: =N27
B28: Employee Pension Programs | G28: 0 | K28: =G28*K21 | M28: =K28*12 | N28: =M28 | O28: =N28
B29: Worker's Compensation | G29: 0 | K29: =G29*$K$21 | M29: =K29*12 | N29: =M29*(1+N8) | O29: =N29*(1+O8)
B30: Employee Health Insurance | G30: 0 | K30: =G30*$K$21 | M30: =K30*12 | N30: =M30*(1+N8) | O30: =N30*(1+O8)
B31: Other Employee Benefit Programs | G31: 0 | K31: =G31*$K$21 | M31: =K31*12 | N31: =M31*(1+N8) | O31: =N31*(1+O8)
A32: Total Payroll Taxes and Benefits | K32: =SUM(K24:K31) | M32: =SUM(M24:M31) | N32: =SUM(N24:N31) | O32: =SUM(O24:O31)
A35: Total Salaries and Related Expenses | K35: =K21+K32 | M35: =M21+M32 | N35: =N21+N32 | O35: =O21+O32

Sheet 3. Fixed Operating Expenses
A1: ='1. Required Start-Up Funds'!A1 | Q1: =NOW()
A2: Fixed Operating Expenses
A6: Fixed Operating Expenses | G6: Monthly | I6: Year One | J6: Year Two | K6: Year Three | M6: Notes
A8: Percent Change | J8: 0.03 | K8: 0.03
A10: Expenses
B11: Advertising | G11: 0 | I11: =G11*12 | J11: =I11*(1+$J$8) | K11: =J11*(1+$K$8)
B12: Car and Truck Expenses | G12: 0 | I12: =G12*12 | J12: =I12*(1+$J$8) | K12: =J12*(1+$K$8)
B13: Commissions and Fees | G13: 0 | I13: =G13*12 | J13: =I13*(1+$J$8) | K13: =J13*(1+$K$8)
B14: Contract Labor | G14: 0 | I14: =G14*12 | J14: =I14*(1+$J$8) | K14: =J14*(1+$K$8)
B15: Credit Card and Bank Charges | G15: 0 | I15: =G15*12 | J15: =I15*(1+$J$8) | K15: =J15*(1+$K$8)
B16: Customer Discounts and Refunds | G16: 0 | I16: =G16*12 | J16: =I16*(1+$J$8) | K16: =J16*(1+$K$8)
B17: Dues and Subscriptions | G17: 0 | I17: =G17*12 | J17: =I17*(1+$J$8) | K17: =J17*(1+$K$8)
B18: Entertainment | G18: 0 | I18: =G18*12 | J18: =I18*(1+$J$8) | K18: =J18*(1+$K$8)
B19: Insurance (Liability and Property) | G19: 0 | I19: =G19*12 | J19: =I19*(1+$J$8) | K19: =J19*(1+$K$8)
B20: Internet | G20: 0 | I20: =G20*12 | J20: =I20*(1+$J$8) | K20: =J20*(1+$K$8)
B21: Legal and Professional Fees | G21: 0 | I21: =G21*12 | J21: =I21*(1+$J$8) | K21: =J21*(1+$K$8)
B22: Office Expenses | G22: 0 | I22: =G22*12 | J22: =I22*(1+$J$8) | K22: =J22*(1+$K$8)
... B30: Utilities | G30: 0 | I30: =G30*12 | J30: =I30*(1+$J$8) | K30: =J30*(1+$K$8)
A31: Total Expenses | G31: =SUM(G11:G30) | I31: =SUM(I11:I30) | J31: =SUM(J11:J30) | K31: =SUM(K11:K30)
A33: Other Expenses
B34: Depreciation | G34: =('1. Required Start-Up Funds'!E9/'1. Required Start-Up Funds'!H9)/12+('1. Required Start-Up Funds'!E10/'1. Required Start-Up Funds'!H10)/12+('1. Required Start-Up Funds'!E11/'1. Required Start-Up Funds'!H11)/12+('1. Required Start-Up Funds'!E12/'1. Required Start-Up Funds'!H12)/12+('1. Required Start-Up Funds'!E13/'1. Required Start-Up Funds'!H13)/12+('1. Required Start-Up Funds'!E14/'1. Required Start-Up Funds'!H14)/12 | I34: =G34*12 | J34: =I34 | K34: =J34
B35: Interest
C36: Commercial Loan | G36: ='20. Amoritization Schedule'!S15/12 | I36: ='20. Amoritization Schedule'!S15 | J36: ='20. Amoritization Schedule'!S19 | K36: ='20. Amoritization Schedule'!S23
C37: Commercial Mortgage | G37: ='20. Amoritization Schedule'!S35/12 | I37: ='20. Amoritization Schedule'!S35 | J37: ='20. Amoritization Schedule'!S39 | K37: ='20. Amoritization Schedule'!S43
C38: Line of Credit | G38: ='8. Income Statement'!Q62/12 | I38: ='8. Income Statement'!Q62 | J38: 0 | K38: 0
A39: Total Other Expenses | G39: =SUM(G34:G38) | I39: =SUM(I34:I38) | J39: =SUM(J34:J38) | K39: =SUM(K34:K38)
A41: Total Fixed Operating Expenses | G41: =G31+G39 | I41: =I31+I39 | J41: =J31+J39 | K41: =K31+K39

Sheet 4. Projected Sales Forecast
A1: ='1. Required Start-Up Funds'!A1 | T1: =NOW()
A2: Projected Sales Forecast
A6: Products and Services | E6: Assumptions | F6: % | H6: Month 1 | I6: Month 2 | J6: Month 3 | K6: Month 4 | L6: Month 5 | M6: Month 6 | N6: Month 7 | O6: Month 8 | P6: Month 9 | Q6: Month 10 | R6: Month 11 | S6: Month 12 | T6: Totals
A8: Product/Service A
B9: Price Per Unit | E9: 0 | F9: 1
B10: Variable Cost Per Unit | E10: 0 | F10: =IF(E9>0,E10/E9,0)
B11: Gross Margin Per Unit | E11: =E9-E10 | F11: =IF(E9>0,E11/E9,0)
B12: Projected Unit Sales
C13: Seasonality Factor | H13: =IF(H14=0,0,H14/$T$14) | I13: =IF(I14=0,0,I14/$T$14) | J13: =IF(J14=0,0,J14/$T$14) | K13: =IF(K14=0,0,K14/$T$14) | L13: =IF(L14=0,0,L14/$T$14) | M13: =IF(M14=0,0,M14/$T$14) | N13: =IF(N14=0,0,N14/$T$14) | O13: =IF(O14=0,0,O14/$T$14) | ... S13: =IF(S14=0,0,S14/$T$14) | T13: =SUM(H13:S13)
C14: Year One | H14: 0 | I14: 0 | J14: 0 | K14: 0 | L14: 0 | M14: 0 | N14: 0 | O14: 0 | P14: 0 | Q14: 0 | R14: 0 | S14: 0 | T14: =SUM(H14:S14)
C15: Year Two Growth | E15: 0.1 | H15: =IF($E$15=0,H14,(1+$E$15)*H14) | I15: =IF($E$15=0,I14,(1+$E$15)*I14) | J15: =IF($E$15=0,J14,(1+$E$15)*J14) | K15: =IF($E$15=0,K14,(1+$E$15)*K14) | L15: =IF($E$15=0,L14,(1+$E$15)*L14) | M15: =IF($E$15=0,M14,(1+$E$15)*M14) | N15: =IF($E$15=0,N14,(1+$E$15)*N14) | O15: =IF($E$15=0,O14,(1+$E$15)*O14) | ... S15: =IF($E$15=0,S14,(1+$E$15)*S14) | T15: =SUM(H15:S15)
C16: Year Three Growth | E16: 0.1 | H16: =IF($E$16=0,H15,(1+$E$16)*H15) | I16: =IF($E$16=0,I15,(1+$E$16)*I15) | J16: =IF($E$16=0,J15,(1+$E$16)*J15) | K16: =IF($E$16=0,K15,(1+$E$16)*K15) | L16: =IF($E$16=0,L15,(1+$E$16)*L15) | M16: =IF($E$16=0,M15,(1+$E$16)*M15) | N16: =IF($E$16=0,N15,(1+$E$16)*N15) | O16: =IF($E$16=0,O15,(1+$E$16)*O15) | ... S16: =IF($E$16=0,S15,(1+$E$16)*S15) | T16: =SUM(H16:S16)
B17: Fixed Expense Allocation | E17: 0.5
B19: Projected Revenue | E19: =T14*E9
B20: Variable Costs | E20: =E10*T14
B21: Gross Margin | E21: =E19-E20
B22: Fixed Expenses | E22: =E17*'3. Fixed Operating Expenses'!I41
B23: Profit | E23: =E21-E22 | F23: =IF(E9>0,E23/E19,0)
B25: Breakeven Sales Revenue | E25: =IF(E9>0,E22/F11,0)
B26: Breakeven Sales Units | E26: =IF(E9>0,E25/E9,0)
A30: Product/Service B
B31: Price Per Unit | E31: 0 | F31: 1
B32: Variable Cost Per Unit | E32: 0 | F32: =IF(E31>0,E32/E31,0)
B33: Gross Margin Per Unit | E33: =E31-E32 | F33: =IF(E31>0,E33/E31,0)
B34: Projected Unit Sales
C35: Seasonality Factor | H35: =IF(H36=0,0,H36/$T$36) | I35: =IF(I36=0,0,I36/$T$36) | J35: =IF(J36=0,0,J36/$T$36) | K35: =IF(K36=0,0,K36/$T$36) | L35: =IF(L36=0,0,L36/$T$36) | M35: =IF(M36=0,0,M36/$T$36) | N35: =IF(N36=0,0,N36/$T$36) | O35: =IF(O36=0,0,O36/$T$36) | ... S35: =IF(S36=0,0,S36/$T$36) | T35: =SUM(H35:S35)
C36: Year One | H36: 0 | I36: 0 | J36: 0 | K36: 0 | L36: 0 | M36: 0 | N36: 0 | O36: 0 | P36: 0 | Q36: 0 | R36: 0 | S36: 0 | T36: =SUM(H36:S36)
C37: Year Two Growth | E37: 0.1 | H37: =IF($E$15=0,H36,(1+$E$37)*H36) | I37: =IF($E$15=0,I36,(1+$E$37)*I36) | J37: =IF($E$15=0,J36,(1+$E$37)*J36) | K37: =IF($E$15=0,K36,(1+$E$37)*K36) | L37: =IF($E$15=0,L36,(1+$E$37)*L36) | M37: =IF($E$15=0,M36,(1+$E$37)*M36) | N37: =IF($E$15=0,N36,(1+$E$37)*N36) | O37: =IF($E$15=0,O36,(1+$E$37)*O36) | ... S37: =IF($E$15=0,S36,(1+$E$37)*S36) | T37: =SUM(H37:S37)
C38: Year Three Growth | E38: 0.1 | H38: =IF($E$16=0,H37,(1+$E$38)*H37) | I38: =IF($E$16=0,I37,(1+$E$38)*I37) | J38: =IF($E$16=0,J37,(1+$E$38)*J37) | K38: =IF($E$16=0,K37,(1+$E$38)*K37) | L38: =IF($E$16=0,L37,(1+$E$38)*L37) | M38: =IF($E$16=0,M37,(1+$E$38)*M37) | N38: =IF($E$16=0,N37,(1+$E$38)*N37) | O38: =IF($E$16=0,O37,(1+$E$38)*O37) | ... S38: =IF($E$16=0,S37,(1+$E$38)*S37) | T38: =SUM(H38:S38)
B39: Fixed Expense Allocation | E39: =(1-E17)/3
B41: Projected Revenue | E41: =T36*E31
B42: Variable Costs | E42: =E32*T36
B43: Gross Margin | E43: =E41-E42
B44: Fixed Expenses | E44: =E39*'3. Fixed Operating Expenses'!I41
B45: Profit | E45: =E43-E44 | F45: =IF(E31>0,E45/E41,0)
B47: Breakeven Sales Revenue | E47: =IF(E31>0,E44/F33,0)
B48: Breakeven Sales Units | E48: =IF(E31>0,E47/E31,0)

Sheet 5. Projected Sales Forecast (2)
A1: ='1. Required Start-Up Funds'!A1 | T1: =NOW()
A2: Projected Sales Forecast - Page 2
A6: Products and Services | E6: Assumptions | F6: % | H6: ='4. Projected Sales Forecast'!H6 | I6: ='4. Projected Sales Forecast'!I6 | J6: ='4. Projected Sales Forecast'!J6 | K6: ='4. Projected Sales Forecast'!K6 | L6: ='4. Projected Sales Forecast'!L6 | M6: ='4. Projected Sales Forecast'!M6 | N6: ='4. Projected Sales Forecast'!N6 | O6: ='4. Projected Sales Forecast'!O6 | ... S6: ='4. Projected Sales Forecast'!S6 | T6: Totals
A8: Product/Service C
B9: Price Per Unit | E9: 0 | F9: 1
B10: Variable Cost Per Unit | E10: 0 | F10: =IF(E9>0,E10/E9,0)
B11: Gross Margin Per Unit | E11: =E9-E10 | F11: =IF(E9>0,E11/E9,0)
B12: Projected Unit Sales
C13: Seasonality Factor | H13: =IF(H14=0,0,H14/$T$14) | I13: =IF(I14=0,0,I14/$T$14) | J13: =IF(J14=0,0,J14/$T$14) | K13: =IF(K14=0,0,K14/$T$14) | L13: =IF(L14=0,0,L14/$T$14) | M13: =IF(M14=0,0,M14/$T$14) | N13: =IF(N14=0,0,N14/$T$14) | O13: =IF(O14=0,0,O14/$T$14) | ... S13: =IF(S14=0,0,S14/$T$14) | T13: =SUM(H13:S13)
C14: Year One | H14: 0 | I14: 0 | J14: 0 | K14: 0 | L14: 0 | M14: 0 | N14: 0 | O14: 0 | P14: 0 | Q14: 0 | R14: 0 | S14: 0 | T14: =SUM(H14:S14)
C15: Year Two Growth | E15: 0.1 | H15: =IF($E$15=0,H14,(1+$E$15)*H14) | I15: =IF($E$15=0,I14,(1+$E$15)*I14) | J15: =IF($E$15=0,J14,(1+$E$15)*J14) | K15: =IF($E$15=0,K14,(1+$E$15)*K14) | L15: =IF($E$15=0,L14,(1+$E$15)*L14) | M15: =IF($E$15=0,M14,(1+$E$15)*M14) | N15: =IF($E$15=0,N14,(1+$E$15)*N14) | O15: =IF($E$15=0,O14,(1+$E$15)*O14) | ... S15: =IF($E$15=0,S14,(1+$E$15)*S14) | T15: =SUM(H15:S15)
C16: Year Three Growth | E16: 0.1 | H16: =IF($E$16=0,H15,(1+$E$16)*H15) | I16: =IF($E$16=0,I15,(1+$E$16)*I15) | J16: =IF($E$16=0,J15,(1+$E$16)*J15) | K16: =IF($E$16=0,K15,(1+$E$16)*K15) | L16: =IF($E$16=0,L15,(1+$E$16)*L15) | M16: =IF($E$16=0,M15,(1+$E$16)*M15) | N16: =IF($E$16=0,N15,(1+$E$16)*N15) | O16: =IF($E$16=0,O15,(1+$E$16)*O15) | ... S16: =IF($E$16=0,S15,(1+$E$16)*S15) | T16: =SUM(H16:S16)
B17: Fixed Expense Allocation | E17: =(1-('4. Projected Sales Forecast'!E17+'4. Projected Sales Forecast'!E39))/2
B19: Projected Revenue | E19: =T14*E9
B20: Variable Costs | E20: =E10*T14
B21: Gross Margin | E21: =E19-E20
B22: Fixed Expenses | E22: =E17*'3. Fixed Operating Expenses'!I41
B23: Profit | E23: =E21-E22 | F23: =IF(E9>0,E23/E19,0)
B25: Breakeven Sales Revenue | E25: =IF(E9>0,E22/F11,0)
B26: Breakeven Sales Units | E26: =IF(E9>0,E25/E9,0)
A30: Product/Service D
B31: Price Per Unit | E31: 0 | F31: 1
B32: Variable Cost Per Unit | E32: 0 | F32: =IF(E31>0,E32/E31,0)
B33: Gross Margin Per Unit | E33: =E31-E32 | F33: =IF(E31>0,E33/E31,0)
B34: Projected Unit Sales
C35: Seasonality Factor | H35: =IF(H36=0,0,H36/$T$36) | I35: =IF(I36=0,0,I36/$T$36) | J35: =IF(J36=0,0,J36/$T$36) | K35: =IF(K36=0,0,K36/$T$36) | L35: =IF(L36=0,0,L36/$T$36) | M35: =IF(M36=0,0,M36/$T$36) | N35: =IF(N36=0,0,N36/$T$36) | O35: =IF(O36=0,0,O36/$T$36) | ... S35: =IF(S36=0,0,S36/$T$36) | T35: =SUM(H35:S35)
C36: Year One | H36: 0 | I36: 0 | J36: 0 | K36: 0 | L36: 0 | M36: 0 | N36: 0 | O36: 0 | P36: 0 | Q36: 0 | R36: 0 | S36: 0 | T36: =SUM(H36:S36)
C37: Year Two Growth | E37: 0.1 | H37: =IF($E$15=0,H36,(1+$E$37)*H36) | I37: =IF($E$15=0,I36,(1+$E$37)*I36) | J37: =IF($E$15=0,J36,(1+$E$37)*J36) | K37: =IF($E$15=0,K36,(1+$E$37)*K36) | L37: =IF($E$15=0,L36,(1+$E$37)*L36) | M37: =IF($E$15=0,M36,(1+$E$37)*M36) | N37: =IF($E$15=0,N36,(1+$E$37)*N36) | O37: =IF($E$15=0,O36,(1+$E$37)*O36) | ... S37: =IF($E$15=0,S36,(1+$E$37)*S36) | T37: =SUM(H37:S37)
C38: Year Three Growth | E38: 0.1 | H38: =IF($E$16=0,H37,(1+$E$38)*H37) | I38: =IF($E$16=0,I37,(1+$E$38)*I37) | J38: =IF($E$16=0,J37,(1+$E$38)*J37) | K38: =IF($E$16=0,K37,(1+$E$38)*K37) | L38: =IF($E$16=0,L37,(1+$E$38)*L37) | M38: =IF($E$16=0,M37,(1+$E$38)*M37) | N38: =IF($E$16=0,N37,(1+$E$38)*N37) | O38: =IF($E$16=0,O37,(1+$E$38)*O37) | ... S38: =IF($E$16=0,S37,(1+$E$38)*S37) | T38: =SUM(H38:S38)
B39: Fixed Expense Allocation | E39: =1-('4. Projected Sales Forecast'!E17+'4. Projected Sales Forecast'!E39+'5. Projected Sales Forecast (2)'!E17)
B41: Projected Revenue | E41: =T36*E31
B42: Variable Costs | E42: =E32*T36
B43: Gross Margin | E43: =E41-E42
B44: Fixed Expenses | E44: =E39*'3. Fixed Operating Expenses'!I41
B45: Profit | E45: =E43-E44 | F45: =IF(E31>0,E45/E41,0)
B47: Breakeven Sales Revenue | E47: =IF(E31>0,E44/F33,0)
B48: Breakeven Sales Units | E48: =IF(E31>0,E47/E31,0)

Sheet 6. Cash Receipts-Disbursements
A1: ='1. Required Start-Up Funds'!A1 | Q1: =NOW()
A2: Cash Receipts and Disbursements
A6: Accounts Receivable Collections
B7: Percent of Collections
C8: 0 to 30 days | G8: 1
C9: 31 to 60 days | G9: 0
C10: More than 60 days | G10: 0
B11: Total Collections Percentage | G11: =SUM(G8:G10)
A13: Accounts Payable Disbursements
B14: Number of Days to Pay Suppliers
C15: 0 to 30 days | G15: 1
C16: 31 to 60 days | G16: 0
C17: More than 60 days | G17: 0
B18: Total Disbursements Percentage | G18: =SUM(G15:G17)
A20: Line of Credit Assumptions
B21: Desired Minimum Cash Balance | G21: 0
B22: Line of Credit Interest Rate | G22: 0.09
A24: Income Tax Assumptions
B25: Effective Income Tax Rate | G25: 0
J26: =IF(G28=0,0,(('1. Required Start-Up Funds'!G29-'1. Required Start-Up Funds'!E28-'1. Required Start-Up Funds'!E20-'1. Required Start-Up Funds'!E27)/'6. Cash Receipts-Disbursements'!G28)) | K26: =J26/12
A27: Amortization of Start-Up Expenses | J27: =IF(G28=0,0,('1. Required Start-Up Funds'!E27/'6. Cash Receipts-Disbursements'!G28)) | K27: =J27/12
B28: Amortization Period in Years | G28: 3 | K28: =K26+K27

Sheet 7. Beginning Balance Sheet
A1: ='1. Required Start-Up Funds'!A1
A2: Balance Sheet (For Existing Businesses Only)
F6: 39082 | G6: %
A8: Assets
B9: Current Assets
C10: Cash | F10: 0
C11: Accounts Receivable | F11: 0
C12: Inventory | F12: 0
C13: Prepaid Expenses | F13: 0
C14: Other Current | F14: 0
B15: Total Current Assets | F15: =SUM(F10:F14)
B17: Fixed Assets
C18: ='1. Required Start-Up Funds'!C8 | F18: 0
C19: ='1. Required Start-Up Funds'!C9 | F19: 0
C20: ='1. Required Start-Up Funds'!C10 | F20: 0
C21: ='1. Required Start-Up Funds'!C11 | F21: 0
C22: ='1. Required Start-Up Funds'!C12 | F22: 0
C23: ='1. Required Start-Up Funds'!C13 | F23: 0
C24: ='1. Required Start-Up Funds'!C14 | F24: 0
B25: Total Fixed Assets | F25: =SUM(F18:F24)
B27: Less: Accumulated Depreciation | F27: 0
A29: Total Assets | F29: =INT(F15+F25-F27)
A33: Liabilities and Owner's Equity
B34: Liabilities
C35: Accounts Payable | F35: 0
C36: Notes Payable | F36: 0
C37: Mortgage Payable | F37: 0
C38: Line of Credit Balance | F38: 0
B39: Total Liabilities | F39: =SUM(F35:F38)
B41: Owner's Equity
C42: Common Stock | F42: 0
C43: Retained Earnings | F43: 0
C44: Dividends Dispersed | F44: 0
B45: Total Owner's Equity | F45: =F42+F43-F44
A47: Total Liabilities and Owner's Equity | F47: =INT(F39+F45)
F50: =IF(F29=F47,"Statement Balances","Does Not Balance")

Sheet 8. Income Statement
A1: ='1. Required Start-Up Funds'!A1
A2: Projected Income Statement - Year One
E6: ='4. Projected Sales Forecast'!H6 | F6: ='4. Projected Sales Forecast'!I6 | G6: ='4. Projected Sales Forecast'!J6 | H6: ='4. Projected Sales Forecast'!K6 | I6: ='4. Projected Sales Forecast'!L6 | J6: ='4. Projected Sales Forecast'!M6 | K6: ='4. Projected Sales Forecast'!N6 | L6: ='4. Projected Sales Forecast'!O6 | ... P6: ='4. Projected Sales Forecast'!S6 | Q6: Totals
A8: Income
B9: ='4. Projected Sales Forecast'!A8 | E9: ='4. Projected Sales Forecast'!$E$9*'4. Projected Sales Forecast'!H14 | F9: ='4. Projected Sales Forecast'!$E$9*'4. Projected Sales Forecast'!I14 | G9: ='4. Projected Sales Forecast'!$E$9*'4. Projected Sales Forecast'!J14 | H9: ='4. Projected Sales Forecast'!$E$9*'4. Projected Sales Forecast'!K14 | I9: ='4. Projected Sales Forecast'!$E$9*'4. Projected Sales Forecast'!L14 | J9: ='4. Projected Sales Forecast'!$E$9*'4. Projected Sales Forecast'!M14 | K9: ='4. Projected Sales Forecast'!$E$9*'4. Projected Sales Forecast'!N14 | L9: ='4. Projected Sales Forecast'!$E$9*'4. Projected Sales Forecast'!O14 | ... P9: ='4. Projected Sales Forecast'!$E$9*'4. Projected Sales Forecast'!S14 | Q9: =SUM(E9:P9)
B10: ='4. Projected Sales Forecast'!A30 | E10: ='4. Projected Sales Forecast'!$E$31*'4. Projected Sales Forecast'!H36 | F10: ='4. Projected Sales Forecast'!$E$31*'4. Projected Sales Forecast'!I36 | G10: ='4. Projected Sales Forecast'!$E$31*'4. Projected Sales Forecast'!J36 | H10: ='4. Projected Sales Forecast'!$E$31*'4. Projected Sales Forecast'!K36 | I10: ='4. Projected Sales Forecast'!$E$31*'4. Projected Sales Forecast'!L36 | J10: ='4. Projected Sales Forecast'!$E$31*'4. Projected Sales Forecast'!M36 | K10: ='4. Projected Sales Forecast'!$E$31*'4. Projected Sales Forecast'!N36 | L10: ='4. Projected Sales Forecast'!$E$31*'4. Projected Sales Forecast'!O36 | ... P10: ='4. Projected Sales Forecast'!$E$31*'4. Projected Sales Forecast'!S36 | Q10: =SUM(E10:P10)
B11: =IF('5. Projected Sales Forecast (2)'!E9>0,'5. Projected Sales Forecast (2)'!A8,"") | E11: =IF('5. Projected Sales Forecast (2)'!$E$9>0,'5. Projected Sales Forecast (2)'!$E$9*'5. Projected Sales Forecast (2)'!H14,"") | F11: =IF('5. Projected Sales Forecast (2)'!$E$9>0,'5. Projected Sales Forecast (2)'!$E$9*'5. Projected Sales Forecast (2)'!I14,"") | G11: =IF('5. Projected Sales Forecast (2)'!$E$9>0,'5. Projected Sales Forecast (2)'!$E$9*'5. Projected Sales Forecast (2)'!J14,"") | H11: =IF('5. Projected Sales Forecast (2)'!$E$9>0,'5. Projected Sales Forecast (2)'!$E$9*'5. Projected Sales Forecast (2)'!K14,"") | I11: =IF('5. Projected Sales Forecast (2)'!$E$9>0,'5. Projected Sales Forecast (2)'!$E$9*'5. Projected Sales Forecast (2)'!L14,"") | J11: =IF('5. Projected Sales Forecast (2)'!$E$9>0,'5. Projected Sales Forecast (2)'!$E$9*'5. Projected Sales Forecast (2)'!M14,"") | K11: =IF('5. Projected Sales Forecast (2)'!$E$9>0,'5. Projected Sales Forecast (2)'!$E$9*'5. Projected Sales Forecast (2)'!N14,"") | L11: =IF('5. Projected Sales Forecast (2)'!$E$9>0,'5. Projected Sales Forecast (2)'!$E$9*'5. Projected Sales Forecast (2)'!O14,"") | ... P11: =IF('5. Projected Sales Forecast (2)'!$E$9>0,'5. Projected Sales Forecast (2)'!$E$9*'5. Projected Sales Forecast (2)'!S14,"") | Q11: =SUM(E11:P11)
B12: =IF('5. Projected Sales Forecast (2)'!E31>0,'5. Projected Sales Forecast (2)'!A30,"") | E12: =IF('5. Projected Sales Forecast (2)'!$E$31>0,'5. Projected Sales Forecast (2)'!$E$31*'5. Projected Sales Forecast (2)'!H36,"") | F12: =IF('5. Projected Sales Forecast (2)'!$E$31>0,'5. Projected Sales Forecast (2)'!$E$31*'5. Projected Sales Forecast (2)'!I36,"") | G12: =IF('5. Projected Sales Forecast (2)'!$E$31>0,'5. Projected Sales Forecast (2)'!$E$31*'5. Projected Sales Forecast (2)'!J36,"") | H12: =IF('5. Projected Sales Forecast (2)'!$E$31>0,'5. Projected Sales Forecast (2)'!$E$31*'5. Projected Sales Forecast (2)'!K36,"") | I12: =IF('5. Projected Sales Forecast (2)'!$E$31>0,'5. Projected Sales Forecast (2)'!$E$31*'5. Projected Sales Forecast (2)'!L36,"") | J12: =IF('5. Projected Sales Forecast (2)'!$E$31>0,'5. Projected Sales Forecast (2)'!$E$31*'5. Projected Sales Forecast (2)'!M36,"") | K12: =IF('5. Projected Sales Forecast (2)'!$E$31>0,'5. Projected Sales Forecast (2)'!$E$31*'5. Projected Sales Forecast (2)'!N36,"") | L12: =IF('5. Projected Sales Forecast (2)'!$E$31>0,'5. Projected Sales Forecast (2)'!$E$31*'5. Projected Sales Forecast (2)'!O36,"") | ... P12: =IF('5. Projected Sales Forecast (2)'!$E$31>0,'5. Projected Sales Forecast (2)'!$E$31*'5. Projected Sales Forecast (2)'!S36,"") | Q12: =SUM(E12:P12)
A13: Total Income | E13: =SUM(E9:E12) | F13: =SUM(F9:F12) | G13: =SUM(G9:G12) | H13: =SUM(H9:H12) | I13: =SUM(I9:I12) | J13: =SUM(J9:J12) | K13: =SUM(K9:K12) | L13: =SUM(L9:L12) | ... Q13: =SUM(Q9:Q12)
A15: Cost of Sales
B16: =B9 | E16: ='4. Projected Sales Forecast'!$E$10*'4. Projected Sales Forecast'!H14 | F16: ='4. Projected Sales Forecast'!$E$10*'4. Projected Sales Forecast'!I14 | G16: ='4. Projected Sales Forecast'!$E$10*'4. Projected Sales Forecast'!J14 | H16: ='4. Projected Sales Forecast'!$E$10*'4. Projected Sales Forecast'!K14 | I16: ='4. Projected Sales Forecast'!$E$10*'4. Projected Sales Forecast'!L14 | J16: ='4. Projected Sales Forecast'!$E$10*'4. Projected Sales Forecast'!M14 | K16: ='4. Projected Sales Forecast'!$E$10*'4. Projected Sales Forecast'!N14 | L16: ='4. Projected Sales Forecast'!$E$10*'4. Projected Sales Forecast'!O14 | ... P16: ='4. Projected Sales Forecast'!$E$10*'4. Projected Sales Forecast'!S14 | Q16: =SUM(E16:P16)
B17: =B10 | E17: ='4. Projected Sales Forecast'!$E$32*'4. Projected Sales Forecast'!H36 | F17: ='4. Projected Sales Forecast'!$E$32*'4. Projected Sales Forecast'!I36 | G17: ='4. Projected Sales Forecast'!$E$32*'4. Projected Sales Forecast'!J36 | H17: ='4. Projected Sales Forecast'!$E$32*'4. Projected Sales Forecast'!K36 | I17: ='4. Projected Sales Forecast'!$E$32*'4. Projected Sales Forecast'!L36 | J17: ='4. Projected Sales Forecast'!$E$32*'4. Projected Sales Forecast'!M36 | K17: ='4. Projected Sales Forecast'!$E$32*'4. Projected Sales Forecast'!N36 | L17: ='4. Projected Sales Forecast'!$E$32*'4. Projected Sales Forecast'!O36 | ... P17: ='4. Projected Sales Forecast'!$E$32*'4. Projected Sales Forecast'!S36 | Q17: =SUM(E17:P17)
B18: =B11 | E18: =IF('5. Projected Sales Forecast (2)'!$E$10>0,'5. Projected Sales Forecast (2)'!$E$10*'5. Projected Sales Forecast (2)'!H14,"") | F18: =IF('5. Projected Sales Forecast (2)'!$E$10>0,'5. Projected Sales Forecast (2)'!$E$10*'5. Projected Sales Forecast (2)'!I14,"") | G18: =IF('5. Projected Sales Forecast (2)'!$E$10>0,'5. Projected Sales Forecast (2)'!$E$10*'5. Projected Sales Forecast (2)'!J14,"") | H18: =IF('5. Projected Sales Forecast (2)'!$E$10>0,'5. Projected Sales Forecast (2)'!$E$10*'5. Projected Sales Forecast (2)'!K14,"") | I18: =IF('5. Projected Sales Forecast (2)'!$E$10>0,'5. Projected Sales Forecast (2)'!$E$10*'5. Projected Sales Forecast (2)'!L14,"") | J18: =IF('5. Projected Sales Forecast (2)'!$E$10>0,'5. Projected Sales Forecast (2)'!$E$10*'5. Projected Sales Forecast (2)'!M14,"") | K18: =IF('5. Projected Sales Forecast (2)'!$E$10>0,'5. Projected Sales Forecast (2)'!$E$10*'5. Projected Sales Forecast (2)'!N14,"") | L18: =IF('5. Projected Sales Forecast (2)'!$E$10>0,'5. Projected Sales Forecast (2)'!$E$10*'5. Projected Sales Forecast (2)'!O14,"") | ... P18: =IF('5. Projected Sales Forecast (2)'!$E$10>0,'5. Projected Sales Forecast (2)'!$E$10*'5. Projected Sales Forecast (2)'!S14,"") | Q18: =SUM(E18:P18)
B19: =B12 | E19: =IF('5. Projected Sales Forecast (2)'!$E$32>0,'5. Projected Sales Forecast (2)'!$E$32*'5. Projected Sales Forecast (2)'!H36,"") | F19: =IF('5. Projected Sales Forecast (2)'!$E$32>0,'5. Projected Sales Forecast (2)'!$E$32*'5. Projected Sales Forecast (2)'!I36,"") | G19: =IF('5. Projected Sales Forecast (2)'!$E$32>0,'5. Projected Sales Forecast (2)'!$E$32*'5. Projected Sales Forecast (2)'!J36,"") | H19: =IF('5. Projected Sales Forecast (2)'!$E$32>0,'5. Projected Sales Forecast (2)'!$E$32*'5. Projected Sales Forecast (2)'!K36,"") | I19: =IF('5. Projected Sales Forecast (2)'!$E$32>0,'5. Projected Sales Forecast (2)'!$E$32*'5. Projected Sales Forecast (2)'!L36,"") | J19: =IF('5. Projected Sales Forecast (2)'!$E$32>0,'5. Projected Sales Forecast (2)'!$E$32*'5. Projected Sales Forecast (2)'!M36,"") | K19: =IF('5. Projected Sales Forecast (2)'!$E$32>0,'5. Projected Sales Forecast (2)'!$E$32*'5. Projected Sales Forecast (2)'!N36,"") | L19: =IF('5. Projected Sales Forecast (2)'!$E$32>0,'5. Projected Sales Forecast (2)'!$E$32*'5. Projected Sales Forecast (2)'!O36,"") | ... P19: =IF('5. Projected Sales Forecast (2)'!$E$32>0,'5. Projected Sales Forecast (2)'!$E$32*'5. Projected Sales Forecast (2)'!S36,"") | Q19: =SUM(E19:P19)
A20: Total Cost of Sales | E20: =SUM(E16:E19) | F20: =SUM(F16:F19) | G20: =SUM(G16:G19) | H20: =SUM(H16:H19) | I20: =SUM(I16:I19) | J20: =SUM(J16:J19) | K20: =SUM(K16:K19) | L20: =SUM(L16:L19) | ... Q20: =SUM(Q16:Q19)
A22: Gross Margin | E22: =E13-E20 | F22: =F13-F20 | G22: =G13-G20 | H22: =H13-H20 | I22: =I13-I20 | J22: =J13-J20 | K22: =K13-K20 | L22: =L13-L20 | ... Q22: =Q13-Q20
A24: ='2. Salaries and Wages'!A10
B25: ='2. Salaries and Wages'!B11 | E25: ='2. Salaries and Wages'!K11 | F25: =E25 | G25: =F25 | H25: =G25 | I25: =H25 | J25: =I25 | K25: =J25 | L25: =K25 | M25: =L25 | ... P25: =O25 | Q25: =SUM(E25:P25)
B26: ='2. Salaries and Wages'!B12 | E26: ='2. Salaries and Wages'!K12 | F26: =E26 | G26: =F26 | H26: =G26 | I26: =H26 | J26: =I26 | K26: =J26 | L26: =K26 | M26: =L26 | ... P26: =O26 | Q26: =SUM(E26:P26)
B27: ='2. Salaries and Wages'!C14 | E27: ='2. Salaries and Wages'!K14 | F27: =E27 | G27: =F27 | H27: =G27 | I27: =H27 | J27: =I27 | K27: =J27 | L27: =K27 | M27: =L27 | ... P27: =O27 | Q27: =SUM(E27:P27)
B28: ='2. Salaries and Wages'!C17 | E28: ='2. Salaries and Wages'!K17 | F28: =E28 | G28: =F28 | H28: =G28 | I28: =H28 | J28: =I28 | K28: =J28 | L28: =K28 | M28: =L28 | ... P28: =O28 | Q28: =SUM(E28:P28)
B29: ='2. Salaries and Wages'!B20 | E29: ='2. Salaries and Wages'!K20 | F29: =E29 | G29: =F29 | H29: =G29 | I29: =H29 | J29: =I29 | K29: =J29 | L29: =K29 | M29: =L29 | ... P29: =O29 | Q29: =SUM(E29:P29)
B30: ='2. Salaries and Wages'!A23 | E30: ='2. Salaries and Wages'!K32 | F30: =E30 | G30: =F30 | H30: =G30 | I30: =H30 | J30: =I30 | K30: =J30 | L30: =K30 | M30: =L30 | ... P30: =O30 | Q30: =SUM(E30:P30)
A31: Total Salary and Wages | E31: =SUM(E25:E30) | F31: =SUM(F25:F30) | G31: =SUM(G25:G30) | H31: =SUM(H25:H30) | I31: =SUM(I25:I30) | J31: =SUM(J25:J30) | K31: =SUM(K25:K30) | L31: =SUM(L25:L30) | ... Q31: =SUM(Q25:Q30)
A33: Fixed Business Expenses
B34: ='3. Fixed Operating Expenses'!B11 | E34: ='3. Fixed Operating Expenses'!G11 | F34: =E34 | G34: =F34 | H34: =G34 | I34: =H34 | J34: =I34 | K34: =J34 | L34: =K34 | M34: =L34 | ... P34: =O34 | Q34: =SUM(E34:P34)
B35: ='3. Fixed Operating Expenses'!B12 | E35: ='3. Fixed Operating Expenses'!G12 | F35: =E35 | G35: =F35 | H35: =G35 | I35: =H35 | J35: =I35 | K35: =J35 | L35: =K35 | M35: =L35 | ... P35: =O35 | Q35: =SUM(E35:P35)
B36: ='3. Fixed Operating Expenses'!B13 | E36: ='3. Fixed Operating Expenses'!G13 | F36: =E36 | G36: =F36 | H36: =G36 | I36: =H36 | J36: =I36 | K36: =J36 | L36: =K36 | M36: =L36 | ... P36: =O36 | Q36: =SUM(E36:P36)
B37: ='3. Fixed Operating Expenses'!B14 | E37: ='3. Fixed Operating Expenses'!G14 | F37: =E37 | G37: =F37 | H37: =G37 | I37: =H37 | J37: =I37 | K37: =J37 | L37: =K37 | M37: =L37 | ... P37: =O37 | Q37: =SUM(E37:P37)
B38: ='3. Fixed Operating Expenses'!B15 | E38: ='3. Fixed Operating Expenses'!G15 | F38: =E38 | G38: =F38 | H38: =G38 | I38: =H38 | J38: =I38 | K38: =J38 | L38: =K38 | M38: =L38 | ... P38: =O38 | Q38: =SUM(E38:P38)
B39: ='3. Fixed Operating Expenses'!B16 | E39: ='3. Fixed Operating Expenses'!G16 | F39: =E39 | G39: =F39 | H39: =G39 | I39: =H39 | J39: =I39 | K39: =J39 | L39: =K39 | M39: =L39 | ... P39: =O39 | Q39: =SUM(E39:P39)
B40: ='3. Fixed Operating Expenses'!B17 | E40: ='3. Fixed Operating Expenses'!G17 | F40: =E40 | G40: =F40 | H40: =G40 | I40: =H40 | J40: =I40 | K40: =J40 | L40: =K40 | M40: =L40 | ... P40: =O40 | Q40: =SUM(E40:P40)
B41: ='3. Fixed Operating Expenses'!B18 | E41: ='3. Fixed Operating Expenses'!G18 | F41: =E41 | G41: =F41 | H41: =G41 | I41: =H41 | J41: =I41 | K41: =J41 | L41: =K41 | M41: =L41 | ... P41: =O41 | Q41: =SUM(E41:P41)
B42: ='3. Fixed Operating Expenses'!B19 | E42: ='3. Fixed Operating Expenses'!G19 | F42: =E42 | G42: =F42 | H42: =G42 | I42: =H42 | J42: =I42 | K42: =J42 | L42: =K42 | M42: =L42 | ... P42: =O42 | Q42: =SUM(E42:P42)
B43: ='3. Fixed Operating Expenses'!B20 | E43: ='3. Fixed Operating Expenses'!G20 | F43: =E43 | G43: =F43 | H43: =G43 | I43: =H43 | J43: =I43 | K43: =J43 | L43: =K43 | M43: =L43 | ... P43: =O43 | Q43: =SUM(E43:P43)
B44: ='3. Fixed Operating Expenses'!B21 | E44: ='3. Fixed Operating Expenses'!G21 | F44: =E44 | G44: =F44 | H44: =G44 | I44: =H44 | J44: =I44 | K44: =J44 | L44: =K44 | M44: =L44 | ... P44: =O44 | Q44: =SUM(E44:P44)
B45: ='3. Fixed Operating Expenses'!B22 | E45: ='3. Fixed Operating Expenses'!G22 | F45: =E45 | G45: =F45 | H45: =G45 | I45: =H45 | J45: =I45 | K45: =J45 | L45: =K45 | M45: =L45 | ... P45: =O45 | Q45: =SUM(E45:P45)
... B53: ='3. Fixed Operating Expenses'!B30 | E53: ='3. Fixed Operating Expenses'!G30 | F53: =E53 | G53: =F53 | H53: =G53 | I53: =H53 | J53: =I53 | K53: =J53 | L53: =K53 | M53: =L53 | ... P53: =O53 | Q53: =SUM(E53:P53)
A54: Total Fixed Business Expenses | E54: =SUM(E34:E53) | F54: =SUM(F34:F53) | G54: =SUM(G34:G53) | H54: =SUM(H34:H53) | I54: =SUM(I34:I53) | J54: =SUM(J34:J53) | K54: =SUM(K34:K53) | L54: =SUM(L34:L53) | ... Q54: =SUM(Q34:Q53)
A56: Other Expenses
...

Sheet 9. Cash Flow Statement
A1: ='1. Required Start-Up Funds'!A1
A2: Projected Cash Flow Statement - Year One
E6: ='4. Projected Sales Forecast'!H6 | F6: ='4. Projected Sales Forecast'!I6 | G6: ='4. Projected Sales Forecast'!J6 | H6: ='4. Projected Sales Forecast'!K6 | I6: ='4. Projected Sales Forecast'!L6 | J6: ='4. Projected Sales Forecast'!M6 | K6: ='4. Projected Sales Forecast'!N6 | L6: ='4. Projected Sales Forecast'!O6 | ... P6: ='4. Projected Sales Forecast'!S6 | Q6: Totals
A8: Beginning Cash Balance | E8: ='10. Balance Sheet'!F10 | F8: =E37 | G8: =F37 | H8: =G37 | I8: =H37 | J8: =I37 | K8: =J37 | L8: =K37 | M8: =L37 | ... P8: =O37
A10: Cash Inflows
B11: Income from Sales | E11: ='8. Income Statement'!E13*'6. Cash Receipts-Disbursements'!$G$8 | F11: ='8. Income Statement'!F13*'6. Cash Receipts-Disbursements'!$G$8 | G11: ='8. Income Statement'!G13*'6. Cash Receipts-Disbursements'!$G$8 | H11: ='8. Income Statement'!H13*'6. Cash Receipts-Disbursements'!$G$8 | I11: ='8. Income Statement'!I13*'6. Cash Receipts-Disbursements'!$G$8 | J11: ='8. Income Statement'!J13*'6. Cash Receipts-Disbursements'!$G$8 | K11: ='8. Income Statement'!K13*'6. Cash Receipts-Disbursements'!$G$8 | L11: ='8. Income Statement'!L13*'6. Cash Receipts-Disbursements'!$G$8 | ... P11: ='8. Income Statement'!P13*'6. Cash Receipts-Disbursements'!$G$8 | Q11: =SUM(E11:P11)
B12: Accounts Receivable | E12: 0 | F12: ='8. Income Statement'!E13*'6. Cash Receipts-Disbursements'!G9 | G12: =('8. Income Statement'!F13*'6. Cash Receipts-Disbursements'!$G$9)+('8. Income Statement'!E13*'6. Cash Receipts-Disbursements'!$G$10) | H12: =('8. Income Statement'!G13*'6. Cash Receipts-Disbursements'!$G$9)+('8. Income Statement'!F13*'6. Cash Receipts-Disbursements'!$G$10) | I12: =('8. Income Statement'!H13*'6. Cash Receipts-Disbursements'!$G$9)+('8. Income Statement'!G13*'6. Cash Receipts-Disbursements'!$G$10) | J12: =('8. Income Statement'!I13*'6. Cash Receipts-Disbursements'!$G$9)+('8. Income Statement'!H13*'6. Cash Receipts-Disbursements'!$G$10) | K12: =('8. Income Statement'!J13*'6. Cash Receipts-Disbursements'!$G$9)+('8. Income Statement'!I13*'6. Cash Receipts-Disbursements'!$G$10) | L12: =('8. Income Statement'!K13*'6. Cash Receipts-Disbursements'!$G$9)+('8. Income Statement'!J13*'6. Cash Receipts-Disbursements'!$G$10) | M12: =('8. Income Statement'!L13*'6. Cash Receipts-Disbursements'!$G$9)+('8. Income Statement'!K13*'6. Cash Receipts-Disbursements'!$G$10) | N12: =('8. Income Statement'!M13*'6. Cash Receipts-Disbursements'!$G$9)+('8. Income Statement'!L13*'6. Cash Receipts-Disbursements'!$G$10) | ... P12: =('8. Income Statement'!O13*'6. Cash Receipts-Disbursements'!$G$9)+('8. Income Statement'!N13*'6. Cash Receipts-Disbursements'!$G$10) | Q12: =SUM(E12:P12)
A13: Total Cash Inflows | E13: =SUM(E11:E12) | F13: =SUM(F11:F12) | G13: =SUM(G11:G12) | H13: =SUM(H11:H12) | I13: =SUM(I11:I12) | J13: =SUM(J11:J12) | K13: =SUM(K11:K12) | L13: =SUM(L11:L12) | ... Q13: =SUM(Q11:Q12)
A15: Cash Outflows
B16: Investing Activities
C17: New Capital Purchases | E17: 0 | F17: 0 | G17: 0 | H17: 0 | I17: 0 | J17: 0 | K17: 0 | L17: 0 | M17: 0 | N17: 0 | O17: 0 | P17: 0 | Q17: =SUM(E17:P17)
C18: Inventory Purchases | E18: 0 | F18: 0 | G18: 0 | H18: 0 | I18: 0 | J18: 0 | K18: 0 | L18: 0 | M18: 0 | N18: 0 | O18: 0 | P18: 0 | Q18: =SUM(E18:P18)
C19: Cost of Sales | E19: ='8. Income Statement'!E20*'6. Cash Receipts-Disbursements'!G15 | F19: =('8. Income Statement'!F20*'6. Cash Receipts-Disbursements'!G15)+('8. Income Statement'!E20*'6. Cash Receipts-Disbursements'!G16) | G19: =('8. Income Statement'!G20*'6. Cash Receipts-Disbursements'!$G$15)+('8. Income Statement'!F20*'6. Cash Receipts-Disbursements'!$G$16)+('8. Income Statement'!E20*'6. Cash Receipts-Disbursements'!$G$17) | H19: =('8. Income Statement'!H20*'6. Cash Receipts-Disbursements'!$G$15)+('8. Income Statement'!G20*'6. Cash Receipts-Disbursements'!$G$16)+('8. Income Statement'!F20*'6. Cash Receipts-Disbursements'!$G$17) | I19: =('8. Income Statement'!I20*'6. Cash Receipts-Disbursements'!$G$15)+('8. Income Statement'!H20*'6. Cash Receipts-Disbursements'!$G$16)+('8. Income Statement'!G20*'6. Cash Receipts-Disbursements'!$G$17) | J19: =('8. Income Statement'!J20*'6. Cash Receipts-Disbursements'!$G$15)+('8. Income Statement'!I20*'6. Cash Receipts-Disbursements'!$G$16)+('8. Income Statement'!H20*'6. Cash Receipts-Disbursements'!$G$17) | K19: =('8. Income Statement'!K20*'6. Cash Receipts-Disbursements'!$G$15)+('8. Income Statement'!J20*'6. Cash Receipts-Disbursements'!$G$16)+('8. Income Statement'!I20*'6. Cash Receipts-Disbursements'!$G$17) | L19: =('8. Income Statement'!L20*'6. Cash Receipts-Disbursements'!$G$15)+('8. Income Statement'!K20*'6. Cash Receipts-Disbursements'!$G$16)+('8. Income Statement'!J20*'6. Cash Receipts-Disbursements'!$G$17) | M19: =('8. Income Statement'!M20*'6. Cash Receipts-Disbursements'!$G$15)+('8. Income Statement'!L20*'6. Cash Receipts-Disbursements'!$G$16)+('8. Income Statement'!K20*'6. Cash Receipts-Disbursements'!$G$17) | N19: =('8. Income Statement'!N20*'6. Cash Receipts-Disbursements'!$G$15)+('8. Income Statement'!M20*'6. Cash Receipts-Disbursements'!$G$16)+('8. Income Statement'!L20*'6. Cash Receipts-Disbursements'!$G$17) | ... P19: =('8. Income Statement'!P20*'6. Cash Receipts-Disbursements'!$G$15)+('8. Income Statement'!O20*'6. Cash Receipts-Disbursements'!$G$16)+('8. Income Statement'!N20*'6. Cash Receipts-Disbursements'!$G$17) | Q19: =SUM(E19:P19)
B20: Operating Activities
C21: ='8. Income Statement'!A24 | E21: ='8. Income Statement'!E31 | F21: ='8. Income Statement'!F31 | G21: ='8. Income Statement'!G31 | H21: ='8. Income Statement'!H31 | I21: ='8. Income Statement'!I31 | J21: ='8. Income Statement'!J31 | K21: ='8. Income Statement'!K31 | L21: ='8. Income Statement'!L31 | ... P21: ='8. Income Statement'!P31 | Q21: =SUM(E21:P21)
C22: ='8. Income Statement'!A33 | E22: ='8. Income Statement'!E54 | F22: ='8. Income Statement'!F54 | G22: ='8. Income Statement'!G54 | H22: ='8. Income Statement'!H54 | I22: ='8. Income Statement'!I54 | J22: ='8. Income Statement'!J54 | K22: ='8. Income Statement'!K54 | L22: ='8. Income Statement'!L54 | ... P22: ='8. Income Statement'!P54 | Q22: =SUM(E22:P22)
C23: Taxes | E23: 0 | F23: 0 | G23: =SUM('8. Income Statement'!E63:G63) | H23: 0 | I23: 0 | J23: =SUM('8. Income Statement'!H63:J63) | K23: 0 | L23: 0 | M23: =SUM('8. Income Statement'!K63:M63) | N23: 0 | O23: 0 | P23: =SUM('8. Income Statement'!N63:P63) | Q23: =SUM(E23:P23)
B24: Financing Activities | Q24: =SUM(E24:P24)
C25: Loan Payments | E25: ='1. Required Start-Up Funds'!J42 | F25: =E25 | G25: =F25 | H25: =G25 | I25: =H25 | J25: =I25 | K25: =J25 | L25: =K25 | M25: =L25 | ... P25: =O25 | Q25: =SUM(E25:P25)
C26: Line of Credit Interest | E26: 0 | F26: =('6. Cash Receipts-Disbursements'!$G$22/12)*E40 | G26: =('6. Cash Receipts-Disbursements'!$G$22/12)*F40 | H26: =('6. Cash Receipts-Disbursements'!$G$22/12)*G40 | I26: =('6. Cash Receipts-Disbursements'!$G$22/12)*H40 | J26: =('6. Cash Receipts-Disbursements'!$G$22/12)*I40 | K26: =('6. Cash Receipts-Disbursements'!$G$22/12)*J40 | L26: =('6. Cash Receipts-Disbursements'!$G$22/12)*K40 | M26: =('6. Cash Receipts-Disbursements'!$G$22/12)*L40 | ... P26: =('6. Cash Receipts-Disbursements'!$G$22/12)*O40 | Q26: =SUM(E26:P26)
C27: Line of Credit Repayments | E27: 0 | F27: 0 | G27: 0 | H27: 0 | I27: 0 | J27: 0 | K27: 0 | L27: 0 | M27: 0 | N27: 0 | O27: 0 | P27: 0 | Q27: =SUM(E27:P27)
C28: Dividends Paid | E28: 0 | F28: 0 | G28: 0 | H28: 0 | I28: 0 | J28: 0 | K28: 0 | L28: 0 | M28: 0 | N28: 0 | O28: 0 | P28: 0 | Q28: =SUM(E28:P28)
A29: Total Cash Outflows | E29: =SUM(E17:E28) | F29: =SUM(F17:F28) | G29: =SUM(G17:G28) | H29: =SUM(H17:H28) | I29: =SUM(I17:I28) | J29: =SUM(J17:J28) | K29: =SUM(K17:K28) | L29: =SUM(L17:L28) | ... Q29: =SUM(Q17:Q28)
A31: Cash Flow | E31: =E13-E29 | F31: =F13-F29 | G31: =G13-G29 | H31: =H13-H29 | I31: =I13-I29 | J31: =J13-J29 | K31: =K13-K29 | L31: =L13-L29 | ... Q31: =Q13-Q29
A33: Operating Cash Balance | E33: =E8+E31 | F33: =F8+F31 | G33: =G8+G31 | H33: =H8+H31 | I33: =I8+I31 | J33: =J8+J31 | K33: =K8+K31 | L33: =L8+L31 | ... P33: =P8+P31
A35: Line of Credit Drawdowns | E35: =IF((E33-'6. Cash Receipts-Disbursements'!$G$21)<0,'6. Cash Receipts-Disbursements'!$G$21-'9. Cash Flow Statement'!E33,0) | F35: =IF((F33-'6. Cash Receipts-Disbursements'!$G$21)<0,'6. Cash Receipts-Disbursements'!$G$21-'9. Cash Flow Statement'!F33,0) | G35: =IF((G33-'6. Cash Receipts-Disbursements'!$G$21)<0,'6. Cash Receipts-Disbursements'!$G$21-'9. Cash Flow Statement'!G33,0) | H35: =IF((H33-'6. Cash Receipts-Disbursements'!$G$21)<0,'6. Cash Receipts-Disbursements'!$G$21-'9. Cash Flow Statement'!H33,0) | I35: =IF((I33-'6. Cash Receipts-Disbursements'!$G$21)<0,'6. Cash Receipts-Disbursements'!$G$21-'9. Cash Flow Statement'!I33,0) | J35: =IF((J33-'6. Cash Receipts-Disbursements'!$G$21)<0,'6. Cash Receipts-Disbursements'!$G$21-'9. Cash Flow Statement'!J33,0) | K35: =IF((K33-'6. Cash Receipts-Disbursements'!$G$21)<0,'6. Cash Receipts-Disbursements'!$G$21-'9. Cash Flow Statement'!K33,0) | L35: =IF((L33-'6. Cash Receipts-Disbursements'!$G$21)<0,'6. Cash Receipts-Disbursements'!$G$21-'9. Cash Flow Statement'!L33,0) | ... P35: =IF((P33-'6. Cash Receipts-Disbursements'!$G$21)<0,'6. Cash Receipts-Disbursements'!$G$21-'9. Cash Flow Statement'!P33,0) | Q35: =SUM(E35:P35)
A37: Ending Cash Balance | E37: =E33+E35 | F37: =F33+F35 | G37: =G33+G35 | H37: =H33+H35 | I37: =I33+I35 | J37: =J33+J35 | K37: =K33+K35 | L37: =L33+L35 | ... P37: =P33+P35
A40: Line of Credit Balance | E40: =E35 | F40: =E40+F35-F27 | G40: =F40+G35-G27 | H40: =G40+H35-H27 | I40: =H40+I35-I27 | J40: =I40+J35-J27 | K40: =J40+K35-K27 | L40: =K40+L35-L27 | M40: =L40+M35-M27 | ... P40: =O40+P35-P27

Sheet 10. Balance Sheet
A1: ='1. Required Start-Up Funds'!A1
A2: Balance Sheet - Year One
F6: Base Period | I6: End of Year One
A8: Assets
B9: Current Assets
C10: Cash | F10: ='1. Required Start-Up Funds'!E28+'7. Beginning Balance Sheet'!F10 | I10: ='9. Cash Flow Statement'!P37
C11: Accounts Receivable | F11: ='7. Beginning Balance Sheet'!F11 | I11: =F11+'8. Income Statement'!Q13-'9. Cash Flow Statement'!Q13
C12: Inventory | F12: ='1. Required Start-Up Funds'!E20+'7. Beginning Balance Sheet'!F12 | I12: =F12
C13: Prepaid Expenses | F13: ='1. Required Start-Up Funds'!G29-'1. Required Start-Up Funds'!E28-'1. Required Start-Up Funds'!E20-'1. Required Start-Up Funds'!E27+'7. Beginning Balance Sheet'!F13 | I13: =F13-'6. Cash Receipts-Disbursements'!J26
C14: Other Current | F14: ='1. Required Start-Up Funds'!E27 | I14: =F14-'6. Cash Receipts-Disbursements'!J27
B15: Total Current Assets | F15: =SUM(F10:F14) | I15: =SUM(I10:I14)
B17: Fixed Assets
C18: ='1. Required Start-Up Funds'!C8 | F18: ='1. Required Start-Up Funds'!E8+'7. Beginning Balance Sheet'!F18 | I18: =F18
C19: ='1. Required Start-Up Funds'!C9 | F19: ='1. Required Start-Up Funds'!E9+'7. Beginning Balance Sheet'!F19 | I19: =F19
C20: ='1. Required Start-Up Funds'!C10 | F20: ='1. Required Start-Up Funds'!E10+'7. Beginning Balance Sheet'!F20 | I20: =F20
C21: ='1. Required Start-Up Funds'!C11 | F21: ='1. Required Start-Up Funds'!E11+'7. Beginning Balance Sheet'!F21 | I21: =F21
C22: ='1. Required Start-Up Funds'!C12 | F22: ='1. Required Start-Up Funds'!E12+'7. Beginning Balance Sheet'!F22 | I22: =F22
C23: ='1. Required Start-Up Funds'!C13 | F23: ='1. Required Start-Up Funds'!E13+'7. Beginning Balance Sheet'!F23 | I23: =F23
C24: ='1. Required Start-Up Funds'!C14 | F24: ='7. Beginning Balance Sheet'!F24+'1. Required Start-Up Funds'!E14 | I24: =F24+'9. Cash Flow Statement'!Q17
B25: Total Fixed Assets | F25: =SUM(F18:F24) | I25: =SUM(I18:I24)
B27: Less: Accumulated Depreciation | F27: ='7. Beginning Balance Sheet'!F27 | I27: =F27+'8. Income Statement'!Q58
A29: Total Assets | F29: =INT(F15+F25-F27) | I29: =INT(I15+I25-I27)
A33: Liabilities and Owner's Equity
B34: Liabilities
C35: Accounts Payable | F35: ='7. Beginning Balance Sheet'!F35 | I35: ='8. Income Statement'!Q20-'9. Cash Flow Statement'!Q19+F35
C36: Notes Payable | F36: ='1. Required Start-Up Funds'!G40+'7. Beginning Balance Sheet'!F36 | I36: ='20. Amoritization Schedule'!R17+'7. Beginning Balance Sheet'!F36
C37: Mortgage Payable | F37: ='1. Required Start-Up Funds'!G41+'7. Beginning Balance Sheet'!F37 | I37: ='20. Amoritization Schedule'!R37+'7. Beginning Balance Sheet'!F37
C38: Line of Credit Balance | F38: ='7. Beginning Balance Sheet'!F38 | I38: ='9. Cash Flow Statement'!P40+F38
B39: Total Liabilities | F39: =SUM(F35:F38) | I39: =SUM(I35:I38)
B41: Owner's Equity
C42: Common Stock | F42: ='1. Required Start-Up Funds'!G37+'1. Required Start-Up Funds'!G38+'7. Beginning Balance Sheet'!F42 | I42: =F42
C43: Retained Earnings | F43: ='7. Beginning Balance Sheet'!F43 | I43: ='8. Income Statement'!Q66+F43
C44: Dividends Dispersed | F44: ='7. Beginning Balance Sheet'!F44 | I44: ='9. Cash Flow Statement'!Q28+F44
B45: Total Owner's Equity | F45: =F42+F43-F44 | I45: =I42+I43-I44
A47: Total Liabilities and Owner's Equity | F47: =INT(F39+F45) | I47: =INT(I39+I45)
F50: =IF(F29=F47,"Statement Balances","Does Not Balance") | I50: =IF(I29-I47=0,"Statement Balances","Does Not Balance")

Sheet 11. Year End Summary
A1: ='1. Required Start-Up Funds'!A1
A2: Year End Summary
F6: Year One | G6: % | I6: Year Two | J6: % | L6: Year Three | M6: %
A8: ='8. Income Statement'!A8
B9: ='8. Income Statement'!B9 | F9: ='8. Income Statement'!Q9 | I9: ='12. Income Statement (2)'!Q9 | L9: ='15. Income Statement (3)'!Q9
B10: ='8. Income Statement'!B10 | F10: ='8. Income Statement'!Q10 | I10: ='12. Income Statement (2)'!Q10 | L10: ='15. Income Statement (3)'!Q10
B11: ='8. Income Statement'!B11 | F11: ='8. Income Statement'!Q11 | I11: ='12. Income Statement (2)'!Q11 | L11: ='15. Income Statement (3)'!Q11
B12: ='8. Income Statement'!B12 | F12: ='8. Income Statement'!Q12 | I12: ='12. Income Statement (2)'!Q12 | L12: ='15. Income Statement (3)'!Q12
A13: ='8. Income Statement'!A13 | F13: ='8. Income Statement'!Q13 | G13: 1 | I13: =SUM(I9:I12) | J13: 1 | L13: =SUM(L9:L12) | M13: 1
A15: ='8. Income Statement'!A15
B16: ='8. Income Statement'!B16 | F16: ='8. Income Statement'!Q16 | I16: ='12. Income Statement (2)'!Q16 | L16: ='15. Income Statement (3)'!Q16
B17: ='8. Income Statement'!B17 | F17: ='8. Income Statement'!Q17 | I17: ='12. Income Statement (2)'!Q17 | L17: ='15. Income Statement (3)'!Q17
B18: ='8. Income Statement'!B18 | F18: ='8. Income Statement'!Q18 | I18: ='12. Income Statement (2)'!Q18 | L18: ='15. Income Statement (3)'!Q18
B19: ='8. Income Statement'!B19 | F19: ='8. Income Statement'!Q19 | I19: ='12. Income Statement (2)'!Q19 | L19: ='15. Income Statement (3)'!Q19
A20: ='8. Income Statement'!A20 | F20: =SUM(F16:F19) | G20: =IF(F20=0,0,F20/F13) | I20: =SUM(I16:I19) | J20: =IF(I20=0,0,I20/I13) | L20: =SUM(L16:L19) | M20: =IF(L20=0,0,L20/L13)
A22: ='8. Income Statement'!A22 | F22: ='8. Income Statement'!Q22 | G22: =IF(F22=0,0,F22/F13) | I22: ='12. Income Statement (2)'!Q22 | J22: =IF(I22=0,0,I22/I13) | L22: ='15. Income Statement (3)'!Q22 | M22: =IF(L22=0,0,L22/L13)
A24: ='8. Income Statement'!A24
B25: ='8. Income Statement'!B25 | F25: ='8. Income Statement'!Q25 | I25: ='12. Income Statement (2)'!Q25 | L25: ='15. Income Statement (3)'!Q25
B26: ='8. Income Statement'!B26 | F26: ='8. Income Statement'!Q26 | I26: ='12. Income Statement (2)'!Q26 | L26: ='15. Income Statement (3)'!Q26
B27: ='8. Income Statement'!B27 | F27: ='8. Income Statement'!Q27 | I27: ='12. Income Statement (2)'!Q27 | L27: ='15. Income Statement (3)'!Q27
B28: ='8. Income Statement'!B28 | F28: ='8. Income Statement'!Q28 | I28: ='12. Income Statement (2)'!Q28 | L28: ='15. Income Statement (3)'!Q28
B29: ='8. Income Statement'!B29 | F29: ='8. Income Statement'!Q29 | I29: ='12. Income Statement (2)'!Q29 | L29: ='15. Income Statement (3)'!Q29
B30: ='8. Income Statement'!B30 | F30: ='8. Income Statement'!Q30 | I30: ='12. Income Statement (2)'!Q30 | L30: ='15. Income Statement (3)'!Q30
A31: ='8. Income Statement'!A31 | F31: =SUM(F25:F30) | G31: =IF(F31=0,0,F31/F13) | I31: =SUM(I25:I30) | J31: =IF(I31=0,0,I31/I13) | L31: =SUM(L25:L30) | M31: =IF(L31=0,0,L31/L13)
A33: ='8. Income Statement'!A33
B34: ='8. Income Statement'!B34 | F34: ='8. Income Statement'!Q34 | I34: ='12. Income Statement (2)'!Q34 | L34: ='15. Income Statement (3)'!Q34
B35: ='8. Income Statement'!B35 | F35: ='8. Income Statement'!Q35 | I35: ='12. Income Statement (2)'!Q35 | L35: ='15. Income Statement (3)'!Q35
B36: ='8. Income Statement'!B36 | F36: ='8. Income Statement'!Q36 | I36: ='12. Income Statement (2)'!Q36 | L36: ='15. Income Statement (3)'!Q36
B37: ='8. Income Statement'!B37 | F37: ='8. Income Statement'!Q37 | I37: ='12. Income Statement (2)'!Q37 | L37: ='15. Income Statement (3)'!Q37
B38: ='8. Income Statement'!B38 | F38: ='8. Income Statement'!Q38 | I38: ='12. Income Statement (2)'!Q38 | L38: ='15. Income Statement (3)'!Q38
B39: ='8. Income Statement'!B39 | F39: ='8. Income Statement'!Q39 | I39: ='12. Income Statement (2)'!Q39 | L39: ='15. Income Statement (3)'!Q39
B40: ='8. Income Statement'!B40 | F40: ='8. Income Statement'!Q40 | I40: ='12. Income Statement (2)'!Q40 | L40: ='15. Income Statement (3)'!Q40
B41: ='8. Income Statement'!B41 | F41: ='8. Income Statement'!Q41 | I41: ='12. Income Statement (2)'!Q41 | L41: ='15. Income Statement (3)'!Q41
B42: ='8. Income Statement'!B42 | F42: ='8. Income Statement'!Q42 | I42: ='12. Income Statement (2)'!Q42 | L42: ='15. Income Statement (3)'!Q42
B43: ='8. Income Statement'!B43 | F43: ='8. Income Statement'!Q43 | I43: ='12. Income Statement (2)'!Q43 | L43: ='15. Income Statement (3)'!Q43
B44: ='8. Income Statement'!B44 | F44: ='8. Income Statement'!Q44 | I44: ='12. Income Statement (2)'!Q44 | L44: ='15. Income Statement (3)'!Q44
B45: ='8. Income Statement'!B45 | F45: ='8. Income Statement'!Q45 | I45: ='12. Income Statement (2)'!Q45 | L45: ='15. Income Statement (3)'!Q45
... B53: ='8. Income Statement'!B53 | F53: ='8. Income Statement'!Q53 | I53: ='12. Income Statement (2)'!Q53 | L53: ='15. Income Statement (3)'!Q53
A54: ='8. Income Statement'!A54 | F54: =SUM(F34:F53) | G54: =IF(F54=0,0,F54/F13) | I54: =SUM(I34:I53) | J54: =IF(I54=0,0,I54/I13) | L54: =SUM(L34:L53) | M54: =IF(L54=0,0,L54/L13)
A56: ='8. Income Statement'!A56
...

Sheet 12. Income Statement (2)
A1: ='1. Required Start-Up Funds'!A1
A2: Projected Income Statement - Year Two
E6: ='4. Projected Sales Forecast'!H6 | F6: ='4. Projected Sales Forecast'!I6 | G6: ='4. Projected Sales Forecast'!J6 | H6: ='4. Projected Sales Forecast'!K6 | I6: ='4. Projected Sales Forecast'!L6 | J6: ='4. Projected Sales Forecast'!M6 | K6: ='4. Projected Sales Forecast'!N6 | L6: ='4. Projected Sales Forecast'!O6 | ... P6: ='4. Projected Sales Forecast'!S6 | Q6: Totals
A8: Income
B9: ='4. Projected Sales Forecast'!A8 | E9: ='4. Projected Sales Forecast'!$E$9*'4. Projected Sales Forecast'!H15 | F9: ='4. Projected Sales Forecast'!$E$9*'4. Projected Sales Forecast'!I15 | G9: ='4. Projected Sales Forecast'!$E$9*'4. Projected Sales Forecast'!J15 | H9: ='4. Projected Sales Forecast'!$E$9*'4. Projected Sales Forecast'!K15 | I9: ='4. Projected Sales Forecast'!$E$9*'4. Projected Sales Forecast'!L15 | J9: ='4. Projected Sales Forecast'!$E$9*'4. Projected Sales Forecast'!M15 | K9: ='4. Projected Sales Forecast'!$E$9*'4. Projected Sales Forecast'!N15 | L9: ='4. Projected Sales Forecast'!$E$9*'4. Projected Sales Forecast'!O15 | ... P9: ='4. Projected Sales Forecast'!$E$9*'4. Projected Sales Forecast'!S15 | Q9: =SUM(E9:P9)
B10: ='4. Projected Sales Forecast'!A30 | E10: ='4. Projected Sales Forecast'!$E$31*'4. Projected Sales Forecast'!H37 | F10: ='4. Projected Sales Forecast'!$E$31*'4. Projected Sales Forecast'!I37 | G10: ='4. Projected Sales Forecast'!$E$31*'4. Projected Sales Forecast'!J37 | H10: ='4. Projected Sales Forecast'!$E$31*'4. Projected Sales Forecast'!K37 | I10: ='4. Projected Sales Forecast'!$E$31*'4. Projected Sales Forecast'!L37 | J10: ='4. Projected Sales Forecast'!$E$31*'4. Projected Sales Forecast'!M37 | K10: ='4. Projected Sales Forecast'!$E$31*'4. Projected Sales Forecast'!N37 | L10: ='4. Projected Sales Forecast'!$E$31*'4. Projected Sales Forecast'!O37 | ... P10: ='4. Projected Sales Forecast'!$E$31*'4. Projected Sales Forecast'!S37 | Q10: =SUM(E10:P10)
B11: =IF('5. Projected Sales Forecast (2)'!E9>0,'5. Projected Sales Forecast (2)'!A8,"") | E11: =IF('5. Projected Sales Forecast (2)'!$E$9>0,'5. Projected Sales Forecast (2)'!$E$9*'5. Projected Sales Forecast (2)'!H15,"") | F11: =IF('5. Projected Sales Forecast (2)'!$E$9>0,'5. Projected Sales Forecast (2)'!$E$9*'5. Projected Sales Forecast (2)'!I15,"") | G11: =IF('5. Projected Sales Forecast (2)'!$E$9>0,'5. Projected Sales Forecast (2)'!$E$9*'5. Projected Sales Forecast (2)'!J15,"") | H11: =IF('5. Projected Sales Forecast (2)'!$E$9>0,'5. Projected Sales Forecast (2)'!$E$9*'5. Projected Sales Forecast (2)'!K15,"") | I11: =IF('5. Projected Sales Forecast (2)'!$E$9>0,'5. Projected Sales Forecast (2)'!$E$9*'5. Projected Sales Forecast (2)'!L15,"") | J11: =IF('5. Projected Sales Forecast (2)'!$E$9>0,'5. Projected Sales Forecast (2)'!$E$9*'5. Projected Sales Forecast (2)'!M15,"") | K11: =IF('5. Projected Sales Forecast (2)'!$E$9>0,'5. Projected Sales Forecast (2)'!$E$9*'5. Projected Sales Forecast (2)'!N15,"") | L11: =IF('5. Projected Sales Forecast (2)'!$E$9>0,'5. Projected Sales Forecast (2)'!$E$9*'5. Projected Sales Forecast (2)'!O15,"") | ... P11: =IF('5. Projected Sales Forecast (2)'!$E$9>0,'5. Projected Sales Forecast (2)'!$E$9*'5. Projected Sales Forecast (2)'!S15,"") | Q11: =SUM(E11:P11)
B12: =IF('5. Projected Sales Forecast (2)'!E31>0,'5. Projected Sales Forecast (2)'!A30,"") | E12: =IF('5. Projected Sales Forecast (2)'!$E$31>0,'5. Projected Sales Forecast (2)'!$E$31*'5. Projected Sales Forecast (2)'!H37,"") | F12: =IF('5. Projected Sales Forecast (2)'!$E$31>0,'5. Projected Sales Forecast (2)'!$E$31*'5. Projected Sales Forecast (2)'!I37,"") | G12: =IF('5. Projected Sales Forecast (2)'!$E$31>0,'5. Projected Sales Forecast (2)'!$E$31*'5. Projected Sales Forecast (2)'!J37,"") | H12: =IF('5. Projected Sales Forecast (2)'!$E$31>0,'5. Projected Sales Forecast (2)'!$E$31*'5. Projected Sales Forecast (2)'!K37,"") | I12: =IF('5. Projected Sales Forecast (2)'!$E$31>0,'5. Projected Sales Forecast (2)'!$E$31*'5. Projected Sales Forecast (2)'!L37,"") | J12: =IF('5. Projected Sales Forecast (2)'!$E$31>0,'5. Projected Sales Forecast (2)'!$E$31*'5. Projected Sales Forecast (2)'!M37,"") | K12: =IF('5. Projected Sales Forecast (2)'!$E$31>0,'5. Projected Sales Forecast (2)'!$E$31*'5. Projected Sales Forecast (2)'!N37,"") | L12: =IF('5. Projected Sales Forecast (2)'!$E$31>0,'5. Projected Sales Forecast (2)'!$E$31*'5. Projected Sales Forecast (2)'!O37,"") | ... P12: =IF('5. Projected Sales Forecast (2)'!$E$31>0,'5. Projected Sales Forecast (2)'!$E$31*'5. Projected Sales Forecast (2)'!S37,"") | Q12: =SUM(E12:P12)
A13: Total Income | E13: =SUM(E9:E12) | F13: =SUM(F9:F12) | G13: =SUM(G9:G12) | H13: =SUM(H9:H12) | I13: =SUM(I9:I12) | J13: =SUM(J9:J12) | K13: =SUM(K9:K12) | L13: =SUM(L9:L12) | ... Q13: =SUM(Q9:Q12)
A15: Cost of Sales
B16: =B9 | E16: ='4. Projected Sales Forecast'!$E$10*'4. Projected Sales Forecast'!H15 | F16: ='4. Projected Sales Forecast'!$E$10*'4. Projected Sales Forecast'!I15 | G16: ='4. Projected Sales Forecast'!$E$10*'4. Projected Sales Forecast'!J15 | H16: ='4. Projected Sales Forecast'!$E$10*'4. Projected Sales Forecast'!K15 | I16: ='4. Projected Sales Forecast'!$E$10*'4. Projected Sales Forecast'!L15 | J16: ='4. Projected Sales Forecast'!$E$10*'4. Projected Sales Forecast'!M15 | K16: ='4. Projected Sales Forecast'!$E$10*'4. Projected Sales Forecast'!N15 | L16: ='4. Projected Sales Forecast'!$E$10*'4. Projected Sales Forecast'!O15 | ... P16: ='4. Projected Sales Forecast'!$E$10*'4. Projected Sales Forecast'!S15 | Q16: =SUM(E16:P16)
B17: =B10 | E17: ='4. Projected Sales Forecast'!$E$32*'4. Projected Sales Forecast'!H37 | F17: ='4. Projected Sales Forecast'!$E$32*'4. Projected Sales Forecast'!I37 | G17: ='4. Projected Sales Forecast'!$E$32*'4. Projected Sales Forecast'!J37 | H17: ='4. Projected Sales Forecast'!$E$32*'4. Projected Sales Forecast'!K37 | I17: ='4. Projected Sales Forecast'!$E$32*'4. Projected Sales Forecast'!L37 | J17: ='4. Projected Sales Forecast'!$E$32*'4. Projected Sales Forecast'!M37 | K17: ='4. Projected Sales Forecast'!$E$32*'4. Projected Sales Forecast'!N37 | L17: ='4. Projected Sales Forecast'!$E$32*'4. Projected Sales Forecast'!O37 | ... P17: ='4. Projected Sales Forecast'!$E$32*'4. Projected Sales Forecast'!S37 | Q17: =SUM(E17:P17)
B18: =B11 | E18: =IF('5. Projected Sales Forecast (2)'!$E$10>0,'5. Projected Sales Forecast (2)'!$E$10*'5. Projected Sales Forecast (2)'!H15,"") | F18: =IF('5. Projected Sales Forecast (2)'!$E$10>0,'5. Projected Sales Forecast (2)'!$E$10*'5. Projected Sales Forecast (2)'!I15,"") | G18: =IF('5. Projected Sales Forecast (2)'!$E$10>0,'5. Projected Sales Forecast (2)'!$E$10*'5. Projected Sales Forecast (2)'!J15,"") | H18: =IF('5. Projected Sales Forecast (2)'!$E$10>0,'5. Projected Sales Forecast (2)'!$E$10*'5. Projected Sales Forecast (2)'!K15,"") | I18: =IF('5. Projected Sales Forecast (2)'!$E$10>0,'5. Projected Sales Forecast (2)'!$E$10*'5. Projected Sales Forecast (2)'!L15,"") | J18: =IF('5. Projected Sales Forecast (2)'!$E$10>0,'5. Projected Sales Forecast (2)'!$E$10*'5. Projected Sales Forecast (2)'!M15,"") | K18: =IF('5. Projected Sales Forecast (2)'!$E$10>0,'5. Projected Sales Forecast (2)'!$E$10*'5. Projected Sales Forecast (2)'!N15,"") | L18: =IF('5. Projected Sales Forecast (2)'!$E$10>0,'5. Projected Sales Forecast (2)'!$E$10*'5. Projected Sales Forecast (2)'!O15,"") | ... P18: =IF('5. Projected Sales Forecast (2)'!$E$10>0,'5. Projected Sales Forecast (2)'!$E$10*'5. Projected Sales Forecast (2)'!S15,"") | Q18: =SUM(E18:P18)
