Workbook

Sheet Input Assumptions
F2: Base Case | G2: Scenario 2 | H2: Gearing+ | I2: Scenario 4 | J2: Scenario 5 | K2: Scenario 6 | L2: Scenario 7 | M2: Scenario 8 | N2: Scenario 9 | O2: Scenario 10
B3: Scenario Chosen | D3: 1 | F3: 1 | G3: 2 | H3: 3 | I3: 4 | J3: 5 | K3: 6 | L3: 7 | M3: 8 | N3: 9 | O3: 10
C5: Units | D5: Values
B6: TIME ASSUMPTIONS
B8: Concession Duration | C8: years | D8: =INDEX(F8:O8,$D$3) | F8: 40 | G8: 36.5 | H8: 38 | I8: 35.5
B9: Construction Duration | C9: years | D9: =INDEX(F9:O9,$D$3) | F9: 4 | G9: 4 | H9: 4 | I9: 4
B10: Operations Duration | C10: years | D10: =INDEX(F10:O10,$D$3) | F10: 36 | G10: 36 | H10: 36 | I10: 36
B12: TRAFFIC & REVENUE ASSUMPTIONS
B14: Traffic - Passenger Car (PC) | C14: veh/year | D14: =INDEX(F14:O14,$D$3) | F14: 3125000 | G14: 2500000 | H14: 3125000 | I14: 1990000
B15: Traffic - Heavy Vehicule (HV) | C15: veh/year | D15: =INDEX(F15:O15,$D$3) | F15: 2800000 | G15: 2100000 | H15: 2800000 | I15: 2390000
B17: Traffic Evolution per year (PC & HV) | C17: % | D17: =INDEX(F17:O17,$D$3) | F17: 0.02 | G17: 0.01 | H17: 0.02 | I17: 0.02
B18: Inflation per year | C18: % | D18: =INDEX(F18:O18,$D$3) | F18: 0.04 | G18: 0.025 | H18: 0.04 | I18: 0.04
B20: Toll Rate - Passenger Car (PC) | C20: £ | D20: =INDEX(F20:O20,$D$3) | F20: 3.56 | G20: 3.56 | H20: 3.56 | I20: 3.56
B21: Toll Rate - Heavy Vehicule (HV) | C21: £ | D21: =INDEX(F21:O21,$D$3) | F21: 19.382655 | G21: 13.96 | H21: 13.96 | I21: 13.96
B23: COSTS DURING CONSTRUCTION
B25: CAPEX (including SPV costs) | C25: £ | D25: =INDEX(F25:O25,$D$3) | F25: 300000000 | G25: 300000000 | H25: 300000000 | I25: 300000000
B27: COSTS DURING OPERATION
B29: Maintenance (including heavy maintenance & SPV costs) | C29: £/year | D29: =INDEX(F29:O29,$D$3) | F29: 8900000 | G29: 8900000 | H29: 8900000 | I29: 8900000
B31: Inflation per year (costs) from beginning of concession | C31: % | D31: =INDEX(F31:O31,$D$3) | F31: 0.04 | G31: 0.04 | H31: 0.04 | I31: 0.04
B33: PROJECT FINANCING
B35: Base Interest Rate | C35: per year | D35: =INDEX(F35:O35,$D$3) | F35: 0.015 | G35: 0.015 | H35: 0.015 | I35: 0.015
B36: Fixed Rate Margin | C36: per year | D36: =INDEX(F36:O36,$D$3) | F36: 0.0585 | G36: 0.0585 | H36: 0.0585 | I36: 0.0585
B37: Arrangement fee | C37: per year | D37: =INDEX(F37:O37,$D$3) | F37: 0.015 | G37: 0.015 | H37: 0.015 | I37: 0.015
B38: Engagement fee | C38: of margin | D38: =INDEX(F38:O38,$D$3) | F38: 0.35 | G38: 0.35 | H38: 0.35 | I38: 0.35
B40: Gearing | C40: % | D40: =INDEX(F40:O40,$D$3) | F40: 0.65 | G40: 0.65 | H40: 0.8 | I40: 0.8
B42: TAX & ACCOUNTING ASSUMPTIONS
B44: Tax Rate | C44: % | D44: =INDEX(F44:O44,$D$3) | F44: 0.3 | G44: 0.3 | H44: 0.3 | I44: 0.3
B45: Dividend distribution policy | C45: % | D45: =INDEX(F45:O45,$D$3) | F45: 1 | G45: 1 | H45: 1 | I45: 1

Sheet TBA
B2: Year | D2: 1 | E2: 2 | F2: 3 | G2: 4 | H2: 5 | I2: 6 | J2: 7 | K2: 8 | L2: 9 | M2: 10 | N2: 11 | O2: 12 | P2: 13 | Q2: 14 | R2: 15 | S2: 16 | T2: 17 | U2: 18 | V2: 19 | W2: 20 | X2: 21 | Y2: 22 | Z2: 23 | AA2: 24 | AB2: 25 | AC2: 26 | AD2: 27 | AE2: 28 | AF2: 29 | AG2: 30 | AH2: 31 | AI2: 32 | AJ2: 33 | AK2: 34 | AL2: 35 | AM2: 36 | AN2: 37 | AO2: 38 | AP2: 39 | AQ2: 40
B5: Flags
B7: Beginning of construction | C7: =SUM(D7:AQ7) | D7: 1 | E7: 0 | F7: 0 | G7: 0 | H7: 0 | I7: 0 | J7: 0 | K7: 0 | L7: 0 | M7: 0 | N7: 0 | O7: 0 | P7: 0 | Q7: 0 | R7: 0 | S7: 0 | T7: 0 | U7: 0 | V7: 0 | W7: 0 | X7: 0 | Y7: 0 | Z7: 0 | AA7: 0 | AB7: 0 | AC7: 0 | AD7: 0 | AE7: 0 | AF7: 0 | AG7: 0 | AH7: 0 | AI7: 0 | AJ7: 0 | AK7: 0 | AL7: 0 | AM7: 0 | AN7: 0 | AO7: 0 | AP7: 0 | AQ7: 0
B8: Construction | C8: =SUM(D8:AQ8) | D8: 1 | E8: 1 | F8: 1 | G8: 1 | H8: 0 | I8: 0 | J8: 0 | K8: 0 | L8: 0 | M8: 0 | N8: 0 | O8: 0 | P8: 0 | Q8: 0 | R8: 0 | S8: 0 | T8: 0 | U8: 0 | V8: 0 | W8: 0 | X8: 0 | Y8: 0 | Z8: 0 | AA8: 0 | AB8: 0 | AC8: 0 | AD8: 0 | AE8: 0 | AF8: 0 | AG8: 0 | AH8: 0 | AI8: 0 | AJ8: 0 | AK8: 0 | AL8: 0 | AM8: 0 | AN8: 0 | AO8: 0 | AP8: 0 | AQ8: 0
B9: End of construction | C9: =SUM(D9:AQ9) | D9: 0 | E9: 0 | F9: 0 | G9: 1 | H9: 0 | I9: 0 | J9: 0 | K9: 0 | L9: 0 | M9: 0 | N9: 0 | O9: 0 | P9: 0 | Q9: 0 | R9: 0 | S9: 0 | T9: 0 | U9: 0 | V9: 0 | W9: 0 | X9: 0 | Y9: 0 | Z9: 0 | AA9: 0 | AB9: 0 | AC9: 0 | AD9: 0 | AE9: 0 | AF9: 0 | AG9: 0 | AH9: 0 | AI9: 0 | AJ9: 0 | AK9: 0 | AL9: 0 | AM9: 0 | AN9: 0 | AO9: 0 | AP9: 0 | AQ9: 0
B10: Operation | C10: =SUM(D10:AQ10) | D10: 0 | E10: 0 | F10: 0 | G10: 0 | H10: 1 | I10: 1 | J10: 1 | K10: 1 | L10: 1 | M10: 1 | N10: 1 | O10: 1 | P10: 1 | Q10: 1 | R10: 1 | S10: 1 | T10: 1 | U10: 1 | V10: 1 | W10: 1 | X10: 1 | Y10: 1 | Z10: 1 | AA10: 1 | AB10: 1 | AC10: 1 | AD10: 1 | AE10: 1 | AF10: 1 | AG10: 1 | AH10: 1 | AI10: 1 | AJ10: 1 | AK10: 1 | AL10: 1 | AM10: 1 | AN10: 1 | AO10: 1 | AP10: 1 | AQ10: 1
B12: DEBT TIMELINE
B13: Availability Start Date | C13: =SUM(D13:AQ13) | D13: 1 | E13: 0 | F13: 0 | G13: 0 | H13: 0 | I13: 0 | J13: 0 | K13: 0 | L13: 0 | M13: 0 | N13: 0 | O13: 0 | P13: 0 | Q13: 0 | R13: 0 | S13: 0 | T13: 0 | U13: 0 | V13: 0 | W13: 0 | X13: 0 | Y13: 0 | Z13: 0 | AA13: 0 | AB13: 0 | AC13: 0 | AD13: 0 | AE13: 0 | AF13: 0 | AG13: 0 | AH13: 0 | AI13: 0 | AJ13: 0 | AK13: 0 | AL13: 0 | AM13: 0 | AN13: 0 | AO13: 0 | AP13: 0 | AQ13: 0
B14: Active | C14: =SUM(D14:AQ14) | D14: 1 | E14: 1 | F14: 1 | G14: 1 | H14: 0 | I14: 0 | J14: 0 | K14: 0 | L14: 0 | M14: 0 | N14: 0 | O14: 0 | P14: 0 | Q14: 0 | R14: 0 | S14: 0 | T14: 0 | U14: 0 | V14: 0 | W14: 0 | X14: 0 | Y14: 0 | Z14: 0 | AA14: 0 | AB14: 0 | AC14: 0 | AD14: 0 | AE14: 0 | AF14: 0 | AG14: 0 | AH14: 0 | AI14: 0 | AJ14: 0 | AK14: 0 | AL14: 0 | AM14: 0 | AN14: 0 | AO14: 0 | AP14: 0 | AQ14: 0
B15: Availability End Date | C15: =SUM(D15:AQ15) | D15: 0 | E15: 0 | F15: 0 | G15: 1 | H15: 0 | I15: 0 | J15: 0 | K15: 0 | L15: 0 | M15: 0 | N15: 0 | O15: 0 | P15: 0 | Q15: 0 | R15: 0 | S15: 0 | T15: 0 | U15: 0 | V15: 0 | W15: 0 | X15: 0 | Y15: 0 | Z15: 0 | AA15: 0 | AB15: 0 | AC15: 0 | AD15: 0 | AE15: 0 | AF15: 0 | AG15: 0 | AH15: 0 | AI15: 0 | AJ15: 0 | AK15: 0 | AL15: 0 | AM15: 0 | AN15: 0 | AO15: 0 | AP15: 0 | AQ15: 0
B17: Repayment Start Date | C17: =SUM(D17:AQ17) | D17: 0 | E17: 0 | F17: 0 | G17: 0 | H17: 1 | I17: 0 | J17: 0 | K17: 0 | L17: 0 | M17: 0 | N17: 0 | O17: 0 | P17: 0 | Q17: 0 | R17: 0 | S17: 0 | T17: 0 | U17: 0 | V17: 0 | W17: 0 | X17: 0 | Y17: 0 | Z17: 0 | AA17: 0 | AB17: 0 | AC17: 0 | AD17: 0 | AE17: 0 | AF17: 0 | AG17: 0 | AH17: 0 | AI17: 0 | AJ17: 0 | AK17: 0 | AL17: 0 | AM17: 0 | AN17: 0 | AO17: 0 | AP17: 0 | AQ17: 0
B18: Active | C18: =SUM(D18:AQ18) | D18: 0 | E18: 0 | F18: 0 | G18: 0 | H18: 1 | I18: 1 | J18: 1 | K18: 1 | L18: 1 | M18: 1 | N18: 1 | O18: 1 | P18: 1 | Q18: 1 | R18: 1 | S18: 1 | T18: 1 | U18: 1 | V18: 1 | W18: 1 | X18: 1 | Y18: 1 | Z18: 1 | AA18: 1 | AB18: 1 | AC18: 1 | AD18: 1 | AE18: 1 | AF18: 1 | AG18: 1 | AH18: 1 | AI18: 1 | AJ18: 1 | AK18: 1 | AL18: 1 | AM18: 1 | AN18: 1 | AO18: 1 | AP18: 1 | AQ18: 1
B19: Repayment End Date | C19: =SUM(D19:AQ19) | D19: 0 | E19: 0 | F19: 0 | G19: 0 | H19: 0 | I19: 0 | J19: 0 | K19: 0 | L19: 0 | M19: 0 | N19: 0 | O19: 0 | P19: 0 | Q19: 0 | R19: 0 | S19: 0 | T19: 0 | U19: 0 | V19: 0 | W19: 0 | X19: 0 | Y19: 0 | Z19: 0 | AA19: 0 | AB19: 0 | AC19: 0 | AD19: 0 | AE19: 0 | AF19: 0 | AG19: 0 | AH19: 0 | AI19: 0 | AJ19: 0 | AK19: 0 | AL19: 0 | AM19: 0 | AN19: 0 | AO19: 0 | AP19: 0 | AQ19: 1

Sheet Construction
B2: Year | E2: 1 | F2: 2 | G2: 3 | H2: 4 | I2: 5 | J2: 6 | K2: 7 | L2: 8 | M2: 9 | N2: 10 | O2: 11 | P2: 12 | Q2: 13 | R2: 14 | S2: 15 | T2: 16 | U2: 17 | V2: 18 | W2: 19 | X2: 20 | Y2: 21 | Z2: 22 | AA2: 23 | AB2: 24 | AC2: 25 | AD2: 26 | AE2: 27 | AF2: 28 | AG2: 29 | AH2: 30 | AI2: 31 | AJ2: 32 | AK2: 33 | AL2: 34 | AM2: 35 | AN2: 36 | AO2: 37 | AP2: 38 | AQ2: 39 | AR2: 40
B5: CAPEX
B6: Construction Cost (k£) | C6: =SUM(E6:AR6) | E6: ='Input Assumptions'!$D$25/'Input Assumptions'!$D$9/1000*TBA!D8 | F6: ='Input Assumptions'!$D$25/'Input Assumptions'!$D$9/1000*TBA!E8 | G6: ='Input Assumptions'!$D$25/'Input Assumptions'!$D$9/1000*TBA!F8 | H6: ='Input Assumptions'!$D$25/'Input Assumptions'!$D$9/1000*TBA!G8 | I6: ='Input Assumptions'!$D$25/'Input Assumptions'!$D$9/1000*TBA!H8 | J6: ='Input Assumptions'!$D$25/'Input Assumptions'!$D$9/1000*TBA!I8 | K6: ='Input Assumptions'!$D$25/'Input Assumptions'!$D$9/1000*TBA!J8 | L6: ='Input Assumptions'!$D$25/'Input Assumptions'!$D$9/1000*TBA!K8 | N6: ='Input Assumptions'!$D$25/'Input Assumptions'!$D$9/1000*TBA!M8 | O6: ='Input Assumptions'!$D$25/'Input Assumptions'!$D$9/1000*TBA!N8 | P6: ='Input Assumptions'!$D$25/'Input Assumptions'!$D$9/1000*TBA!O8 | Q6: ='Input Assumptions'!$D$25/'Input Assumptions'!$D$9/1000*TBA!P8 | R6: ='Input Assumptions'!$D$25/'Input Assumptions'!$D$9/1000*TBA!Q8 | S6: ='Input Assumptions'!$D$25/'Input Assumptions'!$D$9/1000*TBA!R8 | T6: ='Input Assumptions'!$D$25/'Input Assumptions'!$D$9/1000*TBA!S8 | U6: ='Input Assumptions'!$D$25/'Input Assumptions'!$D$9/1000*TBA!T8 | ... AR6: ='Input Assumptions'!$D$25/'Input Assumptions'!$D$9/1000*TBA!AQ8
B8: Total Costs (k£) | C8: =SUM(E8:AR8) | E8: =SUM(E6:E7) | F8: =SUM(F6:F7) | G8: =SUM(G6:G7) | H8: =SUM(H6:H7) | I8: =SUM(I6:I7) | J8: =SUM(J6:J7) | K8: =SUM(K6:K7) | L8: =SUM(L6:L7) | ... AR8: =SUM(AR6:AR7)
B11: Uses
B12: Construction Cost (k£) | C12: =SUM(E12:AR12) | E12: =E8 | F12: =F8 | G12: =G8 | H12: =H8 | I12: =I8 | J12: =J8 | K12: =K8 | L12: =L8 | ... AG12: =AG8 | AI12: =AI8 | AJ12: =AJ8 | AK12: =AK8 | AM12: =AM8 | AN12: =AN8 | AO12: =AO8 | AP12: =AP8 | AQ12: =AQ8 | AR12: =AR8
B13: Arrangement fee (k£) | C13: =SUM(E13:AR13) | E13: =E37 | F13: =F37 | G13: =G37 | H13: =H37 | J13: =J37 | K13: =K37 | L13: =L37 | M13: =M37 | N13: =N37 | O13: =O37 | P13: =P37 | Q13: =Q37 | ... AR13: =AR37
B14: Engagement fee (k£) | C14: =SUM(E14:AR14) | E14: =E38 | F14: =F38 | H14: =H38 | I14: =I38 | J14: =J38 | K14: =K38 | L14: =L38 | M14: =M38 | N14: =N38 | O14: =O38 | P14: =P38 | R14: =R38 | S14: =S38 | T14: =T38 | U14: =U38 | V14: =V38 | W14: =W38 | X14: =X38 | Y14: =Y38 | ... AR14: =AR38
B15: Capitalized Interest (k£) | C15: =SUM(E15:AR15) | E15: =E39 | F15: =F39 | G15: =G39 | H15: =H39 | I15: =I39 | K15: =K39 | L15: =L39 | M15: =M39 | N15: =N39 | O15: =O39 | P15: =P39 | Q15: =Q39 | R15: =R39 | ... AR15: =AR39
B16: Total Uses (k£) | C16: =SUM(E16:AR16) | E16: =SUM(E12:E15) | F16: =SUM(F12:F15) | G16: =SUM(G12:G15) | H16: =SUM(H12:H15) | I16: =SUM(I12:I15) | J16: =SUM(J12:J15) | K16: =SUM(K12:K15) | L16: =SUM(L12:L15) | ... V16: =SUM(V12:V15) | X16: =SUM(X12:X15) | Y16: =SUM(Y12:Y15) | Z16: =SUM(Z12:Z15) | AA16: =SUM(AA12:AA15) | AB16: =SUM(AB12:AB15) | AC16: =SUM(AC12:AC15) | AD16: =SUM(AD12:AD15) | AE16: =SUM(AE12:AE15) | AF16: =SUM(AF12:AF15) | AH16: =SUM(AH12:AH15) | AI16: =SUM(AI12:AI15) | AJ16: =SUM(AJ12:AJ15) | AK16: =SUM(AK12:AK15) | AL16: =SUM(AL12:AL15) | AM16: =SUM(AM12:AM15) | AN16: =SUM(AN12:AN15) | AO16: =SUM(AO12:AO15) | ... AR16: =SUM(AR12:AR15)
B19: Uses of funds for circularity breakdown purpose | E19: 82610.74 | F19: 79392.668 | G19: 81857.421 | H19: 86197.909 | I19: 0 | J19: 0 | K19: 0 | L19: 0 | M19: 0 | N19: 0 | O19: 0 | P19: 0 | Q19: 0 | R19: 0 | S19: 0 | T19: 0 | U19: 0 | V19: 0 | W19: 0 | X19: 0 | Y19: 0 | Z19: 0 | AA19: 0 | AB19: 0 | AC19: 0 | AD19: 0 | AE19: 0 | AF19: 0 | AG19: 0 | AH19: 0 | AI19: 0 | AJ19: 0 | AK19: 0 | AL19: 0 | AM19: 0 | AN19: 0 | AO19: 0 | AP19: 0 | AQ19: 0 | AR19: 0
B20: Uses Total (k£) | C20: =SUM(E19:AR19)
B21: Total Debt Amount (k£) | C21: =$C$20*'Input Assumptions'!$D$40
B22: Total Equity Amount (k£) | C22: =$C$20*(1-'Input Assumptions'!$D$40)
B25: Sources
B26: Equity (k£) | C26: =SUM(E26:AR26) | E26: =IF(MAX($C$22-SUM($D$26:D26),0)>E19,E19,MAX($C$22-SUM($D$26:D26),0)) | F26: =IF(MAX($C$22-SUM($D$26:E26),0)>F19,F19,MAX($C$22-SUM($D$26:E26),0)) | G26: =IF(MAX($C$22-SUM($D$26:F26),0)>G19,G19,MAX($C$22-SUM($D$26:F26),0)) | H26: =IF(MAX($C$22-SUM($D$26:G26),0)>H19,H19,MAX($C$22-SUM($D$26:G26),0)) | I26: =IF(MAX($C$22-SUM($D$26:H26),0)>I19,I19,MAX($C$22-SUM($D$26:H26),0)) | J26: =IF(MAX($C$22-SUM($D$26:I26),0)>J19,J19,MAX($C$22-SUM($D$26:I26),0)) | K26: =IF(MAX($C$22-SUM($D$26:J26),0)>K19,K19,MAX($C$22-SUM($D$26:J26),0)) | L26: =IF(MAX($C$22-SUM($D$26:K26),0)>L19,L19,MAX($C$22-SUM($D$26:K26),0)) | ... AI26: =IF(MAX($C$22-SUM($D$26:AH26),0)>AI19,AI19,MAX($C$22-SUM($D$26:AH26),0)) | AK26: =IF(MAX($C$22-SUM($D$26:AJ26),0)>AK19,AK19,MAX($C$22-SUM($D$26:AJ26),0)) | AL26: =IF(MAX($C$22-SUM($D$26:AK26),0)>AL19,AL19,MAX($C$22-SUM($D$26:AK26),0)) | AM26: =IF(MAX($C$22-SUM($D$26:AL26),0)>AM19,AM19,MAX($C$22-SUM($D$26:AL26),0)) | AN26: =IF(MAX($C$22-SUM($D$26:AM26),0)>AN19,AN19,MAX($C$22-SUM($D$26:AM26),0)) | AO26: =IF(MAX($C$22-SUM($D$26:AN26),0)>AO19,AO19,MAX($C$22-SUM($D$26:AN26),0)) | AP26: =IF(MAX($C$22-SUM($D$26:AO26),0)>AP19,AP19,MAX($C$22-SUM($D$26:AO26),0)) | AQ26: =IF(MAX($C$22-SUM($D$26:AP26),0)>AQ19,AQ19,MAX($C$22-SUM($D$26:AP26),0)) | AR26: =IF(MAX($C$22-SUM($D$26:AQ26),0)>AR19,AR19,MAX($C$22-SUM($D$26:AQ26),0))
B27: Debt (k£) | C27: =SUM(E27:AR27) | E27: =IF(E19-E26>0,E19-E26,0) | F27: =IF(F19-F26>0,F19-F26,0) | G27: =IF(G19-G26>0,G19-G26,0) | H27: =IF(H19-H26>0,H19-H26,0) | I27: =IF(I19-I26>0,I19-I26,0) | J27: =IF(J19-J26>0,J19-J26,0) | K27: =IF(K19-K26>0,K19-K26,0) | L27: =IF(L19-L26>0,L19-L26,0) | ... U27: =IF(U19-U26>0,U19-U26,0) | W27: =IF(W19-W26>0,W19-W26,0) | X27: =IF(X19-X26>0,X19-X26,0) | Y27: =IF(Y19-Y26>0,Y19-Y26,0) | Z27: =IF(Z19-Z26>0,Z19-Z26,0) | AA27: =IF(AA19-AA26>0,AA19-AA26,0) | AB27: =IF(AB19-AB26>0,AB19-AB26,0) | AC27: =IF(AC19-AC26>0,AC19-AC26,0) | AD27: =IF(AD19-AD26>0,AD19-AD26,0) | ... AJ27: =IF(AJ19-AJ26>0,AJ19-AJ26,0) | AL27: =IF(AL19-AL26>0,AL19-AL26,0) | AM27: =IF(AM19-AM26>0,AM19-AM26,0) | AN27: =IF(AN19-AN26>0,AN19-AN26,0) | AO27: =IF(AO19-AO26>0,AO19-AO26,0) | AP27: =IF(AP19-AP26>0,AP19-AP26,0) | AQ27: =IF(AQ19-AQ26>0,AQ19-AQ26,0) | AR27: =IF(AR19-AR26>0,AR19-AR26,0)
B28: Total Sources (k£) | C28: =SUM(E28:AR28) | E28: =SUM(E26:E27) | G28: =SUM(G26:G27) | H28: =SUM(H26:H27) | I28: =SUM(I26:I27) | J28: =SUM(J26:J27) | K28: =SUM(K26:K27) | L28: =SUM(L26:L27) | M28: =SUM(M26:M27) | N28: =SUM(N26:N27) | ... T28: =SUM(T26:T27) | V28: =SUM(V26:V27) | W28: =SUM(W26:W27) | X28: =SUM(X26:X27) | Y28: =SUM(Y26:Y27) | Z28: =SUM(Z26:Z27) | AA28: =SUM(AA26:AA27) | AB28: =SUM(AB26:AB27) | AC28: =SUM(AC26:AC27) | AD28: =SUM(AD26:AD27) | AF28: =SUM(AF26:AF27) | AG28: =SUM(AG26:AG27) | AH28: =SUM(AH26:AH27) | AI28: =SUM(AI26:AI27) | AJ28: =SUM(AJ26:AJ27) | AK28: =SUM(AK26:AK27) | AL28: =SUM(AL26:AL27) | AM28: =SUM(AM26:AM27) | ... AR28: =SUM(AR26:AR27)
B32: Debt Drawdown Schedule
B33: Debt Outstanding BoP (k£) | E33: 0 | F33: =E35 | G33: =F35 | H33: =G35 | I33: =H35 | J33: =I35 | K33: =J35 | L33: =K35 | M33: =L35 | ... AR33: =AQ35
B34: Debt Drawdown (k£) | C34: =SUM(E34:AR34) | E34: =E27 | F34: =F27 | G34: =G27 | H34: =H27 | I34: =I27 | J34: =J27 | K34: =K27 | L34: =L27 | ... Y34: =Y27 | AA34: =AA27 | AB34: =AB27 | AC34: =AC27 | AD34: =AD27 | AE34: =AE27 | AF34: =AF27 | AG34: =AG27 | AH34: =AH27 | ... AR34: =AR27
B35: Debt Outstanding EoP (k£) | E35: =SUM(E33:E34) | F35: =SUM(F33:F34) | G35: =SUM(G33:G34) | H35: =SUM(H33:H34) | I35: =SUM(I33:I34) | J35: =SUM(J33:J34) | K35: =SUM(K33:K34) | L35: =SUM(L33:L34) | ... T35: =SUM(T33:T34) | V35: =SUM(V33:V34) | W35: =SUM(W33:W34) | X35: =SUM(X33:X34) | Y35: =SUM(Y33:Y34) | AA35: =SUM(AA33:AA34) | AB35: =SUM(AB33:AB34) | AC35: =SUM(AC33:AC34) | AD35: =SUM(AD33:AD34) | AE35: =SUM(AE33:AE34) | AF35: =SUM(AF33:AF34) | AG35: =SUM(AG33:AG34) | AH35: =SUM(AH33:AH34) | ... AR35: =SUM(AR33:AR34)
B37: Arrangement fee (k£) | E37: ='Input Assumptions'!$D$37*Construction!$C$34*TBA!D13 | F37: ='Input Assumptions'!$D$37*Construction!$C$34*TBA!E13 | G37: ='Input Assumptions'!$D$37*Construction!$C$34*TBA!F13 | H37: ='Input Assumptions'!$D$37*Construction!$C$34*TBA!G13 | I37: ='Input Assumptions'!$D$37*Construction!$C$34*TBA!H13 | J37: ='Input Assumptions'!$D$37*Construction!$C$34*TBA!I13 | K37: ='Input Assumptions'!$D$37*Construction!$C$34*TBA!J13 | L37: ='Input Assumptions'!$D$37*Construction!$C$34*TBA!K13 | ... S37: ='Input Assumptions'!$D$37*Construction!$C$34*TBA!R13 | U37: ='Input Assumptions'!$D$37*Construction!$C$34*TBA!T13 | V37: ='Input Assumptions'!$D$37*Construction!$C$34*TBA!U13 | W37: ='Input Assumptions'!$D$37*Construction!$C$34*TBA!V13 | X37: ='Input Assumptions'!$D$37*Construction!$C$34*TBA!W13 | Y37: ='Input Assumptions'!$D$37*Construction!$C$34*TBA!X13 | Z37: ='Input Assumptions'!$D$37*Construction!$C$34*TBA!Y13 | AA37: ='Input Assumptions'!$D$37*Construction!$C$34*TBA!Z13 | AB37: ='Input Assumptions'!$D$37*Construction!$C$34*TBA!AA13 | AD37: ='Input Assumptions'!$D$37*Construction!$C$34*TBA!AC13 | AE37: ='Input Assumptions'!$D$37*Construction!$C$34*TBA!AD13 | AF37: ='Input Assumptions'!$D$37*Construction!$C$34*TBA!AE13 | AG37: ='Input Assumptions'!$D$37*Construction!$C$34*TBA!AF13 | AH37: ='Input Assumptions'!$D$37*Construction!$C$34*TBA!AG13 | AI37: ='Input Assumptions'!$D$37*Construction!$C$34*TBA!AH13 | AJ37: ='Input Assumptions'!$D$37*Construction!$C$34*TBA!AI13 | AK37: ='Input Assumptions'!$D$37*Construction!$C$34*TBA!AJ13 | ... AR37: ='Input Assumptions'!$D$37*Construction!$C$34*TBA!AQ13
B38: Engagement fee (k£) | E38: =($C$34-E33)*TBA!D14*'Input Assumptions'!$D$36*'Input Assumptions'!$D$38 | F38: =($C$34-F33)*TBA!E14*'Input Assumptions'!$D$36*'Input Assumptions'!$D$38 | G38: =($C$34-G33)*TBA!F14*'Input Assumptions'!$D$36*'Input Assumptions'!$D$38 | H38: =($C$34-H33)*TBA!G14*'Input Assumptions'!$D$36*'Input Assumptions'!$D$38 | I38: =($C$34-I33)*TBA!H14*'Input Assumptions'!$D$36*'Input Assumptions'!$D$38 | J38: =($C$34-J33)*TBA!I14*'Input Assumptions'!$D$36*'Input Assumptions'!$D$38 | K38: =($C$34-K33)*TBA!J14*'Input Assumptions'!$D$36*'Input Assumptions'!$D$38 | L38: =($C$34-L33)*TBA!K14*'Input Assumptions'!$D$36*'Input Assumptions'!$D$38 | ... AA38: =($C$34-AA33)*TBA!Z14*'Input Assumptions'!$D$36*'Input Assumptions'!$D$38 | AC38: =($C$34-AC33)*TBA!AB14*'Input Assumptions'!$D$36*'Input Assumptions'!$D$38 | AD38: =($C$34-AD33)*TBA!AC14*'Input Assumptions'!$D$36*'Input Assumptions'!$D$38 | AE38: =($C$34-AE33)*TBA!AD14*'Input Assumptions'!$D$36*'Input Assumptions'!$D$38 | AF38: =($C$34-AF33)*TBA!AE14*'Input Assumptions'!$D$36*'Input Assumptions'!$D$38 | AG38: =($C$34-AG33)*TBA!AF14*'Input Assumptions'!$D$36*'Input Assumptions'!$D$38 | AH38: =($C$34-AH33)*TBA!AG14*'Input Assumptions'!$D$36*'Input Assumptions'!$D$38 | AI38: =($C$34-AI33)*TBA!AH14*'Input Assumptions'!$D$36*'Input Assumptions'!$D$38 | AJ38: =($C$34-AJ33)*TBA!AI14*'Input Assumptions'!$D$36*'Input Assumptions'!$D$38 | ... AR38: =($C$34-AR33)*TBA!AQ14*'Input Assumptions'!$D$36*'Input Assumptions'!$D$38
B39: Capitalized Interests (k£) | E39: =('Input Assumptions'!$D$35+'Input Assumptions'!$D$36)*E33*TBA!D14 | F39: =('Input Assumptions'!$D$35+'Input Assumptions'!$D$36)*F33*TBA!E14 | G39: =('Input Assumptions'!$D$35+'Input Assumptions'!$D$36)*G33*TBA!F14 | H39: =('Input Assumptions'!$D$35+'Input Assumptions'!$D$36)*H33*TBA!G14 | I39: =('Input Assumptions'!$D$35+'Input Assumptions'!$D$36)*I33*TBA!H14 | J39: =('Input Assumptions'!$D$35+'Input Assumptions'!$D$36)*J33*TBA!I14 | K39: =('Input Assumptions'!$D$35+'Input Assumptions'!$D$36)*K33*TBA!J14 | M39: =('Input Assumptions'!$D$35+'Input Assumptions'!$D$36)*M33*TBA!L14 | N39: =('Input Assumptions'!$D$35+'Input Assumptions'!$D$36)*N33*TBA!M14 | O39: =('Input Assumptions'!$D$35+'Input Assumptions'!$D$36)*O33*TBA!N14 | P39: =('Input Assumptions'!$D$35+'Input Assumptions'!$D$36)*P33*TBA!O14 | Q39: =('Input Assumptions'!$D$35+'Input Assumptions'!$D$36)*Q33*TBA!P14 | R39: =('Input Assumptions'!$D$35+'Input Assumptions'!$D$36)*R33*TBA!Q14 | S39: =('Input Assumptions'!$D$35+'Input Assumptions'!$D$36)*S33*TBA!R14 | T39: =('Input Assumptions'!$D$35+'Input Assumptions'!$D$36)*T33*TBA!S14 | ... Z39: =('Input Assumptions'!$D$35+'Input Assumptions'!$D$36)*Z33*TBA!Y14 | AB39: =('Input Assumptions'!$D$35+'Input Assumptions'!$D$36)*AB33*TBA!AA14 | AC39: =('Input Assumptions'!$D$35+'Input Assumptions'!$D$36)*AC33*TBA!AB14 | AE39: =('Input Assumptions'!$D$35+'Input Assumptions'!$D$36)*AE33*TBA!AD14 | AF39: =('Input Assumptions'!$D$35+'Input Assumptions'!$D$36)*AF33*TBA!AE14 | AG39: =('Input Assumptions'!$D$35+'Input Assumptions'!$D$36)*AG33*TBA!AF14 | AH39: =('Input Assumptions'!$D$35+'Input Assumptions'!$D$36)*AH33*TBA!AG14 | AI39: =('Input Assumptions'!$D$35+'Input Assumptions'!$D$36)*AI33*TBA!AH14 | AJ39: =('Input Assumptions'!$D$35+'Input Assumptions'!$D$36)*AJ33*TBA!AI14 | AK39: =('Input Assumptions'!$D$35+'Input Assumptions'!$D$36)*AK33*TBA!AJ14 | AL39: =('Input Assumptions'!$D$35+'Input Assumptions'!$D$36)*AL33*TBA!AK14 | ... AR39: =('Input Assumptions'!$D$35+'Input Assumptions'!$D$36)*AR33*TBA!AQ14
B43: CHECK | E43: =E16-E28<0.01 | F43: =F16-F28<0.01 | G43: =G16-G28<0.01 | H43: =H16-H28<0.01 | I43: =I16-I28<0.01 | J43: =J16-J28<0.01 | K43: =K16-K28<0.01 | L43: =L16-L28<0.01 | ... AF43: =AF16-AF28<0.01 | AH43: =AH16-AH28<0.01 | AI43: =AI16-AI28<0.01 | AJ43: =AJ16-AJ28<0.01 | AK43: =AK16-AK28<0.01 | AL43: =AL16-AL28<0.01 | AM43: =AM16-AM28<0.01 | AN43: =AN16-AN28<0.01 | AO43: =AO16-AO28<0.01 | ... AR43: =AR16-AR28<0.01

Sheet Operation
B2: Year | E2: 1 | F2: 2 | G2: 3 | H2: 4 | I2: 5 | J2: 6 | K2: 7 | L2: 8 | M2: 9 | N2: 10 | O2: 11 | P2: 12 | Q2: 13 | R2: 14 | S2: 15 | T2: 16 | U2: 17 | V2: 18 | W2: 19 | X2: 20 | Y2: 21 | Z2: 22 | AA2: 23 | AB2: 24 | AC2: 25 | AD2: 26 | AE2: 27 | AF2: 28 | AG2: 29 | AH2: 30 | AI2: 31 | AJ2: 32 | AK2: 33 | AL2: 34 | AM2: 35 | AN2: 36 | AO2: 37 | AP2: 38 | AQ2: 39 | AR2: 40
B5: TRAFFIC & REVENUE ASSUMPTIONS
B7: TRAFFIC - Passenger Car (PC) | C7: veh/year | E7: ='Input Assumptions'!$D$14*(1+'Input Assumptions'!$D$17)^(SUM(TBA!$D$10:'TBA'!D10)-1)*TBA!D10 | F7: ='Input Assumptions'!$D$14*(1+'Input Assumptions'!$D$17)^(SUM(TBA!$D$10:'TBA'!E10)-1)*TBA!E10 | G7: ='Input Assumptions'!$D$14*(1+'Input Assumptions'!$D$17)^(SUM(TBA!$D$10:'TBA'!F10)-1)*TBA!F10 | H7: ='Input Assumptions'!$D$14*(1+'Input Assumptions'!$D$17)^(SUM(TBA!$D$10:'TBA'!G10)-1)*TBA!G10 | I7: ='Input Assumptions'!$D$14*(1+'Input Assumptions'!$D$17)^(SUM(TBA!$D$10:'TBA'!H10)-1)*TBA!H10 | J7: ='Input Assumptions'!$D$14*(1+'Input Assumptions'!$D$17)^(SUM(TBA!$D$10:'TBA'!I10)-1)*TBA!I10 | K7: ='Input Assumptions'!$D$14*(1+'Input Assumptions'!$D$17)^(SUM(TBA!$D$10:'TBA'!J10)-1)*TBA!J10 | L7: ='Input Assumptions'!$D$14*(1+'Input Assumptions'!$D$17)^(SUM(TBA!$D$10:'TBA'!K10)-1)*TBA!K10 | ... W7: ='Input Assumptions'!$D$14*(1+'Input Assumptions'!$D$17)^(SUM(TBA!$D$10:'TBA'!V10)-1)*TBA!V10 | Y7: ='Input Assumptions'!$D$14*(1+'Input Assumptions'!$D$17)^(SUM(TBA!$D$10:'TBA'!X10)-1)*TBA!X10 | Z7: ='Input Assumptions'!$D$14*(1+'Input Assumptions'!$D$17)^(SUM(TBA!$D$10:'TBA'!Y10)-1)*TBA!Y10 | AA7: ='Input Assumptions'!$D$14*(1+'Input Assumptions'!$D$17)^(SUM(TBA!$D$10:'TBA'!Z10)-1)*TBA!Z10 | AB7: ='Input Assumptions'!$D$14*(1+'Input Assumptions'!$D$17)^(SUM(TBA!$D$10:'TBA'!AA10)-1)*TBA!AA10 | AC7: ='Input Assumptions'!$D$14*(1+'Input Assumptions'!$D$17)^(SUM(TBA!$D$10:'TBA'!AB10)-1)*TBA!AB10 | AD7: ='Input Assumptions'!$D$14*(1+'Input Assumptions'!$D$17)^(SUM(TBA!$D$10:'TBA'!AC10)-1)*TBA!AC10 | AE7: ='Input Assumptions'!$D$14*(1+'Input Assumptions'!$D$17)^(SUM(TBA!$D$10:'TBA'!AD10)-1)*TBA!AD10 | AF7: ='Input Assumptions'!$D$14*(1+'Input Assumptions'!$D$17)^(SUM(TBA!$D$10:'TBA'!AE10)-1)*TBA!AE10 | ... AR7: ='Input Assumptions'!$D$14*(1+'Input Assumptions'!$D$17)^(SUM(TBA!$D$10:'TBA'!AQ10)-1)*TBA!AQ10
B8: TRAFFIC - Heavy Vehicle (HV) | C8: veh/year | E8: ='Input Assumptions'!$D$15*(1+'Input Assumptions'!$D$17)^(SUM(TBA!$D$10:'TBA'!D10)-1)*TBA!D10 | F8: ='Input Assumptions'!$D$15*(1+'Input Assumptions'!$D$17)^(SUM(TBA!$D$10:'TBA'!E10)-1)*TBA!E10 | G8: ='Input Assumptions'!$D$15*(1+'Input Assumptions'!$D$17)^(SUM(TBA!$D$10:'TBA'!F10)-1)*TBA!F10 | H8: ='Input Assumptions'!$D$15*(1+'Input Assumptions'!$D$17)^(SUM(TBA!$D$10:'TBA'!G10)-1)*TBA!G10 | I8: ='Input Assumptions'!$D$15*(1+'Input Assumptions'!$D$17)^(SUM(TBA!$D$10:'TBA'!H10)-1)*TBA!H10 | J8: ='Input Assumptions'!$D$15*(1+'Input Assumptions'!$D$17)^(SUM(TBA!$D$10:'TBA'!I10)-1)*TBA!I10 | K8: ='Input Assumptions'!$D$15*(1+'Input Assumptions'!$D$17)^(SUM(TBA!$D$10:'TBA'!J10)-1)*TBA!J10 | L8: ='Input Assumptions'!$D$15*(1+'Input Assumptions'!$D$17)^(SUM(TBA!$D$10:'TBA'!K10)-1)*TBA!K10 | ... R8: ='Input Assumptions'!$D$15*(1+'Input Assumptions'!$D$17)^(SUM(TBA!$D$10:'TBA'!Q10)-1)*TBA!Q10 | U8: ='Input Assumptions'!$D$15*(1+'Input Assumptions'!$D$17)^(SUM(TBA!$D$10:'TBA'!T10)-1)*TBA!T10 | V8: ='Input Assumptions'!$D$15*(1+'Input Assumptions'!$D$17)^(SUM(TBA!$D$10:'TBA'!U10)-1)*TBA!U10 | W8: ='Input Assumptions'!$D$15*(1+'Input Assumptions'!$D$17)^(SUM(TBA!$D$10:'TBA'!V10)-1)*TBA!V10 | X8: ='Input Assumptions'!$D$15*(1+'Input Assumptions'!$D$17)^(SUM(TBA!$D$10:'TBA'!W10)-1)*TBA!W10 | Y8: ='Input Assumptions'!$D$15*(1+'Input Assumptions'!$D$17)^(SUM(TBA!$D$10:'TBA'!X10)-1)*TBA!X10 | Z8: ='Input Assumptions'!$D$15*(1+'Input Assumptions'!$D$17)^(SUM(TBA!$D$10:'TBA'!Y10)-1)*TBA!Y10 | AA8: ='Input Assumptions'!$D$15*(1+'Input Assumptions'!$D$17)^(SUM(TBA!$D$10:'TBA'!Z10)-1)*TBA!Z10 | AB8: ='Input Assumptions'!$D$15*(1+'Input Assumptions'!$D$17)^(SUM(TBA!$D$10:'TBA'!AA10)-1)*TBA!AA10 | ... AF8: ='Input Assumptions'!$D$15*(1+'Input Assumptions'!$D$17)^(SUM(TBA!$D$10:'TBA'!AE10)-1)*TBA!AE10 | AH8: ='Input Assumptions'!$D$15*(1+'Input Assumptions'!$D$17)^(SUM(TBA!$D$10:'TBA'!AG10)-1)*TBA!AG10 | AI8: ='Input Assumptions'!$D$15*(1+'Input Assumptions'!$D$17)^(SUM(TBA!$D$10:'TBA'!AH10)-1)*TBA!AH10 | AJ8: ='Input Assumptions'!$D$15*(1+'Input Assumptions'!$D$17)^(SUM(TBA!$D$10:'TBA'!AI10)-1)*TBA!AI10 | AK8: ='Input Assumptions'!$D$15*(1+'Input Assumptions'!$D$17)^(SUM(TBA!$D$10:'TBA'!AJ10)-1)*TBA!AJ10 | AL8: ='Input Assumptions'!$D$15*(1+'Input Assumptions'!$D$17)^(SUM(TBA!$D$10:'TBA'!AK10)-1)*TBA!AK10 | AM8: ='Input Assumptions'!$D$15*(1+'Input Assumptions'!$D$17)^(SUM(TBA!$D$10:'TBA'!AL10)-1)*TBA!AL10 | AN8: ='Input Assumptions'!$D$15*(1+'Input Assumptions'!$D$17)^(SUM(TBA!$D$10:'TBA'!AM10)-1)*TBA!AM10 | AO8: ='Input Assumptions'!$D$15*(1+'Input Assumptions'!$D$17)^(SUM(TBA!$D$10:'TBA'!AN10)-1)*TBA!AN10 | ... AR8: ='Input Assumptions'!$D$15*(1+'Input Assumptions'!$D$17)^(SUM(TBA!$D$10:'TBA'!AQ10)-1)*TBA!AQ10
B10: REVENUE - Passenger Car (PC) | C10: k£ | D10: =SUM(E10:AR10) | E10: =E7*'Input Assumptions'!$D$20/1000 | F10: =F7*'Input Assumptions'!$D$20/1000 | G10: =G7*'Input Assumptions'!$D$20/1000 | H10: =H7*'Input Assumptions'!$D$20/1000 | I10: =I7*'Input Assumptions'!$D$20/1000 | J10: =J7*'Input Assumptions'!$D$20/1000 | K10: =K7*'Input Assumptions'!$D$20/1000 | L10: =L7*'Input Assumptions'!$D$20/1000 | ... AL10: =AL7*'Input Assumptions'!$D$20/1000 | AN10: =AN7*'Input Assumptions'!$D$20/1000 | AO10: =AO7*'Input Assumptions'!$D$20/1000 | AP10: =AP7*'Input Assumptions'!$D$20/1000 | AQ10: =AQ7*'Input Assumptions'!$D$20/1000 | AR10: =AR7*'Input Assumptions'!$D$20/1000
B11: REVENUE - Heavy Vehicle (HV) | C11: k£ | D11: =SUM(E11:AR11) | E11: =E8*'Input Assumptions'!$D$21/1000 | F11: =F8*'Input Assumptions'!$D$21/1000 | H11: =H8*'Input Assumptions'!$D$21/1000 | I11: =I8*'Input Assumptions'!$D$21/1000 | J11: =J8*'Input Assumptions'!$D$21/1000 | K11: =K8*'Input Assumptions'!$D$21/1000 | L11: =L8*'Input Assumptions'!$D$21/1000 | M11: =M8*'Input Assumptions'!$D$21/1000 | N11: =N8*'Input Assumptions'!$D$21/1000 | O11: =O8*'Input Assumptions'!$D$21/1000 | Q11: =Q8*'Input Assumptions'!$D$21/1000 | R11: =R8*'Input Assumptions'!$D$21/1000 | S11: =S8*'Input Assumptions'!$D$21/1000 | T11: =T8*'Input Assumptions'!$D$21/1000 | U11: =U8*'Input Assumptions'!$D$21/1000 | V11: =V8*'Input Assumptions'!$D$21/1000 | W11: =W8*'Input Assumptions'!$D$21/1000 | X11: =X8*'Input Assumptions'!$D$21/1000 | ... AR11: =AR8*'Input Assumptions'!$D$21/1000
B12: Total Revenue (real) | C12: k£ | D12: =SUM(E12:AR12) | E12: =SUM(E10:E11) | F12: =SUM(F10:F11) | G12: =SUM(G10:G11) | H12: =SUM(H10:H11) | I12: =SUM(I10:I11) | J12: =SUM(J10:J11) | K12: =SUM(K10:K11) | L12: =SUM(L10:L11) | ... V12: =SUM(V10:V11) | X12: =SUM(X10:X11) | Y12: =SUM(Y10:Y11) | Z12: =SUM(Z10:Z11) | AA12: =SUM(AA10:AA11) | AB12: =SUM(AB10:AB11) | AC12: =SUM(AC10:AC11) | AD12: =SUM(AD10:AD11) | AE12: =SUM(AE10:AE11) | ... AJ12: =SUM(AJ10:AJ11) | AL12: =SUM(AL10:AL11) | AM12: =SUM(AM10:AM11) | AN12: =SUM(AN10:AN11) | AO12: =SUM(AO10:AO11) | AP12: =SUM(AP10:AP11) | AQ12: =SUM(AQ10:AQ11) | AR12: =SUM(AR10:AR11)
B14: Total Revenue (nominal) | C14: k£ | D14: =SUM(E14:AR14) | E14: =E12*(1+'Input Assumptions'!$D$18)^(E2-$E$2) | F14: =F12*(1+'Input Assumptions'!$D$18)^(F2-$E$2) | G14: =G12*(1+'Input Assumptions'!$D$18)^(G2-$E$2) | H14: =H12*(1+'Input Assumptions'!$D$18)^(H2-$E$2) | I14: =I12*(1+'Input Assumptions'!$D$18)^(I2-$E$2) | J14: =J12*(1+'Input Assumptions'!$D$18)^(J2-$E$2) | M14: =M12*(1+'Input Assumptions'!$D$18)^(M2-$E$2) | O14: =O12*(1+'Input Assumptions'!$D$18)^(O2-$E$2) | P14: =P12*(1+'Input Assumptions'!$D$18)^(P2-$E$2) | Q14: =Q12*(1+'Input Assumptions'!$D$18)^(Q2-$E$2) | R14: =R12*(1+'Input Assumptions'!$D$18)^(R2-$E$2) | T14: =T12*(1+'Input Assumptions'!$D$18)^(T2-$E$2) | U14: =U12*(1+'Input Assumptions'!$D$18)^(U2-$E$2) | V14: =V12*(1+'Input Assumptions'!$D$18)^(V2-$E$2) | W14: =W12*(1+'Input Assumptions'!$D$18)^(W2-$E$2) | Y14: =Y12*(1+'Input Assumptions'!$D$18)^(Y2-$E$2) | Z14: =Z12*(1+'Input Assumptions'!$D$18)^(Z2-$E$2) | AA14: =AA12*(1+'Input Assumptions'!$D$18)^(AA2-$E$2) | AB14: =AB12*(1+'Input Assumptions'!$D$18)^(AB2-$E$2) | AC14: =AC12*(1+'Input Assumptions'!$D$18)^(AC2-$E$2) | AD14: =AD12*(1+'Input Assumptions'!$D$18)^(AD2-$E$2) | AE14: =AE12*(1+'Input Assumptions'!$D$18)^(AE2-$E$2) | AF14: =AF12*(1+'Input Assumptions'!$D$18)^(AF2-$E$2) | AH14: =AH12*(1+'Input Assumptions'!$D$18)^(AH2-$E$2) | AI14: =AI12*(1+'Input Assumptions'!$D$18)^(AI2-$E$2) | AJ14: =AJ12*(1+'Input Assumptions'!$D$18)^(AJ2-$E$2) | AK14: =AK12*(1+'Input Assumptions'!$D$18)^(AK2-$E$2) | AL14: =AL12*(1+'Input Assumptions'!$D$18)^(AL2-$E$2) | AM14: =AM12*(1+'Input Assumptions'!$D$18)^(AM2-$E$2) | AN14: =AN12*(1+'Input Assumptions'!$D$18)^(AN2-$E$2) | AO14: =AO12*(1+'Input Assumptions'!$D$18)^(AO2-$E$2) | ... AR14: =AR12*(1+'Input Assumptions'!$D$18)^(AR2-$E$2)
B18: COSTS
B20: Maintenance & SPV costs | C20: k£ | E20: ='Input Assumptions'!$D$29/1000*(1+'Input Assumptions'!$D$31)^(E2-$E$2)*TBA!D10 | F20: ='Input Assumptions'!$D$29/1000*(1+'Input Assumptions'!$D$31)^(F2-$E$2)*TBA!E10 | G20: ='Input Assumptions'!$D$29/1000*(1+'Input Assumptions'!$D$31)^(G2-$E$2)*TBA!F10 | H20: ='Input Assumptions'!$D$29/1000*(1+'Input Assumptions'!$D$31)^(H2-$E$2)*TBA!G10 | I20: ='Input Assumptions'!$D$29/1000*(1+'Input Assumptions'!$D$31)^(I2-$E$2)*TBA!H10 | J20: ='Input Assumptions'!$D$29/1000*(1+'Input Assumptions'!$D$31)^(J2-$E$2)*TBA!I10 | K20: ='Input Assumptions'!$D$29/1000*(1+'Input Assumptions'!$D$31)^(K2-$E$2)*TBA!J10 | L20: ='Input Assumptions'!$D$29/1000*(1+'Input Assumptions'!$D$31)^(L2-$E$2)*TBA!K10 | ... N20: ='Input Assumptions'!$D$29/1000*(1+'Input Assumptions'!$D$31)^(N2-$E$2)*TBA!M10 | P20: ='Input Assumptions'!$D$29/1000*(1+'Input Assumptions'!$D$31)^(P2-$E$2)*TBA!O10 | Q20: ='Input Assumptions'!$D$29/1000*(1+'Input Assumptions'!$D$31)^(Q2-$E$2)*TBA!P10 | R20: ='Input Assumptions'!$D$29/1000*(1+'Input Assumptions'!$D$31)^(R2-$E$2)*TBA!Q10 | S20: ='Input Assumptions'!$D$29/1000*(1+'Input Assumptions'!$D$31)^(S2-$E$2)*TBA!R10 | T20: ='Input Assumptions'!$D$29/1000*(1+'Input Assumptions'!$D$31)^(T2-$E$2)*TBA!S10 | U20: ='Input Assumptions'!$D$29/1000*(1+'Input Assumptions'!$D$31)^(U2-$E$2)*TBA!T10 | V20: ='Input Assumptions'!$D$29/1000*(1+'Input Assumptions'!$D$31)^(V2-$E$2)*TBA!U10 | W20: ='Input Assumptions'!$D$29/1000*(1+'Input Assumptions'!$D$31)^(W2-$E$2)*TBA!V10 | ... AB20: ='Input Assumptions'!$D$29/1000*(1+'Input Assumptions'!$D$31)^(AB2-$E$2)*TBA!AA10 | AE20: ='Input Assumptions'!$D$29/1000*(1+'Input Assumptions'!$D$31)^(AE2-$E$2)*TBA!AD10 | AF20: ='Input Assumptions'!$D$29/1000*(1+'Input Assumptions'!$D$31)^(AF2-$E$2)*TBA!AE10 | AG20: ='Input Assumptions'!$D$29/1000*(1+'Input Assumptions'!$D$31)^(AG2-$E$2)*TBA!AF10 | AH20: ='Input Assumptions'!$D$29/1000*(1+'Input Assumptions'!$D$31)^(AH2-$E$2)*TBA!AG10 | AI20: ='Input Assumptions'!$D$29/1000*(1+'Input Assumptions'!$D$31)^(AI2-$E$2)*TBA!AH10 | AJ20: ='Input Assumptions'!$D$29/1000*(1+'Input Assumptions'!$D$31)^(AJ2-$E$2)*TBA!AI10 | AK20: ='Input Assumptions'!$D$29/1000*(1+'Input Assumptions'!$D$31)^(AK2-$E$2)*TBA!AJ10 | AL20: ='Input Assumptions'!$D$29/1000*(1+'Input Assumptions'!$D$31)^(AL2-$E$2)*TBA!AK10 | ... AR20: ='Input Assumptions'!$D$29/1000*(1+'Input Assumptions'!$D$31)^(AR2-$E$2)*TBA!AQ10
B21: Total Costs (nominal) | C21: k£ | D21: =SUM(E21:AR21) | E21: =SUM(E19:E20) | F21: =SUM(F19:F20) | H21: =SUM(H19:H20) | I21: =SUM(I19:I20) | J21: =SUM(J19:J20) | K21: =SUM(K19:K20) | L21: =SUM(L19:L20) | O21: =SUM(O19:O20) | P21: =SUM(P19:P20) | Q21: =SUM(Q19:Q20) | R21: =SUM(R19:R20) | S21: =SUM(S19:S20) | T21: =SUM(T19:T20) | U21: =SUM(U19:U20) | V21: =SUM(V19:V20) | ... AG21: =SUM(AG19:AG20) | AI21: =SUM(AI19:AI20) | AJ21: =SUM(AJ19:AJ20) | AK21: =SUM(AK19:AK20) | AL21: =SUM(AL19:AL20) | AN21: =SUM(AN19:AN20) | AO21: =SUM(AO19:AO20) | AP21: =SUM(AP19:AP20) | AQ21: =SUM(AQ19:AQ20) | AR21: =SUM(AR19:AR20)

Sheet Amortization
B2: Year | E2: 1 | F2: 2 | G2: 3 | H2: 4 | I2: 5 | J2: 6 | K2: 7 | L2: 8 | M2: 9 | N2: 10 | O2: 11 | P2: 12 | Q2: 13 | R2: 14 | S2: 15 | T2: 16 | U2: 17 | V2: 18 | W2: 19 | X2: 20 | Y2: 21 | Z2: 22 | AA2: 23 | AB2: 24 | AC2: 25 | AD2: 26 | AE2: 27 | AF2: 28 | AG2: 29 | AH2: 30 | AI2: 31 | AJ2: 32 | AK2: 33 | AL2: 34 | AM2: 35 | AN2: 36 | AO2: 37 | AP2: 38 | AQ2: 39 | AR2: 40
B5: D&A
B8: Asset Value opening (k£) | E8: =D10+Construction!E19 | F8: =E10+Construction!F19 | G8: =F10+Construction!G19 | H8: =G10+Construction!H19 | I8: =H10+Construction!I19 | J8: =I10+Construction!J19 | K8: =J10+Construction!K19 | L8: =K10+Construction!L19 | ... AR8: =AQ10+Construction!AR19
B10: Asset Value closing (k£) | E10: =E8+E13 | F10: =F8+F13 | G10: =G8+G13 | H10: =H8+H13 | I10: =I8+I13 | J10: =J8+J13 | K10: =K8+K13 | L10: =L8+L13 | ... AR10: =AR8+AR13
B13: Amortization (k£) | D13: =SUM(E13:AR13) | E13: =-Construction!$C$20/('Input Assumptions'!$D$8-'Input Assumptions'!$D$9)*TBA!D10 | F13: =-Construction!$C$20/('Input Assumptions'!$D$8-'Input Assumptions'!$D$9)*TBA!E10 | G13: =-Construction!$C$20/('Input Assumptions'!$D$8-'Input Assumptions'!$D$9)*TBA!F10 | H13: =-Construction!$C$20/('Input Assumptions'!$D$8-'Input Assumptions'!$D$9)*TBA!G10 | I13: =-Construction!$C$20/('Input Assumptions'!$D$8-'Input Assumptions'!$D$9)*TBA!H10 | J13: =-Construction!$C$20/('Input Assumptions'!$D$8-'Input Assumptions'!$D$9)*TBA!I10 | K13: =-Construction!$C$20/('Input Assumptions'!$D$8-'Input Assumptions'!$D$9)*TBA!J10 | L13: =-Construction!$C$20/('Input Assumptions'!$D$8-'Input Assumptions'!$D$9)*TBA!K10 | ... AR13: =-Construction!$C$20/('Input Assumptions'!$D$8-'Input Assumptions'!$D$9)*TBA!AQ10

Sheet Debt
B3: Year | F3: 1 | G3: 2 | H3: 3 | I3: 4 | J3: 5 | K3: 6 | L3: 7 | M3: 8 | N3: 9 | O3: 10 | P3: 11 | Q3: 12 | R3: 13 | S3: 14 | T3: 15 | U3: 16 | V3: 17 | W3: 18 | X3: 19 | Y3: 20 | Z3: 21 | AA3: 22 | AB3: 23 | AC3: 24 | AD3: 25 | AE3: 26 | AF3: 27 | AG3: 28 | AH3: 29 | AI3: 30 | AJ3: 31 | AK3: 32 | AL3: 33 | AM3: 34 | AN3: 35 | AO3: 36 | AP3: 37 | AQ3: 38 | AR3: 39 | AS3: 40
B6: Debt Repayment Schedule
B8: Opening Balance | C8: k£ | F8: =E11 | G8: =F11 | H8: =G11 | I8: =H11 | J8: =I11 | K8: =J11 | L8: =K11 | M8: =L11 | ... AS8: =AR11
B9: Drawdowns | C9: k£ | F9: =Construction!E34 | G9: =Construction!F34 | H9: =Construction!G34 | I9: =Construction!H34 | J9: =Construction!I34 | K9: =Construction!J34 | L9: =Construction!K34 | M9: =Construction!L34 | ... AS9: =Construction!AR34
B10: Principal Repayment | C10: k£ | F10: =IF(TBA!D18=1,PPMT('Input Assumptions'!$D$35+'Input Assumptions'!$D$36,Debt!F3-Debt!$I$3,TBA!$C$18,Construction!$C$34),0) | G10: =IF(TBA!E18=1,PPMT('Input Assumptions'!$D$35+'Input Assumptions'!$D$36,Debt!G3-Debt!$I$3,TBA!$C$18,Construction!$C$34),0) | H10: =IF(TBA!F18=1,PPMT('Input Assumptions'!$D$35+'Input Assumptions'!$D$36,Debt!H3-Debt!$I$3,TBA!$C$18,Construction!$C$34),0) | I10: =IF(TBA!G18=1,PPMT('Input Assumptions'!$D$35+'Input Assumptions'!$D$36,Debt!I3-Debt!$I$3,TBA!$C$18,Construction!$C$34),0) | J10: =IF(TBA!H18=1,PPMT('Input Assumptions'!$D$35+'Input Assumptions'!$D$36,Debt!J3-Debt!$I$3,TBA!$C$18,Construction!$C$34),0) | K10: =IF(TBA!I18=1,PPMT('Input Assumptions'!$D$35+'Input Assumptions'!$D$36,Debt!K3-Debt!$I$3,TBA!$C$18,Construction!$C$34),0) | L10: =IF(TBA!J18=1,PPMT('Input Assumptions'!$D$35+'Input Assumptions'!$D$36,Debt!L3-Debt!$I$3,TBA!$C$18,Construction!$C$34),0) | M10: =IF(TBA!K18=1,PPMT('Input Assumptions'!$D$35+'Input Assumptions'!$D$36,Debt!M3-Debt!$I$3,TBA!$C$18,Construction!$C$34),0) | ... AS10: =IF(TBA!AQ18=1,PPMT('Input Assumptions'!$D$35+'Input Assumptions'!$D$36,Debt!AS3-Debt!$I$3,TBA!$C$18,Construction!$C$34),0)
B11: Closing Balance | C11: k£ | F11: =SUM(F8:F10) | G11: =SUM(G8:G10) | H11: =SUM(H8:H10) | I11: =SUM(I8:I10) | J11: =SUM(J8:J10) | K11: =SUM(K8:K10) | L11: =SUM(L8:L10) | M11: =SUM(M8:M10) | ... AS11: =SUM(AS8:AS10)
B14: Interests | C14: k£ | F14: =-('Input Assumptions'!$D$35+'Input Assumptions'!$D$36)*Debt!F8*TBA!D18 | G14: =-('Input Assumptions'!$D$35+'Input Assumptions'!$D$36)*Debt!G8*TBA!E18 | H14: =-('Input Assumptions'!$D$35+'Input Assumptions'!$D$36)*Debt!H8*TBA!F18 | I14: =-('Input Assumptions'!$D$35+'Input Assumptions'!$D$36)*Debt!I8*TBA!G18 | J14: =-('Input Assumptions'!$D$35+'Input Assumptions'!$D$36)*Debt!J8*TBA!H18 | K14: =-('Input Assumptions'!$D$35+'Input Assumptions'!$D$36)*Debt!K8*TBA!I18 | L14: =-('Input Assumptions'!$D$35+'Input Assumptions'!$D$36)*Debt!L8*TBA!J18 | M14: =-('Input Assumptions'!$D$35+'Input Assumptions'!$D$36)*Debt!M8*TBA!K18 | ... AS14: =-('Input Assumptions'!$D$35+'Input Assumptions'!$D$36)*Debt!AS8*TBA!AQ18
B17: Debt service | C17: k£ | F17: =(F10+F14)*TBA!D18 | G17: =(G10+G14)*TBA!E18 | H17: =(H10+H14)*TBA!F18 | I17: =(I10+I14)*TBA!G18 | J17: =(J10+J14)*TBA!H18 | K17: =(K10+K14)*TBA!I18 | L17: =(L10+L14)*TBA!J18 | M17: =(M10+M14)*TBA!K18 | ... AS17: =(AS10+AS14)*TBA!AQ18

Sheet P&L
B2: Year | F2: 1 | G2: 2 | H2: 3 | I2: 4 | J2: 5 | K2: 6 | L2: 7 | M2: 8 | N2: 9 | O2: 10 | P2: 11 | Q2: 12 | R2: 13 | S2: 14 | T2: 15 | U2: 16 | V2: 17 | W2: 18 | X2: 19 | Y2: 20 | Z2: 21 | AA2: 22 | AB2: 23 | AC2: 24 | AD2: 25 | AE2: 26 | AF2: 27 | AG2: 28 | AH2: 29 | AI2: 30 | AJ2: 31 | AK2: 32 | AL2: 33 | AM2: 34 | AN2: 35 | AO2: 36 | AP2: 37 | AQ2: 38 | AR2: 39 | AS2: 40
B6: P&L
B9: Gross revenues | C9: k£ | F9: =Operation!E14 | G9: =Operation!F14 | H9: =Operation!G14 | I9: =Operation!H14 | J9: =Operation!I14 | K9: =Operation!J14 | M9: =Operation!L14 | N9: =Operation!M14 | O9: =Operation!N14 | Q9: =Operation!P14 | R9: =Operation!Q14 | S9: =Operation!R14 | T9: =Operation!S14 | U9: =Operation!T14 | V9: =Operation!U14 | W9: =Operation!V14 | X9: =Operation!W14 | ... AS9: =Operation!AR14
B11: OPEX | C11: k£ | F11: =-Operation!E21 | G11: =-Operation!F21 | H11: =-Operation!G21 | I11: =-Operation!H21 | J11: =-Operation!I21 | K11: =-Operation!J21 | L11: =-Operation!K21 | M11: =-Operation!L21 | ... AJ11: =-Operation!AI21 | AL11: =-Operation!AK21 | AM11: =-Operation!AL21 | AN11: =-Operation!AM21 | AO11: =-Operation!AN21 | AP11: =-Operation!AO21 | AQ11: =-Operation!AP21 | AR11: =-Operation!AQ21 | AS11: =-Operation!AR21
B13: EBITDA | C13: k£ | F13: =SUM(F9:F12) | H13: =SUM(H9:H12) | I13: =SUM(I9:I12) | J13: =SUM(J9:J12) | K13: =SUM(K9:K12) | L13: =SUM(L9:L12) | M13: =SUM(M9:M12) | N13: =SUM(N9:N12) | O13: =SUM(O9:O12) | ... AQ13: =SUM(AQ9:AQ12) | AS13: =SUM(AS9:AS12)
B15: Amortization | C15: k£ | F15: =Amortization!E13 | H15: =Amortization!G13 | I15: =Amortization!H13 | J15: =Amortization!I13 | K15: =Amortization!J13 | L15: =Amortization!K13 | M15: =Amortization!L13 | N15: =Amortization!M13 | O15: =Amortization!N13 | ... Q15: =Amortization!P13 | S15: =Amortization!R13 | T15: =Amortization!S13 | U15: =Amortization!T13 | V15: =Amortization!U13 | W15: =Amortization!V13 | X15: =Amortization!W13 | Z15: =Amortization!Y13 | AA15: =Amortization!Z13 | AB15: =Amortization!AA13 | AC15: =Amortization!AB13 | AD15: =Amortization!AC13 | AE15: =Amortization!AD13 | AF15: =Amortization!AE13 | AG15: =Amortization!AF13 | ... AI15: =Amortization!AH13 | AK15: =Amortization!AJ13 | AL15: =Amortization!AK13 | AM15: =Amortization!AL13 | AN15: =Amortization!AM13 | AO15: =Amortization!AN13 | AP15: =Amortization!AO13 | AR15: =Amortization!AQ13 | AS15: =Amortization!AR13
B17: EBIT | C17: k£ | F17: =SUM(F13:F16) | G17: =SUM(G13:G16) | H17: =SUM(H13:H16) | I17: =SUM(I13:I16) | J17: =SUM(J13:J16) | K17: =SUM(K13:K16) | L17: =SUM(L13:L16) | M17: =SUM(M13:M16) | ... AS17: =SUM(AS13:AS16)
B19: Interest | C19: k£ | F19: =Debt!F14 | G19: =Debt!G14 | H19: =Debt!H14 | I19: =Debt!I14 | J19: =Debt!J14 | K19: =Debt!K14 | L19: =Debt!L14 | M19: =Debt!M14 | ... AI19: =Debt!AI14 | AK19: =Debt!AK14 | AL19: =Debt!AL14 | AM19: =Debt!AM14 | AN19: =Debt!AN14 | AO19: =Debt!AO14 | AP19: =Debt!AP14 | AQ19: =Debt!AQ14 | AR19: =Debt!AR14 | AS19: =Debt!AS14
B21: EBT (Taxable Profit) | C21: k£ | F21: =SUM(F17:F20) | G21: =SUM(G17:G20) | H21: =SUM(H17:H20) | I21: =SUM(I17:I20) | J21: =SUM(J17:J20) | K21: =SUM(K17:K20) | M21: =SUM(M17:M20) | N21: =SUM(N17:N20) | O21: =SUM(O17:O20) | P21: =SUM(P17:P20) | Q21: =SUM(Q17:Q20) | R21: =SUM(R17:R20) | S21: =SUM(S17:S20) | T21: =SUM(T17:T20) | ... Y21: =SUM(Y17:Y20) | AA21: =SUM(AA17:AA20) | AB21: =SUM(AB17:AB20) | AC21: =SUM(AC17:AC20) | AD21: =SUM(AD17:AD20) | AE21: =SUM(AE17:AE20) | AF21: =SUM(AF17:AF20) | AG21: =SUM(AG17:AG20) | AI21: =SUM(AI17:AI20) | AJ21: =SUM(AJ17:AJ20) | AK21: =SUM(AK17:AK20) | AL21: =SUM(AL17:AL20) | AM21: =SUM(AM17:AM20) | AN21: =SUM(AN17:AN20) | AO21: =SUM(AO17:AO20) | AP21: =SUM(AP17:AP20) | ... AS21: =SUM(AS17:AS20)
B23: Income Tax | C23: k£ | F23: =IF(F21<0,0,-'Input Assumptions'!$D$44*'P&L'!F21) | G23: =IF(G21<0,0,-'Input Assumptions'!$D$44*'P&L'!G21) | I23: =IF(I21<0,0,-'Input Assumptions'!$D$44*'P&L'!I21) | J23: =IF(J21<0,0,-'Input Assumptions'!$D$44*'P&L'!J21) | K23: =IF(K21<0,0,-'Input Assumptions'!$D$44*'P&L'!K21) | L23: =IF(L21<0,0,-'Input Assumptions'!$D$44*'P&L'!L21) | M23: =IF(M21<0,0,-'Input Assumptions'!$D$44*'P&L'!M21) | N23: =IF(N21<0,0,-'Input Assumptions'!$D$44*'P&L'!N21) | O23: =IF(O21<0,0,-'Input Assumptions'!$D$44*'P&L'!O21) | P23: =IF(P21<0,0,-'Input Assumptions'!$D$44*'P&L'!P21) | ... Y23: =IF(Y21<0,0,-'Input Assumptions'!$D$44*'P&L'!Y21) | AA23: =IF(AA21<0,0,-'Input Assumptions'!$D$44*'P&L'!AA21) | AB23: =IF(AB21<0,0,-'Input Assumptions'!$D$44*'P&L'!AB21) | AC23: =IF(AC21<0,0,-'Input Assumptions'!$D$44*'P&L'!AC21) | AD23: =IF(AD21<0,0,-'Input Assumptions'!$D$44*'P&L'!AD21) | AE23: =IF(AE21<0,0,-'Input Assumptions'!$D$44*'P&L'!AE21) | AF23: =IF(AF21<0,0,-'Input Assumptions'!$D$44*'P&L'!AF21) | AG23: =IF(AG21<0,0,-'Input Assumptions'!$D$44*'P&L'!AG21) | AH23: =IF(AH21<0,0,-'Input Assumptions'!$D$44*'P&L'!AH21) | ... AL23: =IF(AL21<0,0,-'Input Assumptions'!$D$44*'P&L'!AL21) | AN23: =IF(AN21<0,0,-'Input Assumptions'!$D$44*'P&L'!AN21) | AO23: =IF(AO21<0,0,-'Input Assumptions'!$D$44*'P&L'!AO21) | AP23: =IF(AP21<0,0,-'Input Assumptions'!$D$44*'P&L'!AP21) | AQ23: =IF(AQ21<0,0,-'Input Assumptions'!$D$44*'P&L'!AQ21) | AR23: =IF(AR21<0,0,-'Input Assumptions'!$D$44*'P&L'!AR21)
B25: Net Profit | C25: k£ | F25: =SUM(F21:F24) | G25: =SUM(G21:G24) | H25: =SUM(H21:H24) | J25: =SUM(J21:J24) | K25: =SUM(K21:K24) | L25: =SUM(L21:L24) | M25: =SUM(M21:M24) | N25: =SUM(N21:N24) | O25: =SUM(O21:O24) | Q25: =SUM(Q21:Q24) | S25: =SUM(S21:S24) | U25: =SUM(U21:U24) | V25: =SUM(V21:V24) | W25: =SUM(W21:W24) | X25: =SUM(X21:X24) | Y25: =SUM(Y21:Y24) | Z25: =SUM(Z21:Z24) | AA25: =SUM(AA21:AA24) | AB25: =SUM(AB21:AB24) | AD25: =SUM(AD21:AD24) | AE25: =SUM(AE21:AE24) | AF25: =SUM(AF21:AF24) | AG25: =SUM(AG21:AG24) | AH25: =SUM(AH21:AH24) | AI25: =SUM(AI21:AI24) | AJ25: =SUM(AJ21:AJ24) | AK25: =SUM(AK21:AK24) | ... AS25: =SUM(AS21:AS24)

Sheet CFS
B3: Year | F3: 1 | G3: 2 | H3: 3 | I3: 4 | J3: 5 | K3: 6 | L3: 7 | M3: 8 | N3: 9 | O3: 10 | P3: 11 | Q3: 12 | R3: 13 | S3: 14 | T3: 15 | U3: 16 | V3: 17 | W3: 18 | X3: 19 | Y3: 20 | Z3: 21 | AA3: 22 | AB3: 23 | AC3: 24 | AD3: 25 | AE3: 26 | AF3: 27 | AG3: 28 | AH3: 29 | AI3: 30 | AJ3: 31 | AK3: 32 | AL3: 33 | AM3: 34 | AN3: 35 | AO3: 36 | AP3: 37 | AQ3: 38 | AR3: 39 | AS3: 40
B6: Cashflow Statement
B8: Gross Revenues | C8: k£ | F8: =Operation!E14 | G8: =Operation!F14 | H8: =Operation!G14 | I8: =Operation!H14 | J8: =Operation!I14 | K8: =Operation!J14 | L8: =Operation!K14 | M8: =Operation!L14 | ... R8: =Operation!Q14 | T8: =Operation!S14 | U8: =Operation!T14 | V8: =Operation!U14 | W8: =Operation!V14 | X8: =Operation!W14 | Y8: =Operation!X14 | Z8: =Operation!Y14 | AA8: =Operation!Z14 | ... AS8: =Operation!AR14
B10: OPEX (Maintenance & SPV Costs) | C10: k£ | F10: =-Operation!E21 | H10: =-Operation!G21 | J10: =-Operation!I21 | K10: =-Operation!J21 | L10: =-Operation!K21 | M10: =-Operation!L21 | N10: =-Operation!M21 | O10: =-Operation!N21 | P10: =-Operation!O21 | Q10: =-Operation!P21 | ... AA10: =-Operation!Z21 | AC10: =-Operation!AB21 | AD10: =-Operation!AC21 | AE10: =-Operation!AD21 | AF10: =-Operation!AE21 | AG10: =-Operation!AF21 | AH10: =-Operation!AG21 | AI10: =-Operation!AH21 | AJ10: =-Operation!AI21 | ... AS10: =-Operation!AR21
B12: Income Tax | C12: k£ | F12: ='P&L'!F23 | G12: ='P&L'!G23 | H12: ='P&L'!H23 | I12: ='P&L'!I23 | J12: ='P&L'!J23 | K12: ='P&L'!K23 | L12: ='P&L'!L23 | M12: ='P&L'!M23 | ... S12: ='P&L'!S23 | U12: ='P&L'!U23 | V12: ='P&L'!V23 | W12: ='P&L'!W23 | X12: ='P&L'!X23 | Y12: ='P&L'!Y23 | AA12: ='P&L'!AA23 | AB12: ='P&L'!AB23 | AC12: ='P&L'!AC23 | AD12: ='P&L'!AD23 | AE12: ='P&L'!AE23 | AF12: ='P&L'!AF23 | AH12: ='P&L'!AH23 | AI12: ='P&L'!AI23 | AJ12: ='P&L'!AJ23 | AK12: ='P&L'!AK23 | AL12: ='P&L'!AL23 | AN12: ='P&L'!AN23 | AO12: ='P&L'!AO23 | AP12: ='P&L'!AP23 | AQ12: ='P&L'!AQ23 | AR12: ='P&L'!AR23 | AS12: ='P&L'!AS23
B14: Cash Flow Available for Debt Service (CFADS) | C14: k£ | F14: =SUM(F8:F13) | G14: =SUM(G8:G13) | I14: =SUM(I8:I13) | J14: =SUM(J8:J13) | L14: =SUM(L8:L13) | M14: =SUM(M8:M13) | N14: =SUM(N8:N13) | Q14: =SUM(Q8:Q13) | R14: =SUM(R8:R13) | S14: =SUM(S8:S13) | T14: =SUM(T8:T13) | U14: =SUM(U8:U13) | V14: =SUM(V8:V13) | W14: =SUM(W8:W13) | X14: =SUM(X8:X13) | ... Z14: =SUM(Z8:Z13) | AB14: =SUM(AB8:AB13) | AC14: =SUM(AC8:AC13) | AD14: =SUM(AD8:AD13) | AE14: =SUM(AE8:AE13) | AF14: =SUM(AF8:AF13) | AG14: =SUM(AG8:AG13) | AH14: =SUM(AH8:AH13) | AI14: =SUM(AI8:AI13) | ... AO14: =SUM(AO8:AO13) | AQ14: =SUM(AQ8:AQ13) | AR14: =SUM(AR8:AR13) | AS14: =SUM(AS8:AS13)
B16: Interest | C16: k£ | F16: =Debt!F14 | G16: =Debt!G14 | H16: =Debt!H14 | I16: =Debt!I14 | J16: =Debt!J14 | K16: =Debt!K14 | L16: =Debt!L14 | M16: =Debt!M14 | ... AS16: =Debt!AS14
B17: Principal repayment | C17: k£ | F17: =Debt!F10 | H17: =Debt!H10 | I17: =Debt!I10 | J17: =Debt!J10 | K17: =Debt!K10 | L17: =Debt!L10 | M17: =Debt!M10 | N17: =Debt!N10 | O17: =Debt!O10 | ... AS17: =Debt!AS10
B19: Cash Flow Available for Equity | C19: k£ | F19: =F14+F16+F17 | G19: =G14+G16+G17 | H19: =H14+H16+H17 | I19: =I14+I16+I17 | K19: =K14+K16+K17 | L19: =L14+L16+L17 | M19: =M14+M16+M17 | N19: =N14+N16+N17 | O19: =O14+O16+O17 | P19: =P14+P16+P17 | Q19: =Q14+Q16+Q17 | R19: =R14+R16+R17 | ... AE19: =AE14+AE16+AE17 | AG19: =AG14+AG16+AG17 | AI19: =AI14+AI16+AI17 | AJ19: =AJ14+AJ16+AJ17 | AK19: =AK14+AK16+AK17 | AL19: =AL14+AL16+AL17 | AM19: =AM14+AM16+AM17 | AO19: =AO14+AO16+AO17 | AQ19: =AQ14+AQ16+AQ17 | AR19: =AR14+AR16+AR17 | AS19: =AS14+AS16+AS17
B21: Dividends | C21: k£ | F21: =-MIN(MAX('Input Assumptions'!$D$45*'P&L'!F25,0),MAX(F19+E25,0)) | G21: =-MIN(MAX('Input Assumptions'!$D$45*'P&L'!G25,0),MAX(G19+F25,0)) | H21: =-MIN(MAX('Input Assumptions'!$D$45*'P&L'!H25,0),MAX(H19+G25,0)) | I21: =-MIN(MAX('Input Assumptions'!$D$45*'P&L'!I25,0),MAX(I19+H25,0)) | J21: =-MIN(MAX('Input Assumptions'!$D$45*'P&L'!J25,0),MAX(J19+I25,0)) | K21: =-MIN(MAX('Input Assumptions'!$D$45*'P&L'!K25,0),MAX(K19+J25,0)) | L21: =-MIN(MAX('Input Assumptions'!$D$45*'P&L'!L25,0),MAX(L19+K25,0)) | M21: =-MIN(MAX('Input Assumptions'!$D$45*'P&L'!M25,0),MAX(M19+L25,0)) | ... AS21: =-MIN(MAX('Input Assumptions'!$D$45*'P&L'!AS25,0),MAX(AS19+AR25,0))
B23: Net Cash Flow | C23: k£ | F23: =F19+F21 | G23: =G19+G21 | H23: =H19+H21 | I23: =I19+I21 | J23: =J19+J21 | K23: =K19+K21 | L23: =L19+L21 | M23: =M19+M21 | ... AB23: =AB19+AB21 | AD23: =AD19+AD21 | AE23: =AE19+AE21 | AF23: =AF19+AF21 | AG23: =AG19+AG21 | AH23: =AH19+AH21 | AI23: =AI19+AI21 | AJ23: =AJ19+AJ21 | AK23: =AK19+AK21 | ... AN23: =AN19+AN21 | AP23: =AP19+AP21 | AQ23: =AQ19+AQ21 | AR23: =AR19+AR21 | AS23: =AS19+AS21
B25: Cash in hands | C25: k£ | F25: =E25+F23 | G25: =F25+G23 | H25: =G25+H23 | I25: =H25+I23 | J25: =I25+J23 | K25: =J25+K23 | L25: =K25+L23 | M25: =L25+M23 | ... AR25: =AQ25+AR23

Sheet Balance Sheet
B3: Year | F3: 1 | G3: 2 | H3: 3 | I3: 4 | J3: 5 | K3: 6 | L3: 7 | M3: 8 | N3: 9 | O3: 10 | P3: 11 | Q3: 12 | R3: 13 | S3: 14 | T3: 15 | U3: 16 | V3: 17 | W3: 18 | X3: 19 | Y3: 20 | Z3: 21 | AA3: 22 | AB3: 23 | AC3: 24 | AD3: 25 | AE3: 26 | AF3: 27 | AG3: 28 | AH3: 29 | AI3: 30 | AJ3: 31 | AK3: 32 | AL3: 33 | AM3: 34 | AN3: 35 | AO3: 36 | AP3: 37 | AQ3: 38 | AR3: 39 | AS3: 40
B6: Balance Sheet
B8: Asset | C8: k£ | F8: =Amortization!E10 | G8: =Amortization!F10 | H8: =Amortization!G10 | I8: =Amortization!H10 | J8: =Amortization!I10 | K8: =Amortization!J10 | L8: =Amortization!K10 | M8: =Amortization!L10 | P8: =Amortization!O10 | Q8: =Amortization!P10 | R8: =Amortization!Q10 | S8: =Amortization!R10 | U8: =Amortization!T10 | V8: =Amortization!U10 | W8: =Amortization!V10 | X8: =Amortization!W10 | Z8: =Amortization!Y10 | AA8: =Amortization!Z10 | AB8: =Amortization!AA10 | AC8: =Amortization!AB10 | AD8: =Amortization!AC10 | AE8: =Amortization!AD10 | AF8: =Amortization!AE10 | AG8: =Amortization!AF10 | ... AS8: =Amortization!AR10
B9: Cash in hand | C9: k£ | F9: =CFS!F25 | G9: =CFS!G25 | H9: =CFS!H25 | I9: =CFS!I25 | J9: =CFS!J25 | L9: =CFS!L25 | M9: =CFS!M25 | O9: =CFS!O25 | P9: =CFS!P25 | Q9: =CFS!Q25 | R9: =CFS!R25 | S9: =CFS!S25 | T9: =CFS!T25 | U9: =CFS!U25 | V9: =CFS!V25 | ... AC9: =CFS!AC25 | AE9: =CFS!AE25 | AF9: =CFS!AF25 | AG9: =CFS!AG25 | AH9: =CFS!AH25 | AI9: =CFS!AI25 | AJ9: =CFS!AJ25 | AK9: =CFS!AK25 | AL9: =CFS!AL25 | ... AP9: =CFS!AP25 | AR9: =CFS!AR25
B10: Total | C10: k£ | F10: =SUM(F8:F9) | G10: =SUM(G8:G9) | H10: =SUM(H8:H9) | I10: =SUM(I8:I9) | K10: =SUM(K8:K9) | L10: =SUM(L8:L9) | M10: =SUM(M8:M9) | N10: =SUM(N8:N9) | O10: =SUM(O8:O9) | P10: =SUM(P8:P9) | Q10: =SUM(Q8:Q9) | R10: =SUM(R8:R9) | ... W10: =SUM(W8:W9) | Y10: =SUM(Y8:Y9) | Z10: =SUM(Z8:Z9) | AA10: =SUM(AA8:AA9) | AB10: =SUM(AB8:AB9) | AC10: =SUM(AC8:AC9) | AD10: =SUM(AD8:AD9) | AE10: =SUM(AE8:AE9) | AF10: =SUM(AF8:AF9) | ... AS10: =SUM(AS8:AS9)
B13: Equity | C13: k£ | F13: =SUM(Construction!$E$26:E26) | G13: =SUM(Construction!$E$26:F26) | H13: =SUM(Construction!$E$26:G26) | I13: =SUM(Construction!$E$26:H26) | J13: =SUM(Construction!$E$26:I26) | K13: =SUM(Construction!$E$26:J26) | L13: =SUM(Construction!$E$26:K26) | M13: =SUM(Construction!$E$26:L26) | ... X13: =SUM(Construction!$E$26:W26) | Z13: =SUM(Construction!$E$26:Y26) | AA13: =SUM(Construction!$E$26:Z26) | AB13: =SUM(Construction!$E$26:AA26) | AC13: =SUM(Construction!$E$26:AB26) | AD13: =SUM(Construction!$E$26:AC26) | AE13: =SUM(Construction!$E$26:AD26) | AF13: =SUM(Construction!$E$26:AE26) | AG13: =SUM(Construction!$E$26:AF26) | ... AS13: =SUM(Construction!$E$26:AR26)
B14: Retained Earnings | C14: k£ | G14: ='P&L'!G25+CFS!G21+'Balance Sheet'!F14 | H14: ='P&L'!H25+CFS!H21+'Balance Sheet'!G14 | I14: ='P&L'!I25+CFS!I21+'Balance Sheet'!H14 | K14: ='P&L'!K25+CFS!K21+'Balance Sheet'!J14 | L14: ='P&L'!L25+CFS!L21+'Balance Sheet'!K14 | M14: ='P&L'!M25+CFS!M21+'Balance Sheet'!L14 | N14: ='P&L'!N25+CFS!N21+'Balance Sheet'!M14 | O14: ='P&L'!O25+CFS!O21+'Balance Sheet'!N14 | P14: ='P&L'!P25+CFS!P21+'Balance Sheet'!O14 | Q14: ='P&L'!Q25+CFS!Q21+'Balance Sheet'!P14 | R14: ='P&L'!R25+CFS!R21+'Balance Sheet'!Q14 | ... X14: ='P&L'!X25+CFS!X21+'Balance Sheet'!W14 | Z14: ='P&L'!Z25+CFS!Z21+'Balance Sheet'!Y14 | AA14: ='P&L'!AA25+CFS!AA21+'Balance Sheet'!Z14 | AB14: ='P&L'!AB25+CFS!AB21+'Balance Sheet'!AA14 | AC14: ='P&L'!AC25+CFS!AC21+'Balance Sheet'!AB14 | AD14: ='P&L'!AD25+CFS!AD21+'Balance Sheet'!AC14 | AE14: ='P&L'!AE25+CFS!AE21+'Balance Sheet'!AD14 | AF14: ='P&L'!AF25+CFS!AF21+'Balance Sheet'!AE14 | AG14: ='P&L'!AG25+CFS!AG21+'Balance Sheet'!AF14 | ... AS14: ='P&L'!AS25+CFS!AS21+'Balance Sheet'!AR14
B15: Debt | C15: k£ | F15: =Debt!F11 | G15: =Debt!G11 | H15: =Debt!H11 | I15: =Debt!I11 | J15: =Debt!J11 | K15: =Debt!K11 | L15: =Debt!L11 | M15: =Debt!M11 | ... R15: =Debt!R11 | T15: =Debt!T11 | U15: =Debt!U11 | V15: =Debt!V11 | W15: =Debt!W11 | X15: =Debt!X11 | Z15: =Debt!Z11 | AA15: =Debt!AA11 | AB15: =Debt!AB11 | AC15: =Debt!AC11 | AD15: =Debt!AD11 | AE15: =Debt!AE11 | AF15: =Debt!AF11 | AG15: =Debt!AG11 | AI15: =Debt!AI11 | AJ15: =Debt!AJ11 | AK15: =Debt!AK11 | AL15: =Debt!AL11 | AM15: =Debt!AM11 | AN15: =Debt!AN11 | AO15: =Debt!AO11 | AP15: =Debt!AP11 | ... AS15: =Debt!AS11
B16: Total | C16: k£ | F16: =SUM(F13:F15) | G16: =SUM(G13:G15) | H16: =SUM(H13:H15) | I16: =SUM(I13:I15) | J16: =SUM(J13:J15) | K16: =SUM(K13:K15) | L16: =SUM(L13:L15) | M16: =SUM(M13:M15) | ... P16: =SUM(P13:P15) | R16: =SUM(R13:R15) | S16: =SUM(S13:S15) | T16: =SUM(T13:T15) | U16: =SUM(U13:U15) | V16: =SUM(V13:V15) | W16: =SUM(W13:W15) | X16: =SUM(X13:X15) | Y16: =SUM(Y13:Y15) | ... AD16: =SUM(AD13:AD15) | AF16: =SUM(AF13:AF15) | AG16: =SUM(AG13:AG15) | AH16: =SUM(AH13:AH15) | AI16: =SUM(AI13:AI15) | AK16: =SUM(AK13:AK15) | AL16: =SUM(AL13:AL15) | AM16: =SUM(AM13:AM15) | AN16: =SUM(AN13:AN15) | AO16: =SUM(AO13:AO15) | AP16: =SUM(AP13:AP15) | AQ16: =SUM(AQ13:AQ15) | AR16: =SUM(AR13:AR15) | AS16: =SUM(AS13:AS15)
E19: CHECK | F19: =F10-F16<0.01 | G19: =G10-G16<0.01 | H19: =H10-H16<0.01 | J19: =J10-J16<0.01 | K19: =K10-K16<0.01 | L19: =L10-L16<0.01 | N19: =N10-N16<0.01 | O19: =O10-O16<0.01 | P19: =P10-P16<0.01 | Q19: =Q10-Q16<0.01 | R19: =R10-R16<0.01 | S19: =S10-S16<0.01 | T19: =T10-T16<0.01 | U19: =U10-U16<0.01 | ... AS19: =AS10-AS16<0.01

Sheet Ratios
B3: Year | F3: 1 | G3: 2 | H3: 3 | I3: 4 | J3: 5 | K3: 6 | L3: 7 | M3: 8 | N3: 9 | O3: 10 | P3: 11 | Q3: 12 | R3: 13 | S3: 14 | T3: 15 | U3: 16 | V3: 17 | W3: 18 | X3: 19 | Y3: 20 | Z3: 21 | AA3: 22 | AB3: 23 | AC3: 24 | AD3: 25 | AE3: 26 | AF3: 27 | AG3: 28 | AH3: 29 | AI3: 30 | AJ3: 31 | AK3: 32 | AL3: 33 | AM3: 34 | AN3: 35 | AO3: 36 | AP3: 37 | AQ3: 38 | AR3: 39 | AS3: 40
B6: Project IRR
B8: CAPEX (incl. SPV costs) | C8: k£ | F8: =-Construction!E12 | G8: =-Construction!F12 | H8: =-Construction!G12 | I8: =-Construction!H12 | J8: =-Construction!I12 | K8: =-Construction!J12 | L8: =-Construction!K12 | M8: =-Construction!L12 | ... U8: =-Construction!T12 | W8: =-Construction!V12 | X8: =-Construction!W12 | Y8: =-Construction!X12 | Z8: =-Construction!Y12 | AA8: =-Construction!Z12 | AB8: =-Construction!AA12 | AC8: =-Construction!AB12 | AD8: =-Construction!AC12 | ... AS8: =-Construction!AR12
B9: Arrangement fee | C9: k£ | F9: =-Construction!E13 | G9: =-Construction!F13 | H9: =-Construction!G13 | I9: =-Construction!H13 | J9: =-Construction!I13 | K9: =-Construction!J13 | L9: =-Construction!K13 | M9: =-Construction!L13 | ... P9: =-Construction!O13 | R9: =-Construction!Q13 | S9: =-Construction!R13 | T9: =-Construction!S13 | U9: =-Construction!T13 | V9: =-Construction!U13 | W9: =-Construction!V13 | X9: =-Construction!W13 | Y9: =-Construction!X13 | ... AS9: =-Construction!AR13
B10: Engagement fee | C10: k£ | F10: =-Construction!E14 | G10: =-Construction!F14 | H10: =-Construction!G14 | I10: =-Construction!H14 | J10: =-Construction!I14 | K10: =-Construction!J14 | L10: =-Construction!K14 | M10: =-Construction!L14 | ... AS10: =-Construction!AR14
B11: Capitalized Interests | C11: k£ | F11: =-Construction!E15 | G11: =-Construction!F15 | H11: =-Construction!G15 | I11: =-Construction!H15 | J11: =-Construction!I15 | K11: =-Construction!J15 | L11: =-Construction!K15 | M11: =-Construction!L15 | ... AF11: =-Construction!AE15 | AH11: =-Construction!AG15 | AJ11: =-Construction!AI15 | AK11: =-Construction!AJ15 | AL11: =-Construction!AK15 | AM11: =-Construction!AL15 | AN11: =-Construction!AM15 | AO11: =-Construction!AN15 | AP11: =-Construction!AO15 | AQ11: =-Construction!AP15 | ... AS11: =-Construction!AR15
B12: Total Investment | C12: k£ | E12: =SUM(F12:AS12) | F12: =SUM(F8:F11) | H12: =SUM(H8:H11) | J12: =SUM(J8:J11) | K12: =SUM(K8:K11) | L12: =SUM(L8:L11) | M12: =SUM(M8:M11) | N12: =SUM(N8:N11) | O12: =SUM(O8:O11) | Q12: =SUM(Q8:Q11) | R12: =SUM(R8:R11) | S12: =SUM(S8:S11) | T12: =SUM(T8:T11) | U12: =SUM(U8:U11) | V12: =SUM(V8:V11) | W12: =SUM(W8:W11) | X12: =SUM(X8:X11) | ... AL12: =SUM(AL8:AL11) | AN12: =SUM(AN8:AN11) | AO12: =SUM(AO8:AO11) | AP12: =SUM(AP8:AP11) | AQ12: =SUM(AQ8:AQ11) | AR12: =SUM(AR8:AR11) | AS12: =SUM(AS8:AS11)
B14: Revenues PC+HV | C14: k£ | F14: =Operation!E14 | G14: =Operation!F14 | H14: =Operation!G14 | I14: =Operation!H14 | J14: =Operation!I14 | K14: =Operation!J14 | M14: =Operation!L14 | N14: =Operation!M14 | O14: =Operation!N14 | Q14: =Operation!P14 | R14: =Operation!Q14 | S14: =Operation!R14 | T14: =Operation!S14 | U14: =Operation!T14 | V14: =Operation!U14 | W14: =Operation!V14 | X14: =Operation!W14 | ... AS14: =Operation!AR14
B15: Maintenance & SPV Costs | C15: k£ | F15: =-Operation!E21 | G15: =-Operation!F21 | H15: =-Operation!G21 | I15: =-Operation!H21 | J15: =-Operation!I21 | K15: =-Operation!J21 | L15: =-Operation!K21 | M15: =-Operation!L21 | O15: =-Operation!N21 | P15: =-Operation!O21 | Q15: =-Operation!P21 | R15: =-Operation!Q21 | S15: =-Operation!R21 | T15: =-Operation!S21 | U15: =-Operation!T21 | V15: =-Operation!U21 | ... AS15: =-Operation!AR21
B16: Corporate Tax | C16: k£ | G16: ='P&L'!G23 | H16: ='P&L'!H23 | I16: ='P&L'!I23 | J16: ='P&L'!J23 | K16: ='P&L'!K23 | L16: ='P&L'!L23 | M16: ='P&L'!M23 | P16: ='P&L'!P23 | Q16: ='P&L'!Q23 | R16: ='P&L'!R23 | S16: ='P&L'!S23 | U16: ='P&L'!U23 | V16: ='P&L'!V23 | W16: ='P&L'!W23 | X16: ='P&L'!X23 | Y16: ='P&L'!Y23 | Z16: ='P&L'!Z23 | AA16: ='P&L'!AA23 | AB16: ='P&L'!AB23 | AC16: ='P&L'!AC23 | AE16: ='P&L'!AE23 | AF16: ='P&L'!AF23 | AG16: ='P&L'!AG23 | AH16: ='P&L'!AH23 | AI16: ='P&L'!AI23 | AJ16: ='P&L'!AJ23 | AK16: ='P&L'!AK23 | AL16: ='P&L'!AL23 | ... AS16: ='P&L'!AS23
B17: Cash Flow | C17: k£ | F17: =SUM(F12:F16) | G17: =SUM(G12:G16) | H17: =SUM(H12:H16) | I17: =SUM(I12:I16) | J17: =SUM(J12:J16) | K17: =SUM(K12:K16) | L17: =SUM(L12:L16) | M17: =SUM(M12:M16) | ... AS17: =SUM(AS12:AS16)
B19: Project IRR | C19: % | E19: =IRR(F17:AS17)
B22: Equity IRR
B24: Equity Injected | C24: k£ | E24: =SUM(F24:AS24) | F24: =-Construction!E26 | G24: =-Construction!F26 | H24: =-Construction!G26 | I24: =-Construction!H26 | J24: =-Construction!I26 | K24: =-Construction!J26 | L24: =-Construction!K26 | M24: =-Construction!L26 | ... AC24: =-Construction!AB26 | AE24: =-Construction!AD26 | AF24: =-Construction!AE26 | AH24: =-Construction!AG26 | AI24: =-Construction!AH26 | AJ24: =-Construction!AI26 | AK24: =-Construction!AJ26 | AL24: =-Construction!AK26 | AM24: =-Construction!AL26 | AN24: =-Construction!AM26 | AO24: =-Construction!AN26 | ... AS24: =-Construction!AR26
B25: Dividends earned | C25: k£ | F25: =-CFS!F21 | G25: =-CFS!G21 | I25: =-CFS!I21 | J25: =-CFS!J21 | K25: =-CFS!K21 | L25: =-CFS!L21 | M25: =-CFS!M21 | O25: =-CFS!O21 | P25: =-CFS!P21 | Q25: =-CFS!Q21 | R25: =-CFS!R21 | S25: =-CFS!S21 | T25: =-CFS!T21 | U25: =-CFS!U21 | V25: =-CFS!V21 | X25: =-CFS!X21 | Y25: =-CFS!Y21 | Z25: =-CFS!Z21 | AA25: =-CFS!AA21 | AB25: =-CFS!AB21 | AC25: =-CFS!AC21 | AD25: =-CFS!AD21 | AE25: =-CFS!AE21 | ... AS25: =-CFS!AS21
B26: Cash out End of Concession | C26: k£ | AS26: ='Balance Sheet'!AS9
