Workbook

Sheet Model Inputs
B1: [Company Name]
B2: 5-Year Financial Plan—Manufacturing
B3: Model inputs and investor scenario
B5: Enter data in white cells only.
B6: Italicized numbers in gray cells are calculations that should not be overwritten.
B7: Non-italicized numbers in gray cells are calculations that can be overwritten.
B9: General notes and assumptions
B10: [Document key financial planning assumptions here.]
B19: Year 1 model inputs
B20: Use this area to capture key components of the Profit and Loss Statement and the Balance Sheet for the first year only.
B22: 1. Year-one revenue expectancy
C23: <Product 1> | D23: <Product 2> | E23: <Product 3> | F23: <Product 4>
B24: Number of units sold annually | C24: 2800 | D24: 1200 | E24: 1600 | F24: 0
B25: Average sales price per unit | C25: 120 | D25: 80 | E25: 40 | F25: 0
B26: Annual revenue per product | C26: =+C24*C25 | D26: =+D24*D25 | E26: =+E24*E25 | F26: =+F24*F25
B28: Total year 1 revenue | C28: =SUM(C26:F26)
B30: 2. Year 1 cost of goods sold
C31: =C32 | D31: =D32 | E31: =E32 | F31: =F32
B32: Expected gross margin per product | C32: 0.5 | D32: 0.4 | E32: 0.25 | F32: 0
B33: Annual cost of goods sold per product | C33: =+C26*(1-C32) | D33: =+D26*(1-D32) | E33: =+E26*(1-E32) | F33: =+F26*(1-F32)
B35: Total year 1 cost of goods sold | C35: =SUM(C33:F33)
B37: 3. Annual maintenance, repair, and overhaul
B38: Factor (%) on capital equipment | C38: 0.15
B40: 4. Number of years for straight-line depreciation | C40: 5
B42: 5. Annual tax rate | C42: 0.3
B44: 6. If long-term debt is being used to finance operations, enter the total loan value. | C44: 80000

Sheet Profit and Loss
B1: =+'Model Inputs'!B1
B2: =+'Model Inputs'!B2
B3: Profit and loss projections
B6: Year-by-year profit and loss assumptions
E7: Year 1 | F7: Year 2 | G7: Year 3 | H7: Year 4 | I7: Year 5
C8: Annual cumulative price (revenue) increase | E8: - | F8: 0.02 | G8: 0.04 | H8: 0.06 | I8: 0.08
C9: Annual cumulative inflation (expense) increase | E9: - | F9: 0.02 | G9: 0.04 | H9: 0.06 | I9: 0.08
C10: Interest rate on ending cash balance | E10: 0.005 | F10: 0.005 | G10: 0.005 | H10: 0.005 | I10: 0.005
E13: =+E7 | F13: =+F7 | G13: =+G7 | H13: =+H7 | I13: =+I7
B14: Revenue
C15: Gross revenue | E15: =+'Model Inputs'!C28 | F15: =+E15*(1+F8) | G15: =+F15*(1+G8) | H15: =+G15*(1+H8) | I15: =+H15*(1+I8)
C16: Cost of goods sold | E16: =+'Model Inputs'!C35 | F16: =+E16*(1+F9) | G16: =+F16*(1+G9) | H16: =+G16*(1+H9) | I16: =+H16*(1+I9)
C17: Gross margin | E17: =E15-E16 | F17: =F15-F16 | G17: =G15-G16 | H17: =H15-H16 | I17: =I15-I16
C19: Other revenue [source] | E19: 0 | F19: 0 | G19: 10000 | H19: 0 | I19: 0
C20: Interest income | E20: 1000 | F20: 0 | G20: 0 | H20: 0 | I20: 0
C21: Total revenue | E21: =+E17+E19+E20 | F21: =+F17+F19+F20 | G21: =+G17+G19+G20 | H21: =+H17+H19+H20 | I21: =+I17+I19+I20
B23: Operating expenses
C24: Sales and marketing | E24: 40000 | F24: =+E24*(1+F$9) | G24: =+F24*(1+G$9) | H24: =+G24*(1+H$9) | I24: =+H24*(1+I$9)
C25: Payroll and payroll taxes | E25: 60000 | F25: =+E25*(1+F$9) | G25: =+F25*(1+G$9) | H25: =+G25*(1+H$9) | I25: =+H25*(1+I$9)
C26: Depreciation | E26: =('Balance Sheet'!D15+'Balance Sheet'!D17+'Balance Sheet'!D18)/'Model Inputs'!$C$40 | F26: =('Balance Sheet'!E15+'Balance Sheet'!E17+'Balance Sheet'!E18)/'Model Inputs'!$C$40*(1+F$9) | G26: =('Balance Sheet'!F15+'Balance Sheet'!F17+'Balance Sheet'!F18)/'Model Inputs'!$C$40*(1+G$9) | H26: =('Balance Sheet'!G15+'Balance Sheet'!G17+'Balance Sheet'!G18)/'Model Inputs'!$C$40*(1+H$9) | I26: =('Balance Sheet'!H15+'Balance Sheet'!H17+'Balance Sheet'!H18)/'Model Inputs'!$C$40*(1+I$9)
C27: Insurance | E27: 40000 | F27: =+E27*(1+F$9) | G27: =+F27*(1+G$9) | H27: =+G27*(1+H$9) | I27: =+H27*(1+I$9)
C28: Maintenance, repair, and overhaul | E28: =+'Balance Sheet'!D18*'Model Inputs'!$C$38 | F28: =('Balance Sheet'!E18*'Model Inputs'!$C$38)*(1+F$9) | G28: =('Balance Sheet'!F18*'Model Inputs'!$C$38)*(1+G$9) | H28: =('Balance Sheet'!G18*'Model Inputs'!$C$38)*(1+H$9) | I28: =('Balance Sheet'!H18*'Model Inputs'!$C$38)*(1+I$9)
C29: Utilities | E29: 30000 | F29: =+E29*(1+F$9) | G29: =+F29*(1+G$9) | H29: =+G29*(1+H$9) | I29: =+H29*(1+I$9)
C30: Property taxes | E30: 15000 | F30: =+E30*(1+F$9) | G30: =+F30*(1+G$9) | H30: =+G30*(1+H$9) | I30: =+H30*(1+I$9)
C31: Administrative fees | E31: 18000 | F31: =+E31*(1+F$9) | G31: =+F31*(1+G$9) | H31: =+G31*(1+H$9) | I31: =+H31*(1+I$9)
C32: Other | E32: 4000 | F32: =+E32*(1+F$9) | G32: =+F32*(1+G$9) | H32: =+G32*(1+H$9) | I32: =+H32*(1+I$9)
C33: Total operating expenses | E33: =SUM(E24:E32) | F33: =SUM(F24:F32) | G33: =SUM(G24:G32) | H33: =SUM(H24:H32) | I33: =SUM(I24:I32)
B35: Operating income | E35: =E21-E33 | F35: =F21-F33 | G35: =G21-G33 | H35: =H21-H33 | I35: =I21-I33
C37: Interest expense on long-term debt | E37: =-SUM('Loan Payment Calculator'!F12:F23) | F37: =-SUM('Loan Payment Calculator'!F24:F35) | G37: =-SUM('Loan Payment Calculator'!F36:F47) | H37: =-SUM('Loan Payment Calculator'!F48:F59) | I37: =-SUM('Loan Payment Calculator'!F60:F71)
B39: Operating income before other items | E39: =+E35-E37 | F39: =+F35-F37 | G39: =+G35-G37 | H39: =+H35-H37 | I39: =+I35-I37
C41: Loss (gain) on sale of assets | E41: 0 | F41: 0 | G41: 1000 | H41: 0 | I41: 0
C42: Other unusual expenses (income) | E42: 0 | F42: 0 | G42: 0 | H42: 0 | I42: 0
B44: Earnings before taxes | E44: =E39+E41+E42 | F44: =F39+F41+F42 | G44: =G39+G41+G42 | H44: =H39+H41+H42 | I44: =I39+I41+I42
B46: Taxes on income | D46: ='Model Inputs'!C42 | E46: =IF(E44<0,0,$D$46*E44) | F46: =IF(F44<0,0,$D$46*F44) | G46: =IF(G44<0,0,$D$46*G44) | H46: =IF(H44<0,0,$D$46*H44) | I46: =IF(I44<0,0,$D$46*I44)
B48: Net income (loss) | E48: =E44-E46 | F48: =F44-F46 | G48: =G44-G46 | H48: =H44-H46 | I48: =I44-I46

Sheet Balance Sheet
B1: =+'Model Inputs'!B1
B2: =+'Model Inputs'!B2
B3: Balance sheet projections
B6: Assets | D6: Initial balance | E6: Year 1 | F6: Year 2 | G6: Year 3 | H6: Year 4 | I6: Year 5
C7: Cash and short-term investments | D7: 50000 | E7: =+'Cash Flow'!D36 | F7: =+'Cash Flow'!E36 | G7: =+'Cash Flow'!F36 | H7: =+'Cash Flow'!G36 | I7: =+'Cash Flow'!H36
C8: Accounts receivable | D8: 3000 | E8: =D8 | F8: =E8 | G8: =F8 | H8: =G8 | I8: =H8
C9: Total inventory | D9: 25000 | E9: =D9 | F9: =E9 | G9: =F9 | H9: =G9 | I9: =H9
C10: Prepaid expenses | D10: 0 | E10: =+D10 | F10: =+E10 | G10: =+F10 | H10: =+G10 | I10: =+H10
C11: Deferred income tax | D11: 0 | E11: =+D11 | F11: =+E11 | G11: =+F11 | H11: =+G11 | I11: =+H11
C12: Other current assets | D12: 5000 | E12: =+D12 | F12: =+E12 | G12: =+F12 | H12: =+G12 | I12: =+H12
C13: Total current assets | D13: =SUM(D7:D12) | E13: =SUM(E7:E12) | F13: =SUM(F7:F12) | G13: =SUM(G7:G12) | H13: =SUM(H7:H12) | I13: =SUM(I7:I12)
C15: Buildings | D15: 100000 | E15: =+D15 | F15: =+E15 | G15: =+F15 | H15: =+G15 | I15: =+H15
C16: Land | D16: 100000 | E16: =+D16 | F16: =+E16 | G16: =+F16 | H16: =+G16 | I16: =+H16
C17: Capital improvements | D17: 0 | E17: =+D17 | F17: =+E17 | G17: =+F17 | H17: =+G17 | I17: =+H17
C18: Machinery and equipment | D18: 100000 | E18: =D18 | F18: =+E18 | G18: =F18 | H18: =G18 | I18: =H18
C19: Less: Accumulated depreciation expense | D19: 0 | E19: =+D19+'Profit and Loss'!E26 | F19: =+E19+'Profit and Loss'!F26 | G19: =+F19+'Profit and Loss'!G26 | H19: =+G19+'Profit and Loss'!H26 | I19: =+H19+'Profit and Loss'!I26
C20: Net property/equipment | D20: =SUM(D15:D18)-D19 | E20: =SUM(E15:E18)-E19 | F20: =SUM(F15:F18)-F19 | G20: =SUM(G15:G18)-G19 | H20: =SUM(H15:H18)-H19 | I20: =SUM(I15:I18)-I19
C22: Goodwill | D22: 0 | E22: =+D22 | F22: =+E22 | G22: =+F22 | H22: =+G22 | I22: =+H22
C23: Deferred income tax | D23: 0 | E23: =+D23 | F23: =+E23 | G23: =+F23 | H23: =+G23 | I23: =+H23
C24: Long-term investments | D24: 0 | E24: =+D24 | F24: =+E24 | G24: =+F24 | H24: =+G24 | I24: =+H24
C25: Deposits | D25: 0 | E25: =+D25 | F25: =+E25 | G25: =+F25 | H25: =+G25 | I25: =+H25
C26: Other long-term assets | D26: 0 | E26: =+D26 | F26: =+E26 | G26: =+F26 | H26: =+G26 | I26: =+H26
C27: Total assets | D27: =SUM(D22:D26)+D20+D13 | E27: =SUM(E22:E26)+E20+E13 | F27: =SUM(F22:F26)+F20+F13 | G27: =SUM(G22:G26)+G20+G13 | H27: =SUM(H22:H26)+H20+H13 | I27: =SUM(I22:I26)+I20+I13
B29: Liabilities | D29: Initial balance | E29: =E6 | F29: =F6 | G29: =G6 | H29: =H6 | I29: =I6
C30: Accounts payable | D30: 2000 | E30: =+D30 | F30: 3000 | G30: =+F30 | H30: 1500 | I30: =+H30
C31: Accrued expenses | D31: 0 | E31: =+D31 | F31: =+E31 | G31: =+F31 | H31: =+G31 | I31: =+H31
C32: Notes payable/short-term debt | D32: 0 | E32: =+D32 | F32: =+E32 | G32: =+F32 | H32: =+G32 | I32: =+H32
C33: Capital leases | D33: 0 | E33: =+D33 | F33: =+E33 | G33: =+F33 | H33: =+G33 | I33: =+H33
C34: Other current liabilities | D34: 100 | E34: =+D34 | F34: =+E34 | G34: =+F34 | H34: =+G34 | I34: =+H34
C35: Total current liabilities | D35: =SUM(D30:D34) | E35: =SUM(E30:E34) | F35: =SUM(F30:F34) | G35: =SUM(G30:G34) | H35: =SUM(H30:H34) | I35: =SUM(I30:I34)
C37: Long-term debt from loan payment calculator | D37: =+'Model Inputs'!C44 | E37: ='Loan Payment Calculator'!D24 | F37: ='Loan Payment Calculator'!D36 | G37: ='Loan Payment Calculator'!D48 | H37: ='Loan Payment Calculator'!D60 | I37: ='Loan Payment Calculator'!D72
C38: Other long-term debt | D38: 100000 | E38: 200000 | F38: 150000 | G38: 175000 | H38: 225000 | I38: 150000
C39: Total debt | D39: =D35+D37+D38 | E39: =E35+E37+E38 | F39: =F35+F37+F38 | G39: =G35+G37+G38 | H39: =H35+H37+H38 | I39: =I35+I37+I38
C41: Other liabilities | D41: 0 | E41: =+D41 | F41: =+E41 | G41: =+F41 | H41: =+G41 | I41: =+H41
C43: Total liabilities | D43: =D35+D37+D38+D41 | E43: =E35+E37+E38+E41 | F43: =F35+F37+F38+F41 | G43: =G35+G37+G38+G41 | H43: =H35+H37+H38+H41 | I43: =I35+I37+I38+I41
B45: Equity | D45: Initial balance | E45: =E6 | F45: =F6 | G45: =G6 | H45: =H6 | I45: =I6
C46: Owner's equity (common) | D46: 50000 | E46: =D46 | F46: =E46 | G46: =F46 | H46: =G46 | I46: =H46
C47: Paid-in capital | D47: 250000 | E47: =+D47 | F47: =E47 | G47: =F47 | H47: =G47 | I47: =H47
C48: Preferred equity | D48: 0 | E48: =+D48 | F48: =E48 | G48: =F48 | H48: =G48 | I48: =H48
C49: Retained earnings | D49: 0 | E49: =+'Profit and Loss'!E48 | F49: =+E49+'Profit and Loss'!F48 | G49: =+F49+'Profit and Loss'!G48 | H49: =+G49+'Profit and Loss'!H48 | I49: =+H49+'Profit and Loss'!I48
...

Sheet Cash Flow
B1: =+'Model Inputs'!B1
B2: =+'Model Inputs'!B2
B3: Cash flow
D6: Year 1 | E6: Year 2 | F6: Year 3 | G6: Year 4 | H6: Year 5 | I6: Total
B7: Operating activities
C8: Net income | D8: =+'Profit and Loss'!E48 | E8: =+'Profit and Loss'!F48 | F8: =+'Profit and Loss'!G48 | G8: =+'Profit and Loss'!H48 | H8: =+'Profit and Loss'!I48 | I8: =SUM(D8:H8)
C9: Depreciation | D9: ='Profit and Loss'!E26 | E9: ='Profit and Loss'!F26 | F9: ='Profit and Loss'!G26 | G9: ='Profit and Loss'!H26 | H9: ='Profit and Loss'!I26 | I9: =SUM(D9:H9)
C10: Accounts receivable | D10: =+'Balance Sheet'!D8-'Balance Sheet'!E8 | E10: =+'Balance Sheet'!E8-'Balance Sheet'!F8 | F10: =+'Balance Sheet'!F8-'Balance Sheet'!G8 | G10: =+'Balance Sheet'!G8-'Balance Sheet'!H8 | H10: =+'Balance Sheet'!H8-'Balance Sheet'!I8 | I10: =SUM(D10:H10)
C11: Inventories | D11: =+'Balance Sheet'!D9-'Balance Sheet'!E9 | E11: =+'Balance Sheet'!E9-'Balance Sheet'!F9 | F11: =+'Balance Sheet'!F9-'Balance Sheet'!G9 | G11: =+'Balance Sheet'!G9-'Balance Sheet'!H9 | H11: =+'Balance Sheet'!H9-'Balance Sheet'!I9 | I11: =SUM(D11:H11)
C12: Accounts payable | D12: =+'Balance Sheet'!E30-'Balance Sheet'!D30 | E12: =+'Balance Sheet'!F30-'Balance Sheet'!E30 | F12: =+'Balance Sheet'!G30-'Balance Sheet'!F30 | G12: =+'Balance Sheet'!H30-'Balance Sheet'!G30 | H12: =+'Balance Sheet'!I30-'Balance Sheet'!H30 | I12: =SUM(D12:H12)
C13: Amortization | D13: 0 | E13: =D13 | F13: =E13 | G13: =F13 | H13: =G13 | I13: =SUM(D13:H13)
C14: Other liabilities | D14: 0 | E14: =D14 | F14: =E14 | G14: =F14 | H14: =G14 | I14: =SUM(D14:H14)
C15: Other operating cash flow items | D15: 0 | E15: =D15 | F15: =E15 | G15: =F15 | H15: =G15 | I15: =SUM(D15:H15)
C16: Total operating activities | D16: =SUM(D8:D15) | E16: =SUM(E8:E15) | F16: =SUM(F8:F15) | G16: =SUM(G8:G15) | H16: =SUM(H8:H15) | I16: =SUM(D16:H16)
B18: Investing activities
C19: Capital expenditures | D19: =-1*MAX(0,SUM('Balance Sheet'!E15:E18)-SUM('Balance Sheet'!D15:D18)) | E19: =-1*MAX(0,SUM('Balance Sheet'!F15:F18)-SUM('Balance Sheet'!E15:E18)) | F19: =-1*MAX(0,SUM('Balance Sheet'!G15:G18)-SUM('Balance Sheet'!F15:F18)) | G19: =-1*MAX(0,SUM('Balance Sheet'!H15:H18)-SUM('Balance Sheet'!G15:G18)) | H19: =-1*MAX(0,SUM('Balance Sheet'!I15:I18)-SUM('Balance Sheet'!H15:H18)) | I19: =SUM(D19:H19)
C20: Acquisition of business | D20: 0 | E20: 0 | F20: 0 | G20: 0 | H20: 0 | I20: =SUM(D20:H20)
C21: Sale of fixed assets | D21: =(-1*MIN(0,SUM('Balance Sheet'!E15:E18)-SUM('Balance Sheet'!D15:D18))-'Profit and Loss'!E41) | E21: =(-1*MIN(0,SUM('Balance Sheet'!F15:F18)-SUM('Balance Sheet'!E15:E18))-'Profit and Loss'!F41) | F21: =(-1*MIN(0,SUM('Balance Sheet'!G15:G18)-SUM('Balance Sheet'!F15:F18))-'Profit and Loss'!G41) | G21: =(-1*MIN(0,SUM('Balance Sheet'!H15:H18)-SUM('Balance Sheet'!G15:G18))-'Profit and Loss'!H41) | H21: =(-1*MIN(0,SUM('Balance Sheet'!I15:I18)-SUM('Balance Sheet'!H15:H18))-'Profit and Loss'!I41) | I21: =SUM(D21:H21)
C22: Other investing cash flow items | D22: 0 | E22: 0 | F22: 0 | G22: 0 | H22: 0 | I22: =SUM(D22:H22)
C23: Total investing activities | D23: =SUM(D19:D22) | E23: =SUM(E19:E22) | F23: =SUM(F19:F22) | G23: =SUM(G19:G22) | H23: =SUM(H19:H22) | I23: =SUM(D23:H23)
B25: Financing activities
C26: Long-term debt/financing | D26: ='Balance Sheet'!E37+'Balance Sheet'!E38-('Balance Sheet'!D37+'Balance Sheet'!D38) | E26: =+'Balance Sheet'!F37+'Balance Sheet'!F38-('Balance Sheet'!E37+'Balance Sheet'!E38) | F26: ='Balance Sheet'!G37+'Balance Sheet'!G38-('Balance Sheet'!F37+'Balance Sheet'!F38) | G26: ='Balance Sheet'!H37+'Balance Sheet'!H38-('Balance Sheet'!G37+'Balance Sheet'!G38) | H26: ='Balance Sheet'!I37+'Balance Sheet'!I38-('Balance Sheet'!H37+'Balance Sheet'!H38) | I26: =SUM(D26:H26)
C27: Preferred stock | D27: 0 | E27: =D27 | F27: =E27 | G27: =F27 | H27: =G27 | I27: =SUM(D27:H27)
C28: Total cash dividends paid | D28: 0 | E28: =D28 | F28: =E28 | G28: =F28 | H28: =G28 | I28: =SUM(D28:H28)
C29: Common stock | D29: 0 | E29: =D29 | F29: =E29 | G29: =F29 | H29: =G29 | I29: =SUM(D29:H29)
C30: Other financing cash flow items | D30: 0 | E30: =D30 | F30: =E30 | G30: =F30 | H30: =G30 | I30: =SUM(D30:H30)
C31: Total financing activities | D31: =SUM(D26:D30) | E31: =SUM(E26:E30) | F31: =SUM(F26:F30) | G31: =SUM(G26:G30) | H31: =SUM(H26:H30) | I31: =SUM(D31:H31)
B33: Cumulative cash flow | D33: =D16+D23+D31 | E33: =E16+E23+E31 | F33: =F16+F23+F31 | G33: =G16+G23+G31 | H33: =H16+H23+H31 | I33: =SUM(D33:H33)
B35: Beginning cash balance | D35: =+'Balance Sheet'!D7 | E35: =D36 | F35: =E36 | G35: =F36 | H35: =G36
B36: Ending cash balance | D36: =D35+D33 | E36: =E35+E33 | F36: =F35+F33 | G36: =G35+G33 | H36: =H35+H33

Sheet Loan Payment Calculator
B1: =+'Model Inputs'!B1
B2: =+'Model Inputs'!B2
B3: Loan payment calculator
B5: Annual interest rate | C5: 0.05 | E5: Note: This calculator can generate principal and interest payments for a period of up to 30 years (360 months).
B6: Monthly rate | C6: =(1+C5)^(1/12)-1
B7: Loan amount | C7: =+'Model Inputs'!C44
B8: Term of loan (months) | C8: 60
B9: Payment | C9: =PMT(C6,C8,C7)
C11: Month | D11: Principal balance | E11: Principal payment | F11: Interest | G11: Payment
C12: 1 | D12: =C7 | E12: =G12-F12 | F12: =-$C$6*D12 | G12: =IF(C12>$C$8,0,$C$9)
C13: 2 | D13: =D12+E12 | E13: =G13-F13 | F13: =-$C$6*D13 | G13: =IF(C13>$C$8,0,$C$9)
C14: 3 | D14: =D13+E13 | E14: =G14-F14 | F14: =-$C$6*D14 | G14: =IF(C14>$C$8,0,$C$9)
C15: 4 | D15: =D14+E14 | E15: =G15-F15 | F15: =-$C$6*D15 | G15: =IF(C15>$C$8,0,$C$9)
C16: 5 | D16: =D15+E15 | E16: =G16-F16 | F16: =-$C$6*D16 | G16: =IF(C16>$C$8,0,$C$9)
C17: 6 | D17: =D16+E16 | E17: =G17-F17 | F17: =-$C$6*D17 | G17: =IF(C17>$C$8,0,$C$9)
C18: 7 | D18: =D17+E17 | E18: =G18-F18 | F18: =-$C$6*D18 | G18: =IF(C18>$C$8,0,$C$9)
C19: 8 | D19: =D18+E18 | E19: =G19-F19 | F19: =-$C$6*D19 | G19: =IF(C19>$C$8,0,$C$9)
C20: 9 | D20: =D19+E19 | E20: =G20-F20 | F20: =-$C$6*D20 | G20: =IF(C20>$C$8,0,$C$9)
C21: 10 | D21: =D20+E20 | E21: =G21-F21 | F21: =-$C$6*D21 | G21: =IF(C21>$C$8,0,$C$9)
C22: 11 | D22: =D21+E21 | E22: =G22-F22 | F22: =-$C$6*D22 | G22: =IF(C22>$C$8,0,$C$9)
C23: 12 | D23: =D22+E22 | E23: =G23-F23 | F23: =-$C$6*D23 | G23: =IF(C23>$C$8,0,$C$9)
C24: 13 | D24: =D23+E23 | E24: =G24-F24 | F24: =-$C$6*D24 | G24: =IF(C24>$C$8,0,$C$9)
... C371: 360 | D371: =D370+E370 | E371: =G371-F371 | F371: =-$C$6*D371 | G371: =IF(C371>$C$8,0,$C$9)
